{
  size: [4, 4, 4],
  entities: [],
  blocks: [
    {
      pos: [1, 0, 0],
      state: 0
    },
    {
      pos: [2, 0, 0],
      state: 0
    },
    {
      pos: [1, 1, 0],
      state: 1
    },
    {
      pos: [2, 1, 0],
      state: 1
    },
    {
      pos: [1, 2, 0],
      state: 1
    },
    {
      pos: [0, 3, 0],
      state: 1
    },
    {
      pos: [1, 0, 1],
      state: 0
    },
    {
      pos: [2, 0, 1],
      state: 0
    },
    {
      pos: [3, 0, 1],
      state: 0
    },
    {
      pos: [1, 1, 1],
      state: 1
    },
    {
      pos: [2, 1, 1],
      state: 1
    },
    {
      pos: [3, 1, 1],
      state: 1
    },
    {
      pos: [1, 2, 1],
      state: 1
    },
    {
      pos: [0, 3, 1],
      state: 1
    },
    {
      pos: [1, 0, 2],
      state: 0
    },
    {
      pos: [2, 0, 2],
      state: 0
    },
    {
      pos: [3, 0, 2],
      state: 0
    },
    {
      pos: [1, 1, 2],
      state: 1
    },
    {
      pos: [2, 1, 2],
      state: 1
    },
    {
      pos: [3, 1, 2],
      state: 1
    },
    {
      pos: [1, 2, 2],
      state: 1
    },
    {
      pos: [2, 2, 2],
      state: 1
    },
    {
      pos: [3, 2, 2],
      state: 1
    },
    {
      pos: [0, 3, 2],
      state: 1
    },
    {
      pos: [0, 3, 3],
      state: 1
    },
    {
      pos: [1, 3, 3],
      state: 1
    },
    {
      pos: [2, 3, 3],
      state: 1
    },
    {
      pos: [3, 3, 3],
      state: 1
    },
    {
      pos: [3, 0, 0],
      state: 2
    },
    {
      pos: [3, 1, 0],
      state: 3
    },
    {
      pos: [0, 2, 0],
      state: 4
    },
    {
      pos: [2, 2, 0],
      state: 5
    },
    {
      pos: [3, 2, 0],
      state: 2
    },
    {
      pos: [1, 3, 0],
      state: 5
    },
    {
      pos: [2, 3, 0],
      state: 2
    },
    {
      pos: [3, 3, 0],
      state: 2
    },
    {
      pos: [0, 2, 1],
      state: 4
    },
    {
      pos: [2, 2, 1],
      state: 3
    },
    {
      pos: [3, 2, 1],
      state: 3
    },
    {
      pos: [1, 3, 1],
      state: 5
    },
    {
      pos: [2, 3, 1],
      state: 2
    },
    {
      pos: [3, 3, 1],
      state: 2
    },
    {
      pos: [0, 2, 2],
      state: 4
    },
    {
      pos: [1, 3, 2],
      state: 3
    },
    {
      pos: [2, 3, 2],
      state: 3
    },
    {
      pos: [3, 3, 2],
      state: 3
    },
    {
      pos: [0, 2, 3],
      state: 6
    },
    {
      pos: [1, 2, 3],
      state: 6
    },
    {
      pos: [2, 2, 3],
      state: 6
    },
    {
      pos: [3, 2, 3],
      state: 6
    }
  ],
  author: "Player74",
  palette: [
    {
      Name: "minecraft:cobblestone"
    },
    {
      Properties: {
        variant: "dark_oak"
      },
      Name: "minecraft:planks"
    },
    {
      Name: "minecraft:air"
    },
    {
      Properties: {
        half: "bottom",
        shape: "outer_right",
        facing: "south"
      },
      Name: "minecraft:dark_oak_stairs"
    },
    {
      Properties: {
        half: "top",
        shape: "straight",
        facing: "east"
      },
      Name: "minecraft:dark_oak_stairs"
    },
    {
      Properties: {
        half: "bottom",
        shape: "straight",
        facing: "west"
      },
      Name: "minecraft:dark_oak_stairs"
    },
    {
      Properties: {
        half: "top",
        shape: "outer_right",
        facing: "north"
      },
      Name: "minecraft:dark_oak_stairs"
    }
  ],
  version: 1
}