{
  author: "ProfMobius",
  palette: [
    {
      Name: "minecraft:bone_block",
      Properties: {
        axis: "z"
      }
    },
    {
      Name: "minecraft:bone_block",
      Properties: {
        axis: "x"
      }
    },
    {
      Name: "minecraft:bone_block",
      Properties: {
        axis: "y"
      }
    }
  ],
  blocks: [
    {
      state: 0,
      pos: [2, 3, 0]
    },
    {
      state: 1,
      pos: [1, 0, 1]
    },
    {
      state: 1,
      pos: [3, 0, 1]
    },
    {
      state: 2,
      pos: [0, 1, 1]
    },
    {
      state: 2,
      pos: [4, 1, 1]
    },
    {
      state: 2,
      pos: [0, 2, 1]
    },
    {
      state: 2,
      pos: [4, 2, 1]
    },
    {
      state: 1,
      pos: [1, 3, 1]
    },
    {
      state: 0,
      pos: [2, 3, 1]
    },
    {
      state: 1,
      pos: [3, 3, 1]
    },
    {
      state: 0,
      pos: [2, 3, 2]
    },
    {
      state: 1,
      pos: [1, 0, 3]
    },
    {
      state: 1,
      pos: [3, 0, 3]
    },
    {
      state: 2,
      pos: [0, 1, 3]
    },
    {
      state: 2,
      pos: [4, 1, 3]
    },
    {
      state: 2,
      pos: [0, 2, 3]
    },
    {
      state: 2,
      pos: [4, 2, 3]
    },
    {
      state: 1,
      pos: [1, 3, 3]
    },
    {
      state: 0,
      pos: [2, 3, 3]
    },
    {
      state: 1,
      pos: [3, 3, 3]
    },
    {
      state: 0,
      pos: [2, 3, 4]
    },
    {
      state: 1,
      pos: [1, 0, 5]
    },
    {
      state: 1,
      pos: [3, 0, 5]
    },
    {
      state: 2,
      pos: [0, 1, 5]
    },
    {
      state: 2,
      pos: [4, 1, 5]
    },
    {
      state: 2,
      pos: [0, 2, 5]
    },
    {
      state: 2,
      pos: [4, 2, 5]
    },
    {
      state: 1,
      pos: [1, 3, 5]
    },
    {
      state: 0,
      pos: [2, 3, 5]
    },
    {
      state: 1,
      pos: [3, 3, 5]
    },
    {
      state: 0,
      pos: [2, 3, 6]
    },
    {
      state: 1,
      pos: [1, 0, 7]
    },
    {
      state: 1,
      pos: [3, 0, 7]
    },
    {
      state: 2,
      pos: [0, 1, 7]
    },
    {
      state: 2,
      pos: [4, 1, 7]
    },
    {
      state: 2,
      pos: [0, 2, 7]
    },
    {
      state: 2,
      pos: [4, 2, 7]
    },
    {
      state: 1,
      pos: [1, 3, 7]
    },
    {
      state: 0,
      pos: [2, 3, 7]
    },
    {
      state: 1,
      pos: [3, 3, 7]
    },
    {
      state: 0,
      pos: [2, 3, 8]
    },
    {
      state: 1,
      pos: [1, 0, 9]
    },
    {
      state: 1,
      pos: [3, 0, 9]
    },
    {
      state: 2,
      pos: [0, 1, 9]
    },
    {
      state: 2,
      pos: [4, 1, 9]
    },
    {
      state: 2,
      pos: [0, 2, 9]
    },
    {
      state: 2,
      pos: [4, 2, 9]
    },
    {
      state: 1,
      pos: [1, 3, 9]
    },
    {
      state: 0,
      pos: [2, 3, 9]
    },
    {
      state: 1,
      pos: [3, 3, 9]
    },
    {
      state: 0,
      pos: [2, 3, 10]
    },
    {
      state: 1,
      pos: [1, 0, 11]
    },
    {
      state: 1,
      pos: [3, 0, 11]
    },
    {
      state: 2,
      pos: [0, 1, 11]
    },
    {
      state: 2,
      pos: [4, 1, 11]
    },
    {
      state: 2,
      pos: [0, 2, 11]
    },
    {
      state: 2,
      pos: [4, 2, 11]
    },
    {
      state: 1,
      pos: [1, 3, 11]
    },
    {
      state: 0,
      pos: [2, 3, 11]
    },
    {
      state: 1,
      pos: [3, 3, 11]
    },
    {
      state: 0,
      pos: [2, 3, 12]
    }
  ],
  entities: [],
  version: 1,
  size: [5, 4, 13]
}