{
  author: "ProfMobius",
  palette: [
    {
      Name: "minecraft:bone_block",
      Properties: {
        axis: "z"
      }
    },
    {
      Name: "minecraft:bone_block",
      Properties: {
        axis: "x"
      }
    },
    {
      Name: "minecraft:bone_block",
      Properties: {
        axis: "y"
      }
    }
  ],
  blocks: [
    {
      state: 0,
      pos: [4, 4, 0]
    },
    {
      state: 1,
      pos: [1, 0, 1]
    },
    {
      state: 1,
      pos: [2, 0, 1]
    },
    {
      state: 1,
      pos: [6, 0, 1]
    },
    {
      state: 1,
      pos: [7, 0, 1]
    },
    {
      state: 2,
      pos: [0, 1, 1]
    },
    {
      state: 2,
      pos: [8, 1, 1]
    },
    {
      state: 2,
      pos: [0, 2, 1]
    },
    {
      state: 2,
      pos: [8, 2, 1]
    },
    {
      state: 2,
      pos: [0, 3, 1]
    },
    {
      state: 2,
      pos: [8, 3, 1]
    },
    {
      state: 1,
      pos: [0, 4, 1]
    },
    {
      state: 1,
      pos: [1, 4, 1]
    },
    {
      state: 1,
      pos: [2, 4, 1]
    },
    {
      state: 1,
      pos: [3, 4, 1]
    },
    {
      state: 0,
      pos: [4, 4, 1]
    },
    {
      state: 1,
      pos: [5, 4, 1]
    },
    {
      state: 1,
      pos: [6, 4, 1]
    },
    {
      state: 1,
      pos: [7, 4, 1]
    },
    {
      state: 1,
      pos: [8, 4, 1]
    },
    {
      state: 0,
      pos: [4, 4, 2]
    },
    {
      state: 1,
      pos: [1, 0, 3]
    },
    {
      state: 1,
      pos: [2, 0, 3]
    },
    {
      state: 1,
      pos: [6, 0, 3]
    },
    {
      state: 1,
      pos: [7, 0, 3]
    },
    {
      state: 2,
      pos: [0, 1, 3]
    },
    {
      state: 2,
      pos: [8, 1, 3]
    },
    {
      state: 2,
      pos: [0, 2, 3]
    },
    {
      state: 2,
      pos: [8, 2, 3]
    },
    {
      state: 2,
      pos: [0, 3, 3]
    },
    {
      state: 2,
      pos: [8, 3, 3]
    },
    {
      state: 1,
      pos: [0, 4, 3]
    },
    {
      state: 1,
      pos: [1, 4, 3]
    },
    {
      state: 1,
      pos: [2, 4, 3]
    },
    {
      state: 1,
      pos: [3, 4, 3]
    },
    {
      state: 0,
      pos: [4, 4, 3]
    },
    {
      state: 1,
      pos: [5, 4, 3]
    },
    {
      state: 1,
      pos: [6, 4, 3]
    },
    {
      state: 1,
      pos: [7, 4, 3]
    },
    {
      state: 1,
      pos: [8, 4, 3]
    },
    {
      state: 0,
      pos: [4, 4, 4]
    },
    {
      state: 1,
      pos: [1, 0, 5]
    },
    {
      state: 1,
      pos: [2, 0, 5]
    },
    {
      state: 1,
      pos: [6, 0, 5]
    },
    {
      state: 1,
      pos: [7, 0, 5]
    },
    {
      state: 2,
      pos: [0, 1, 5]
    },
    {
      state: 2,
      pos: [8, 1, 5]
    },
    {
      state: 2,
      pos: [0, 2, 5]
    },
    {
      state: 2,
      pos: [8, 2, 5]
    },
    {
      state: 2,
      pos: [0, 3, 5]
    },
    {
      state: 2,
      pos: [8, 3, 5]
    },
    {
      state: 1,
      pos: [0, 4, 5]
    },
    {
      state: 1,
      pos: [1, 4, 5]
    },
    {
      state: 1,
      pos: [2, 4, 5]
    },
    {
      state: 1,
      pos: [3, 4, 5]
    },
    {
      state: 0,
      pos: [4, 4, 5]
    },
    {
      state: 1,
      pos: [5, 4, 5]
    },
    {
      state: 1,
      pos: [6, 4, 5]
    },
    {
      state: 1,
      pos: [7, 4, 5]
    },
    {
      state: 1,
      pos: [8, 4, 5]
    },
    {
      state: 0,
      pos: [4, 4, 6]
    },
    {
      state: 1,
      pos: [1, 0, 7]
    },
    {
      state: 1,
      pos: [2, 0, 7]
    },
    {
      state: 1,
      pos: [6, 0, 7]
    },
    {
      state: 1,
      pos: [7, 0, 7]
    },
    {
      state: 2,
      pos: [0, 1, 7]
    },
    {
      state: 2,
      pos: [8, 1, 7]
    },
    {
      state: 2,
      pos: [0, 2, 7]
    },
    {
      state: 2,
      pos: [8, 2, 7]
    },
    {
      state: 2,
      pos: [0, 3, 7]
    },
    {
      state: 2,
      pos: [8, 3, 7]
    },
    {
      state: 1,
      pos: [0, 4, 7]
    },
    {
      state: 1,
      pos: [1, 4, 7]
    },
    {
      state: 1,
      pos: [2, 4, 7]
    },
    {
      state: 1,
      pos: [3, 4, 7]
    },
    {
      state: 0,
      pos: [4, 4, 7]
    },
    {
      state: 1,
      pos: [5, 4, 7]
    },
    {
      state: 1,
      pos: [6, 4, 7]
    },
    {
      state: 1,
      pos: [7, 4, 7]
    },
    {
      state: 1,
      pos: [8, 4, 7]
    },
    {
      state: 0,
      pos: [4, 4, 8]
    },
    {
      state: 1,
      pos: [1, 0, 9]
    },
    {
      state: 1,
      pos: [2, 0, 9]
    },
    {
      state: 1,
      pos: [6, 0, 9]
    },
    {
      state: 1,
      pos: [7, 0, 9]
    },
    {
      state: 2,
      pos: [0, 1, 9]
    },
    {
      state: 2,
      pos: [8, 1, 9]
    },
    {
      state: 2,
      pos: [0, 2, 9]
    },
    {
      state: 2,
      pos: [8, 2, 9]
    },
    {
      state: 2,
      pos: [0, 3, 9]
    },
    {
      state: 2,
      pos: [8, 3, 9]
    },
    {
      state: 1,
      pos: [0, 4, 9]
    },
    {
      state: 1,
      pos: [1, 4, 9]
    },
    {
      state: 1,
      pos: [2, 4, 9]
    },
    {
      state: 1,
      pos: [3, 4, 9]
    },
    {
      state: 0,
      pos: [4, 4, 9]
    },
    {
      state: 1,
      pos: [5, 4, 9]
    },
    {
      state: 1,
      pos: [6, 4, 9]
    },
    {
      state: 1,
      pos: [7, 4, 9]
    },
    {
      state: 1,
      pos: [8, 4, 9]
    },
    {
      state: 0,
      pos: [4, 4, 10]
    },
    {
      state: 1,
      pos: [1, 0, 11]
    },
    {
      state: 1,
      pos: [2, 0, 11]
    },
    {
      state: 1,
      pos: [6, 0, 11]
    },
    {
      state: 1,
      pos: [7, 0, 11]
    },
    {
      state: 2,
      pos: [0, 1, 11]
    },
    {
      state: 2,
      pos: [8, 1, 11]
    },
    {
      state: 2,
      pos: [0, 2, 11]
    },
    {
      state: 2,
      pos: [8, 2, 11]
    },
    {
      state: 2,
      pos: [0, 3, 11]
    },
    {
      state: 2,
      pos: [8, 3, 11]
    },
    {
      state: 1,
      pos: [0, 4, 11]
    },
    {
      state: 1,
      pos: [1, 4, 11]
    },
    {
      state: 1,
      pos: [2, 4, 11]
    },
    {
      state: 1,
      pos: [3, 4, 11]
    },
    {
      state: 0,
      pos: [4, 4, 11]
    },
    {
      state: 1,
      pos: [5, 4, 11]
    },
    {
      state: 1,
      pos: [6, 4, 11]
    },
    {
      state: 1,
      pos: [7, 4, 11]
    },
    {
      state: 1,
      pos: [8, 4, 11]
    },
    {
      state: 0,
      pos: [4, 4, 12]
    }
  ],
  entities: [],
  version: 1,
  size: [9, 5, 13]
}