{
  author: "ProfMobius",
  palette: [
    {
      Name: "minecraft:coal_ore"
    }
  ],
  blocks: [
    {
      state: 0,
      pos: [0, 0, 0]
    },
    {
      state: 0,
      pos: [4, 0, 0]
    },
    {
      state: 0,
      pos: [0, 1, 0]
    },
    {
      state: 0,
      pos: [1, 1, 0]
    },
    {
      state: 0,
      pos: [2, 1, 0]
    },
    {
      state: 0,
      pos: [3, 1, 0]
    },
    {
      state: 0,
      pos: [4, 1, 0]
    },
    {
      state: 0,
      pos: [0, 2, 0]
    },
    {
      state: 0,
      pos: [2, 2, 0]
    },
    {
      state: 0,
      pos: [4, 2, 0]
    },
    {
      state: 0,
      pos: [0, 3, 0]
    },
    {
      state: 0,
      pos: [1, 3, 0]
    },
    {
      state: 0,
      pos: [2, 3, 0]
    },
    {
      state: 0,
      pos: [3, 3, 0]
    },
    {
      state: 0,
      pos: [4, 3, 0]
    },
    {
      state: 0,
      pos: [1, 0, 1]
    },
    {
      state: 0,
      pos: [2, 0, 1]
    },
    {
      state: 0,
      pos: [3, 0, 1]
    },
    {
      state: 0,
      pos: [0, 1, 1]
    },
    {
      state: 0,
      pos: [4, 1, 1]
    },
    {
      state: 0,
      pos: [0, 2, 1]
    },
    {
      state: 0,
      pos: [4, 2, 1]
    },
    {
      state: 0,
      pos: [1, 3, 1]
    },
    {
      state: 0,
      pos: [2, 3, 1]
    },
    {
      state: 0,
      pos: [3, 3, 1]
    },
    {
      state: 0,
      pos: [1, 0, 2]
    },
    {
      state: 0,
      pos: [2, 0, 2]
    },
    {
      state: 0,
      pos: [3, 0, 2]
    },
    {
      state: 0,
      pos: [0, 1, 2]
    },
    {
      state: 0,
      pos: [4, 1, 2]
    },
    {
      state: 0,
      pos: [0, 2, 2]
    },
    {
      state: 0,
      pos: [4, 2, 2]
    },
    {
      state: 0,
      pos: [1, 3, 2]
    },
    {
      state: 0,
      pos: [2, 3, 2]
    },
    {
      state: 0,
      pos: [3, 3, 2]
    },
    {
      state: 0,
      pos: [1, 0, 3]
    },
    {
      state: 0,
      pos: [2, 0, 3]
    },
    {
      state: 0,
      pos: [3, 0, 3]
    },
    {
      state: 0,
      pos: [0, 1, 3]
    },
    {
      state: 0,
      pos: [4, 1, 3]
    },
    {
      state: 0,
      pos: [0, 2, 3]
    },
    {
      state: 0,
      pos: [4, 2, 3]
    },
    {
      state: 0,
      pos: [1, 3, 3]
    },
    {
      state: 0,
      pos: [2, 3, 3]
    },
    {
      state: 0,
      pos: [3, 3, 3]
    },
    {
      state: 0,
      pos: [1, 0, 4]
    },
    {
      state: 0,
      pos: [2, 0, 4]
    },
    {
      state: 0,
      pos: [3, 0, 4]
    },
    {
      state: 0,
      pos: [0, 1, 4]
    },
    {
      state: 0,
      pos: [1, 1, 4]
    },
    {
      state: 0,
      pos: [2, 1, 4]
    },
    {
      state: 0,
      pos: [3, 1, 4]
    },
    {
      state: 0,
      pos: [4, 1, 4]
    },
    {
      state: 0,
      pos: [0, 2, 4]
    },
    {
      state: 0,
      pos: [1, 2, 4]
    },
    {
      state: 0,
      pos: [2, 2, 4]
    },
    {
      state: 0,
      pos: [3, 2, 4]
    },
    {
      state: 0,
      pos: [4, 2, 4]
    }
  ],
  entities: [],
  version: 1,
  size: [5, 4, 5]
}