{
  author: "jeb_",
  palette: [
    {
      Name: "minecraft:air"
    },
    {
      Name: "minecraft:purpur_block"
    },
    {
      Name: "minecraft:purpur_pillar",
      Properties: {
        axis: "y"
      }
    },
    {
      Name: "minecraft:end_bricks"
    },
    {
      Name: "minecraft:structure_block",
      Properties: {
        mode: "save"
      }
    },
    {
      Name: "minecraft:stained_glass",
      Properties: {
        color: "magenta"
      }
    },
    {
      Name: "minecraft:purpur_stairs",
      Properties: {
        half: "bottom",
        facing: "north",
        shape: "straight"
      }
    }
  ],
  blocks: [
    {
      state: 0,
      pos: [0, 0, 0]
    },
    {
      state: 0,
      pos: [1, 0, 0]
    },
    {
      state: 0,
      pos: [2, 0, 0]
    },
    {
      state: 0,
      pos: [3, 0, 0]
    },
    {
      state: 0,
      pos: [4, 0, 0]
    },
    {
      state: 0,
      pos: [5, 0, 0]
    },
    {
      state: 0,
      pos: [6, 0, 0]
    },
    {
      state: 0,
      pos: [7, 0, 0]
    },
    {
      state: 0,
      pos: [8, 0, 0]
    },
    {
      state: 0,
      pos: [9, 0, 0]
    },
    {
      state: 0,
      pos: [0, 1, 0]
    },
    {
      state: 0,
      pos: [1, 1, 0]
    },
    {
      state: 0,
      pos: [2, 1, 0]
    },
    {
      state: 0,
      pos: [3, 1, 0]
    },
    {
      state: 0,
      pos: [4, 1, 0]
    },
    {
      state: 0,
      pos: [5, 1, 0]
    },
    {
      state: 0,
      pos: [6, 1, 0]
    },
    {
      state: 0,
      pos: [7, 1, 0]
    },
    {
      state: 0,
      pos: [8, 1, 0]
    },
    {
      state: 0,
      pos: [9, 1, 0]
    },
    {
      state: 0,
      pos: [0, 2, 0]
    },
    {
      state: 0,
      pos: [1, 2, 0]
    },
    {
      state: 0,
      pos: [2, 2, 0]
    },
    {
      state: 0,
      pos: [3, 2, 0]
    },
    {
      state: 0,
      pos: [4, 2, 0]
    },
    {
      state: 0,
      pos: [5, 2, 0]
    },
    {
      state: 0,
      pos: [6, 2, 0]
    },
    {
      state: 0,
      pos: [7, 2, 0]
    },
    {
      state: 0,
      pos: [8, 2, 0]
    },
    {
      state: 0,
      pos: [9, 2, 0]
    },
    {
      state: 0,
      pos: [0, 3, 0]
    },
    {
      state: 0,
      pos: [1, 3, 0]
    },
    {
      state: 0,
      pos: [2, 3, 0]
    },
    {
      state: 0,
      pos: [3, 3, 0]
    },
    {
      state: 0,
      pos: [4, 3, 0]
    },
    {
      state: 0,
      pos: [5, 3, 0]
    },
    {
      state: 0,
      pos: [6, 3, 0]
    },
    {
      state: 0,
      pos: [7, 3, 0]
    },
    {
      state: 0,
      pos: [8, 3, 0]
    },
    {
      state: 0,
      pos: [9, 3, 0]
    },
    {
      state: 0,
      pos: [0, 0, 1]
    },
    {
      state: 1,
      pos: [1, 0, 1]
    },
    {
      state: 1,
      pos: [2, 0, 1]
    },
    {
      state: 1,
      pos: [3, 0, 1]
    },
    {
      state: 1,
      pos: [4, 0, 1]
    },
    {
      state: 1,
      pos: [5, 0, 1]
    },
    {
      state: 1,
      pos: [6, 0, 1]
    },
    {
      state: 1,
      pos: [7, 0, 1]
    },
    {
      state: 1,
      pos: [8, 0, 1]
    },
    {
      state: 0,
      pos: [9, 0, 1]
    },
    {
      state: 0,
      pos: [0, 1, 1]
    },
    {
      state: 2,
      pos: [1, 1, 1]
    },
    {
      state: 3,
      pos: [2, 1, 1]
    },
    {
      state: 3,
      pos: [3, 1, 1]
    },
    {
      state: 3,
      pos: [4, 1, 1]
    },
    {
      state: 3,
      pos: [5, 1, 1]
    },
    {
      state: 3,
      pos: [6, 1, 1]
    },
    {
      state: 3,
      pos: [7, 1, 1]
    },
    {
      state: 2,
      pos: [8, 1, 1]
    },
    {
      state: 0,
      pos: [9, 1, 1]
    },
    {
      state: 0,
      pos: [0, 2, 1]
    },
    {
      state: 2,
      pos: [1, 2, 1]
    },
    {
      state: 3,
      pos: [2, 2, 1]
    },
    {
      state: 3,
      pos: [4, 2, 1]
    },
    {
      state: 3,
      pos: [5, 2, 1]
    },
    {
      state: 3,
      pos: [7, 2, 1]
    },
    {
      state: 2,
      pos: [8, 2, 1]
    },
    {
      state: 0,
      pos: [9, 2, 1]
    },
    {
      state: 0,
      pos: [0, 3, 1]
    },
    {
      state: 2,
      pos: [1, 3, 1]
    },
    {
      state: 3,
      pos: [2, 3, 1]
    },
    {
      state: 3,
      pos: [4, 3, 1]
    },
    {
      state: 3,
      pos: [5, 3, 1]
    },
    {
      state: 3,
      pos: [7, 3, 1]
    },
    {
      state: 2,
      pos: [8, 3, 1]
    },
    {
      state: 0,
      pos: [9, 3, 1]
    },
    {
      state: 0,
      pos: [0, 0, 2]
    },
    {
      state: 1,
      pos: [1, 0, 2]
    },
    {
      state: 1,
      pos: [2, 0, 2]
    },
    {
      state: 1,
      pos: [3, 0, 2]
    },
    {
      state: 1,
      pos: [4, 0, 2]
    },
    {
      state: 1,
      pos: [5, 0, 2]
    },
    {
      state: 1,
      pos: [6, 0, 2]
    },
    {
      state: 1,
      pos: [7, 0, 2]
    },
    {
      state: 1,
      pos: [8, 0, 2]
    },
    {
      state: 0,
      pos: [9, 0, 2]
    },
    {
      state: 0,
      pos: [0, 1, 2]
    },
    {
      state: 3,
      pos: [1, 1, 2]
    },
    {
      state: 0,
      pos: [2, 1, 2]
    },
    {
      state: 0,
      pos: [3, 1, 2]
    },
    {
      state: 0,
      pos: [4, 1, 2]
    },
    {
      state: 0,
      pos: [5, 1, 2]
    },
    {
      state: 0,
      pos: [6, 1, 2]
    },
    {
      state: 0,
      pos: [7, 1, 2]
    },
    {
      state: 3,
      pos: [8, 1, 2]
    },
    {
      state: 0,
      pos: [9, 1, 2]
    },
    {
      state: 0,
      pos: [0, 2, 2]
    },
    {
      state: 3,
      pos: [1, 2, 2]
    },
    {
      state: 0,
      pos: [2, 2, 2]
    },
    {
      state: 0,
      pos: [3, 2, 2]
    },
    {
      state: 0,
      pos: [4, 2, 2]
    },
    {
      state: 0,
      pos: [5, 2, 2]
    },
    {
      state: 0,
      pos: [6, 2, 2]
    },
    {
      state: 0,
      pos: [7, 2, 2]
    },
    {
      state: 3,
      pos: [8, 2, 2]
    },
    {
      state: 0,
      pos: [9, 2, 2]
    },
    {
      state: 0,
      pos: [0, 3, 2]
    },
    {
      state: 3,
      pos: [1, 3, 2]
    },
    {
      state: 0,
      pos: [2, 3, 2]
    },
    {
      state: 0,
      pos: [3, 3, 2]
    },
    {
      state: 0,
      pos: [4, 3, 2]
    },
    {
      state: 0,
      pos: [5, 3, 2]
    },
    {
      state: 0,
      pos: [6, 3, 2]
    },
    {
      state: 0,
      pos: [7, 3, 2]
    },
    {
      state: 3,
      pos: [8, 3, 2]
    },
    {
      state: 0,
      pos: [9, 3, 2]
    },
    {
      state: 0,
      pos: [0, 0, 3]
    },
    {
      state: 1,
      pos: [1, 0, 3]
    },
    {
      state: 1,
      pos: [2, 0, 3]
    },
    {
      state: 1,
      pos: [3, 0, 3]
    },
    {
      state: 1,
      pos: [4, 0, 3]
    },
    {
      state: 1,
      pos: [5, 0, 3]
    },
    {
      state: 1,
      pos: [6, 0, 3]
    },
    {
      state: 1,
      pos: [7, 0, 3]
    },
    {
      state: 1,
      pos: [8, 0, 3]
    },
    {
      state: 0,
      pos: [9, 0, 3]
    },
    {
      state: 0,
      pos: [0, 1, 3]
    },
    {
      state: 3,
      pos: [1, 1, 3]
    },
    {
      state: 0,
      pos: [2, 1, 3]
    },
    {
      state: 0,
      pos: [3, 1, 3]
    },
    {
      state: 0,
      pos: [4, 1, 3]
    },
    {
      state: 0,
      pos: [5, 1, 3]
    },
    {
      state: 0,
      pos: [6, 1, 3]
    },
    {
      state: 0,
      pos: [7, 1, 3]
    },
    {
      state: 3,
      pos: [8, 1, 3]
    },
    {
      state: 0,
      pos: [9, 1, 3]
    },
    {
      state: 0,
      pos: [0, 2, 3]
    },
    {
      state: 0,
      pos: [2, 2, 3]
    },
    {
      state: 0,
      pos: [3, 2, 3]
    },
    {
      state: 0,
      pos: [4, 2, 3]
    },
    {
      state: 0,
      pos: [5, 2, 3]
    },
    {
      state: 0,
      pos: [6, 2, 3]
    },
    {
      state: 0,
      pos: [7, 2, 3]
    },
    {
      state: 0,
      pos: [9, 2, 3]
    },
    {
      state: 0,
      pos: [0, 3, 3]
    },
    {
      state: 0,
      pos: [2, 3, 3]
    },
    {
      state: 0,
      pos: [3, 3, 3]
    },
    {
      state: 0,
      pos: [4, 3, 3]
    },
    {
      state: 0,
      pos: [5, 3, 3]
    },
    {
      state: 0,
      pos: [6, 3, 3]
    },
    {
      state: 0,
      pos: [7, 3, 3]
    },
    {
      state: 0,
      pos: [9, 3, 3]
    },
    {
      state: 0,
      pos: [0, 0, 4]
    },
    {
      state: 1,
      pos: [1, 0, 4]
    },
    {
      state: 1,
      pos: [2, 0, 4]
    },
    {
      state: 1,
      pos: [3, 0, 4]
    },
    {
      state: 1,
      pos: [4, 0, 4]
    },
    {
      state: 1,
      pos: [5, 0, 4]
    },
    {
      state: 1,
      pos: [6, 0, 4]
    },
    {
      state: 1,
      pos: [7, 0, 4]
    },
    {
      state: 1,
      pos: [8, 0, 4]
    },
    {
      state: 0,
      pos: [9, 0, 4]
    },
    {
      state: 0,
      pos: [0, 1, 4]
    },
    {
      state: 3,
      pos: [1, 1, 4]
    },
    {
      state: 0,
      pos: [2, 1, 4]
    },
    {
      state: 0,
      pos: [3, 1, 4]
    },
    {
      state: 0,
      pos: [4, 1, 4]
    },
    {
      state: 0,
      pos: [5, 1, 4]
    },
    {
      state: 0,
      pos: [6, 1, 4]
    },
    {
      state: 0,
      pos: [7, 1, 4]
    },
    {
      state: 3,
      pos: [8, 1, 4]
    },
    {
      state: 0,
      pos: [9, 1, 4]
    },
    {
      state: 0,
      pos: [0, 2, 4]
    },
    {
      state: 3,
      pos: [1, 2, 4]
    },
    {
      state: 0,
      pos: [2, 2, 4]
    },
    {
      state: 0,
      pos: [3, 2, 4]
    },
    {
      state: 0,
      pos: [4, 2, 4]
    },
    {
      state: 0,
      pos: [5, 2, 4]
    },
    {
      state: 0,
      pos: [6, 2, 4]
    },
    {
      state: 0,
      pos: [7, 2, 4]
    },
    {
      state: 3,
      pos: [8, 2, 4]
    },
    {
      state: 0,
      pos: [9, 2, 4]
    },
    {
      state: 0,
      pos: [0, 3, 4]
    },
    {
      state: 3,
      pos: [1, 3, 4]
    },
    {
      state: 0,
      pos: [2, 3, 4]
    },
    {
      state: 0,
      pos: [3, 3, 4]
    },
    {
      state: 0,
      pos: [4, 3, 4]
    },
    {
      state: 0,
      pos: [5, 3, 4]
    },
    {
      state: 0,
      pos: [6, 3, 4]
    },
    {
      state: 0,
      pos: [7, 3, 4]
    },
    {
      state: 3,
      pos: [8, 3, 4]
    },
    {
      state: 0,
      pos: [9, 3, 4]
    },
    {
      state: 0,
      pos: [0, 0, 5]
    },
    {
      state: 1,
      pos: [1, 0, 5]
    },
    {
      state: 1,
      pos: [2, 0, 5]
    },
    {
      state: 1,
      pos: [3, 0, 5]
    },
    {
      state: 1,
      pos: [4, 0, 5]
    },
    {
      state: 1,
      pos: [5, 0, 5]
    },
    {
      state: 1,
      pos: [6, 0, 5]
    },
    {
      state: 1,
      pos: [7, 0, 5]
    },
    {
      state: 1,
      pos: [8, 0, 5]
    },
    {
      state: 0,
      pos: [9, 0, 5]
    },
    {
      state: 0,
      pos: [0, 1, 5]
    },
    {
      state: 3,
      pos: [1, 1, 5]
    },
    {
      state: 0,
      pos: [2, 1, 5]
    },
    {
      state: 0,
      pos: [3, 1, 5]
    },
    {
      state: 0,
      pos: [4, 1, 5]
    },
    {
      state: 0,
      pos: [5, 1, 5]
    },
    {
      state: 0,
      pos: [6, 1, 5]
    },
    {
      state: 0,
      pos: [7, 1, 5]
    },
    {
      state: 3,
      pos: [8, 1, 5]
    },
    {
      state: 0,
      pos: [9, 1, 5]
    },
    {
      state: 0,
      pos: [0, 2, 5]
    },
    {
      state: 3,
      pos: [1, 2, 5]
    },
    {
      state: 0,
      pos: [2, 2, 5]
    },
    {
      state: 0,
      pos: [3, 2, 5]
    },
    {
      state: 0,
      pos: [4, 2, 5]
    },
    {
      state: 0,
      pos: [5, 2, 5]
    },
    {
      state: 0,
      pos: [6, 2, 5]
    },
    {
      state: 0,
      pos: [7, 2, 5]
    },
    {
      state: 3,
      pos: [8, 2, 5]
    },
    {
      state: 0,
      pos: [9, 2, 5]
    },
    {
      state: 0,
      pos: [0, 3, 5]
    },
    {
      state: 3,
      pos: [1, 3, 5]
    },
    {
      state: 0,
      pos: [2, 3, 5]
    },
    {
      state: 0,
      pos: [3, 3, 5]
    },
    {
      state: 0,
      pos: [4, 3, 5]
    },
    {
      state: 0,
      pos: [5, 3, 5]
    },
    {
      state: 0,
      pos: [6, 3, 5]
    },
    {
      state: 0,
      pos: [7, 3, 5]
    },
    {
      state: 3,
      pos: [8, 3, 5]
    },
    {
      state: 0,
      pos: [9, 3, 5]
    },
    {
      state: 0,
      pos: [0, 0, 6]
    },
    {
      state: 1,
      pos: [1, 0, 6]
    },
    {
      state: 1,
      pos: [2, 0, 6]
    },
    {
      state: 1,
      pos: [3, 0, 6]
    },
    {
      state: 1,
      pos: [4, 0, 6]
    },
    {
      state: 1,
      pos: [5, 0, 6]
    },
    {
      state: 1,
      pos: [6, 0, 6]
    },
    {
      state: 1,
      pos: [7, 0, 6]
    },
    {
      state: 1,
      pos: [8, 0, 6]
    },
    {
      state: 0,
      pos: [9, 0, 6]
    },
    {
      state: 0,
      pos: [0, 1, 6]
    },
    {
      state: 3,
      pos: [1, 1, 6]
    },
    {
      state: 0,
      pos: [2, 1, 6]
    },
    {
      state: 0,
      pos: [3, 1, 6]
    },
    {
      state: 0,
      pos: [4, 1, 6]
    },
    {
      state: 0,
      pos: [5, 1, 6]
    },
    {
      state: 0,
      pos: [6, 1, 6]
    },
    {
      state: 0,
      pos: [7, 1, 6]
    },
    {
      state: 3,
      pos: [8, 1, 6]
    },
    {
      state: 0,
      pos: [9, 1, 6]
    },
    {
      state: 0,
      pos: [0, 2, 6]
    },
    {
      state: 0,
      pos: [2, 2, 6]
    },
    {
      state: 0,
      pos: [3, 2, 6]
    },
    {
      state: 0,
      pos: [4, 2, 6]
    },
    {
      state: 0,
      pos: [5, 2, 6]
    },
    {
      state: 0,
      pos: [6, 2, 6]
    },
    {
      state: 0,
      pos: [7, 2, 6]
    },
    {
      state: 0,
      pos: [9, 2, 6]
    },
    {
      state: 0,
      pos: [0, 3, 6]
    },
    {
      state: 0,
      pos: [2, 3, 6]
    },
    {
      state: 0,
      pos: [3, 3, 6]
    },
    {
      state: 0,
      pos: [4, 3, 6]
    },
    {
      state: 0,
      pos: [5, 3, 6]
    },
    {
      state: 0,
      pos: [6, 3, 6]
    },
    {
      state: 0,
      pos: [7, 3, 6]
    },
    {
      state: 0,
      pos: [9, 3, 6]
    },
    {
      state: 0,
      pos: [0, 0, 7]
    },
    {
      state: 1,
      pos: [1, 0, 7]
    },
    {
      state: 1,
      pos: [2, 0, 7]
    },
    {
      state: 1,
      pos: [3, 0, 7]
    },
    {
      state: 1,
      pos: [4, 0, 7]
    },
    {
      state: 1,
      pos: [5, 0, 7]
    },
    {
      state: 1,
      pos: [6, 0, 7]
    },
    {
      state: 1,
      pos: [7, 0, 7]
    },
    {
      state: 1,
      pos: [8, 0, 7]
    },
    {
      state: 0,
      pos: [9, 0, 7]
    },
    {
      state: 0,
      pos: [0, 1, 7]
    },
    {
      state: 3,
      pos: [1, 1, 7]
    },
    {
      state: 0,
      pos: [2, 1, 7]
    },
    {
      state: 0,
      pos: [3, 1, 7]
    },
    {
      state: 0,
      pos: [4, 1, 7]
    },
    {
      state: 0,
      pos: [5, 1, 7]
    },
    {
      state: 0,
      pos: [6, 1, 7]
    },
    {
      state: 0,
      pos: [7, 1, 7]
    },
    {
      state: 3,
      pos: [8, 1, 7]
    },
    {
      state: 0,
      pos: [9, 1, 7]
    },
    {
      state: 0,
      pos: [0, 2, 7]
    },
    {
      state: 3,
      pos: [1, 2, 7]
    },
    {
      state: 0,
      pos: [2, 2, 7]
    },
    {
      state: 0,
      pos: [3, 2, 7]
    },
    {
      state: 0,
      pos: [4, 2, 7]
    },
    {
      state: 0,
      pos: [5, 2, 7]
    },
    {
      state: 0,
      pos: [6, 2, 7]
    },
    {
      state: 0,
      pos: [7, 2, 7]
    },
    {
      state: 3,
      pos: [8, 2, 7]
    },
    {
      state: 0,
      pos: [9, 2, 7]
    },
    {
      state: 0,
      pos: [0, 3, 7]
    },
    {
      state: 3,
      pos: [1, 3, 7]
    },
    {
      state: 0,
      pos: [2, 3, 7]
    },
    {
      state: 0,
      pos: [3, 3, 7]
    },
    {
      state: 0,
      pos: [4, 3, 7]
    },
    {
      state: 0,
      pos: [5, 3, 7]
    },
    {
      state: 0,
      pos: [6, 3, 7]
    },
    {
      state: 0,
      pos: [7, 3, 7]
    },
    {
      state: 3,
      pos: [8, 3, 7]
    },
    {
      state: 0,
      pos: [9, 3, 7]
    },
    {
      state: 0,
      pos: [0, 0, 8]
    },
    {
      state: 1,
      pos: [1, 0, 8]
    },
    {
      state: 1,
      pos: [2, 0, 8]
    },
    {
      state: 1,
      pos: [3, 0, 8]
    },
    {
      state: 1,
      pos: [4, 0, 8]
    },
    {
      state: 1,
      pos: [5, 0, 8]
    },
    {
      state: 1,
      pos: [6, 0, 8]
    },
    {
      state: 1,
      pos: [7, 0, 8]
    },
    {
      state: 1,
      pos: [8, 0, 8]
    },
    {
      state: 0,
      pos: [9, 0, 8]
    },
    {
      state: 0,
      pos: [0, 1, 8]
    },
    {
      state: 2,
      pos: [1, 1, 8]
    },
    {
      state: 3,
      pos: [2, 1, 8]
    },
    {
      state: 3,
      pos: [3, 1, 8]
    },
    {
      state: 0,
      pos: [4, 1, 8]
    },
    {
      state: 0,
      pos: [5, 1, 8]
    },
    {
      state: 3,
      pos: [6, 1, 8]
    },
    {
      state: 3,
      pos: [7, 1, 8]
    },
    {
      state: 2,
      pos: [8, 1, 8]
    },
    {
      state: 0,
      pos: [9, 1, 8]
    },
    {
      state: 0,
      pos: [0, 2, 8]
    },
    {
      state: 2,
      pos: [1, 2, 8]
    },
    {
      state: 3,
      pos: [2, 2, 8]
    },
    {
      state: 3,
      pos: [3, 2, 8]
    },
    {
      state: 0,
      pos: [4, 2, 8]
    },
    {
      state: 0,
      pos: [5, 2, 8]
    },
    {
      state: 3,
      pos: [6, 2, 8]
    },
    {
      state: 3,
      pos: [7, 2, 8]
    },
    {
      state: 2,
      pos: [8, 2, 8]
    },
    {
      state: 0,
      pos: [9, 2, 8]
    },
    {
      state: 0,
      pos: [0, 3, 8]
    },
    {
      state: 2,
      pos: [1, 3, 8]
    },
    {
      state: 3,
      pos: [2, 3, 8]
    },
    {
      state: 3,
      pos: [3, 3, 8]
    },
    {
      state: 0,
      pos: [4, 3, 8]
    },
    {
      state: 0,
      pos: [5, 3, 8]
    },
    {
      state: 3,
      pos: [6, 3, 8]
    },
    {
      state: 3,
      pos: [7, 3, 8]
    },
    {
      state: 2,
      pos: [8, 3, 8]
    },
    {
      state: 0,
      pos: [9, 3, 8]
    },
    {
      state: 0,
      pos: [0, 0, 9]
    },
    {
      state: 0,
      pos: [1, 0, 9]
    },
    {
      state: 1,
      pos: [3, 0, 9]
    },
    {
      state: 1,
      pos: [4, 0, 9]
    },
    {
      state: 1,
      pos: [5, 0, 9]
    },
    {
      state: 1,
      pos: [6, 0, 9]
    },
    {
      state: 0,
      pos: [8, 0, 9]
    },
    {
      state: 0,
      pos: [9, 0, 9]
    },
    {
      state: 0,
      pos: [0, 1, 9]
    },
    {
      state: 0,
      pos: [1, 1, 9]
    },
    {
      state: 0,
      pos: [2, 1, 9]
    },
    {
      state: 0,
      pos: [3, 1, 9]
    },
    {
      state: 0,
      pos: [4, 1, 9]
    },
    {
      state: 0,
      pos: [5, 1, 9]
    },
    {
      state: 0,
      pos: [6, 1, 9]
    },
    {
      state: 0,
      pos: [7, 1, 9]
    },
    {
      state: 0,
      pos: [8, 1, 9]
    },
    {
      state: 0,
      pos: [9, 1, 9]
    },
    {
      state: 0,
      pos: [0, 2, 9]
    },
    {
      state: 0,
      pos: [1, 2, 9]
    },
    {
      state: 0,
      pos: [2, 2, 9]
    },
    {
      state: 0,
      pos: [4, 2, 9]
    },
    {
      state: 0,
      pos: [5, 2, 9]
    },
    {
      state: 0,
      pos: [7, 2, 9]
    },
    {
      state: 0,
      pos: [8, 2, 9]
    },
    {
      state: 0,
      pos: [9, 2, 9]
    },
    {
      state: 0,
      pos: [0, 3, 9]
    },
    {
      state: 0,
      pos: [1, 3, 9]
    },
    {
      state: 0,
      pos: [2, 3, 9]
    },
    {
      state: 0,
      pos: [3, 3, 9]
    },
    {
      state: 0,
      pos: [4, 3, 9]
    },
    {
      state: 0,
      pos: [5, 3, 9]
    },
    {
      state: 0,
      pos: [6, 3, 9]
    },
    {
      state: 0,
      pos: [7, 3, 9]
    },
    {
      state: 0,
      pos: [8, 3, 9]
    },
    {
      state: 0,
      pos: [9, 3, 9]
    },
    {
      state: 4,
      nbt: {
        sizeZ: 0,
        posY: 1,
        posX: 1,
        sizeY: 0,
        posZ: 1,
        sizeX: 0,
        mode: "DATA",
        mirror: "NONE",
        id: "Structure",
        author: "jeb_",
        rotation: "NONE",
        name: "",
        ignoreEntities: 0b,
        metadata: "Sentry"
      },
      pos: [3, 2, 9]
    },
    {
      state: 4,
      nbt: {
        sizeZ: 0,
        posY: 1,
        posX: 1,
        sizeY: 0,
        posZ: 1,
        sizeX: 0,
        mode: "DATA",
        mirror: "NONE",
        id: "Structure",
        author: "jeb_",
        rotation: "NONE",
        name: "",
        ignoreEntities: 0b,
        metadata: "Sentry"
      },
      pos: [6, 2, 9]
    },
    {
      state: 5,
      pos: [3, 2, 1]
    },
    {
      state: 5,
      pos: [6, 2, 1]
    },
    {
      state: 5,
      pos: [3, 3, 1]
    },
    {
      state: 5,
      pos: [6, 3, 1]
    },
    {
      state: 5,
      pos: [1, 2, 3]
    },
    {
      state: 5,
      pos: [8, 2, 3]
    },
    {
      state: 5,
      pos: [1, 3, 3]
    },
    {
      state: 5,
      pos: [8, 3, 3]
    },
    {
      state: 5,
      pos: [1, 2, 6]
    },
    {
      state: 5,
      pos: [8, 2, 6]
    },
    {
      state: 5,
      pos: [1, 3, 6]
    },
    {
      state: 5,
      pos: [8, 3, 6]
    },
    {
      state: 6,
      pos: [2, 0, 9]
    },
    {
      state: 6,
      pos: [7, 0, 9]
    }
  ],
  entities: [],
  version: 1,
  size: [10, 4, 10]
}