{
  author: "jeb_",
  palette: [
    {
      Name: "minecraft:air"
    },
    {
      Name: "minecraft:purpur_block"
    },
    {
      Name: "minecraft:purpur_pillar",
      Properties: {
        axis: "y"
      }
    },
    {
      Name: "minecraft:purpur_stairs",
      Properties: {
        half: "top",
        facing: "east",
        shape: "straight"
      }
    },
    {
      Name: "minecraft:purpur_stairs",
      Properties: {
        half: "top",
        facing: "south",
        shape: "straight"
      }
    },
    {
      Name: "minecraft:purpur_stairs",
      Properties: {
        half: "top",
        facing: "west",
        shape: "straight"
      }
    },
    {
      Name: "minecraft:purpur_slab",
      Properties: {
        half: "bottom",
        variant: "default"
      }
    },
    {
      Name: "minecraft:purpur_stairs",
      Properties: {
        half: "top",
        facing: "north",
        shape: "straight"
      }
    }
  ],
  blocks: [
    {
      state: 0,
      pos: [0, 0, 0]
    },
    {
      state: 0,
      pos: [6, 0, 0]
    },
    {
      state: 0,
      pos: [0, 1, 0]
    },
    {
      state: 0,
      pos: [1, 1, 0]
    },
    {
      state: 0,
      pos: [2, 1, 0]
    },
    {
      state: 0,
      pos: [3, 1, 0]
    },
    {
      state: 0,
      pos: [4, 1, 0]
    },
    {
      state: 0,
      pos: [5, 1, 0]
    },
    {
      state: 0,
      pos: [6, 1, 0]
    },
    {
      state: 0,
      pos: [0, 2, 0]
    },
    {
      state: 0,
      pos: [1, 2, 0]
    },
    {
      state: 0,
      pos: [2, 2, 0]
    },
    {
      state: 0,
      pos: [4, 2, 0]
    },
    {
      state: 0,
      pos: [5, 2, 0]
    },
    {
      state: 0,
      pos: [6, 2, 0]
    },
    {
      state: 0,
      pos: [0, 3, 0]
    },
    {
      state: 0,
      pos: [1, 3, 0]
    },
    {
      state: 0,
      pos: [2, 3, 0]
    },
    {
      state: 0,
      pos: [3, 3, 0]
    },
    {
      state: 0,
      pos: [4, 3, 0]
    },
    {
      state: 0,
      pos: [5, 3, 0]
    },
    {
      state: 0,
      pos: [6, 3, 0]
    },
    {
      state: 1,
      pos: [2, 0, 1]
    },
    {
      state: 1,
      pos: [3, 0, 1]
    },
    {
      state: 1,
      pos: [4, 0, 1]
    },
    {
      state: 0,
      pos: [0, 1, 1]
    },
    {
      state: 0,
      pos: [1, 1, 1]
    },
    {
      state: 2,
      pos: [2, 1, 1]
    },
    {
      state: 2,
      pos: [3, 1, 1]
    },
    {
      state: 2,
      pos: [4, 1, 1]
    },
    {
      state: 0,
      pos: [5, 1, 1]
    },
    {
      state: 0,
      pos: [6, 1, 1]
    },
    {
      state: 0,
      pos: [0, 2, 1]
    },
    {
      state: 0,
      pos: [1, 2, 1]
    },
    {
      state: 2,
      pos: [2, 2, 1]
    },
    {
      state: 2,
      pos: [3, 2, 1]
    },
    {
      state: 2,
      pos: [4, 2, 1]
    },
    {
      state: 0,
      pos: [5, 2, 1]
    },
    {
      state: 0,
      pos: [6, 2, 1]
    },
    {
      state: 0,
      pos: [0, 3, 1]
    },
    {
      state: 0,
      pos: [1, 3, 1]
    },
    {
      state: 2,
      pos: [2, 3, 1]
    },
    {
      state: 2,
      pos: [3, 3, 1]
    },
    {
      state: 2,
      pos: [4, 3, 1]
    },
    {
      state: 0,
      pos: [5, 3, 1]
    },
    {
      state: 0,
      pos: [6, 3, 1]
    },
    {
      state: 1,
      pos: [1, 0, 2]
    },
    {
      state: 1,
      pos: [2, 0, 2]
    },
    {
      state: 1,
      pos: [3, 0, 2]
    },
    {
      state: 1,
      pos: [4, 0, 2]
    },
    {
      state: 1,
      pos: [5, 0, 2]
    },
    {
      state: 0,
      pos: [0, 1, 2]
    },
    {
      state: 2,
      pos: [1, 1, 2]
    },
    {
      state: 0,
      pos: [2, 1, 2]
    },
    {
      state: 0,
      pos: [4, 1, 2]
    },
    {
      state: 2,
      pos: [5, 1, 2]
    },
    {
      state: 0,
      pos: [6, 1, 2]
    },
    {
      state: 0,
      pos: [0, 2, 2]
    },
    {
      state: 2,
      pos: [1, 2, 2]
    },
    {
      state: 0,
      pos: [2, 2, 2]
    },
    {
      state: 0,
      pos: [3, 2, 2]
    },
    {
      state: 0,
      pos: [4, 2, 2]
    },
    {
      state: 2,
      pos: [5, 2, 2]
    },
    {
      state: 0,
      pos: [6, 2, 2]
    },
    {
      state: 0,
      pos: [0, 3, 2]
    },
    {
      state: 2,
      pos: [1, 3, 2]
    },
    {
      state: 0,
      pos: [2, 3, 2]
    },
    {
      state: 0,
      pos: [3, 3, 2]
    },
    {
      state: 0,
      pos: [4, 3, 2]
    },
    {
      state: 2,
      pos: [5, 3, 2]
    },
    {
      state: 0,
      pos: [6, 3, 2]
    },
    {
      state: 1,
      pos: [1, 0, 3]
    },
    {
      state: 1,
      pos: [2, 0, 3]
    },
    {
      state: 1,
      pos: [3, 0, 3]
    },
    {
      state: 1,
      pos: [4, 0, 3]
    },
    {
      state: 1,
      pos: [5, 0, 3]
    },
    {
      state: 0,
      pos: [0, 1, 3]
    },
    {
      state: 2,
      pos: [1, 1, 3]
    },
    {
      state: 0,
      pos: [2, 1, 3]
    },
    {
      state: 0,
      pos: [3, 1, 3]
    },
    {
      state: 0,
      pos: [4, 1, 3]
    },
    {
      state: 2,
      pos: [5, 1, 3]
    },
    {
      state: 0,
      pos: [6, 1, 3]
    },
    {
      state: 2,
      pos: [1, 2, 3]
    },
    {
      state: 0,
      pos: [2, 2, 3]
    },
    {
      state: 0,
      pos: [3, 2, 3]
    },
    {
      state: 2,
      pos: [5, 2, 3]
    },
    {
      state: 0,
      pos: [0, 3, 3]
    },
    {
      state: 2,
      pos: [1, 3, 3]
    },
    {
      state: 0,
      pos: [2, 3, 3]
    },
    {
      state: 0,
      pos: [3, 3, 3]
    },
    {
      state: 0,
      pos: [4, 3, 3]
    },
    {
      state: 2,
      pos: [5, 3, 3]
    },
    {
      state: 0,
      pos: [6, 3, 3]
    },
    {
      state: 1,
      pos: [1, 0, 4]
    },
    {
      state: 1,
      pos: [2, 0, 4]
    },
    {
      state: 1,
      pos: [3, 0, 4]
    },
    {
      state: 1,
      pos: [4, 0, 4]
    },
    {
      state: 1,
      pos: [5, 0, 4]
    },
    {
      state: 0,
      pos: [0, 1, 4]
    },
    {
      state: 2,
      pos: [1, 1, 4]
    },
    {
      state: 0,
      pos: [2, 1, 4]
    },
    {
      state: 0,
      pos: [3, 1, 4]
    },
    {
      state: 0,
      pos: [4, 1, 4]
    },
    {
      state: 2,
      pos: [5, 1, 4]
    },
    {
      state: 0,
      pos: [6, 1, 4]
    },
    {
      state: 0,
      pos: [0, 2, 4]
    },
    {
      state: 2,
      pos: [1, 2, 4]
    },
    {
      state: 0,
      pos: [2, 2, 4]
    },
    {
      state: 0,
      pos: [3, 2, 4]
    },
    {
      state: 0,
      pos: [4, 2, 4]
    },
    {
      state: 2,
      pos: [5, 2, 4]
    },
    {
      state: 0,
      pos: [6, 2, 4]
    },
    {
      state: 0,
      pos: [0, 3, 4]
    },
    {
      state: 2,
      pos: [1, 3, 4]
    },
    {
      state: 0,
      pos: [2, 3, 4]
    },
    {
      state: 0,
      pos: [4, 3, 4]
    },
    {
      state: 2,
      pos: [5, 3, 4]
    },
    {
      state: 0,
      pos: [6, 3, 4]
    },
    {
      state: 1,
      pos: [2, 0, 5]
    },
    {
      state: 1,
      pos: [3, 0, 5]
    },
    {
      state: 1,
      pos: [4, 0, 5]
    },
    {
      state: 0,
      pos: [0, 1, 5]
    },
    {
      state: 0,
      pos: [1, 1, 5]
    },
    {
      state: 2,
      pos: [2, 1, 5]
    },
    {
      state: 2,
      pos: [3, 1, 5]
    },
    {
      state: 2,
      pos: [4, 1, 5]
    },
    {
      state: 0,
      pos: [5, 1, 5]
    },
    {
      state: 0,
      pos: [6, 1, 5]
    },
    {
      state: 0,
      pos: [0, 2, 5]
    },
    {
      state: 0,
      pos: [1, 2, 5]
    },
    {
      state: 2,
      pos: [2, 2, 5]
    },
    {
      state: 2,
      pos: [3, 2, 5]
    },
    {
      state: 2,
      pos: [4, 2, 5]
    },
    {
      state: 0,
      pos: [5, 2, 5]
    },
    {
      state: 0,
      pos: [6, 2, 5]
    },
    {
      state: 0,
      pos: [0, 3, 5]
    },
    {
      state: 0,
      pos: [1, 3, 5]
    },
    {
      state: 2,
      pos: [2, 3, 5]
    },
    {
      state: 2,
      pos: [3, 3, 5]
    },
    {
      state: 2,
      pos: [4, 3, 5]
    },
    {
      state: 0,
      pos: [5, 3, 5]
    },
    {
      state: 0,
      pos: [6, 3, 5]
    },
    {
      state: 0,
      pos: [0, 0, 6]
    },
    {
      state: 0,
      pos: [6, 0, 6]
    },
    {
      state: 0,
      pos: [0, 1, 6]
    },
    {
      state: 0,
      pos: [1, 1, 6]
    },
    {
      state: 0,
      pos: [2, 1, 6]
    },
    {
      state: 0,
      pos: [3, 1, 6]
    },
    {
      state: 0,
      pos: [4, 1, 6]
    },
    {
      state: 0,
      pos: [5, 1, 6]
    },
    {
      state: 0,
      pos: [6, 1, 6]
    },
    {
      state: 0,
      pos: [0, 2, 6]
    },
    {
      state: 0,
      pos: [1, 2, 6]
    },
    {
      state: 0,
      pos: [2, 2, 6]
    },
    {
      state: 0,
      pos: [4, 2, 6]
    },
    {
      state: 0,
      pos: [5, 2, 6]
    },
    {
      state: 0,
      pos: [6, 2, 6]
    },
    {
      state: 0,
      pos: [0, 3, 6]
    },
    {
      state: 0,
      pos: [1, 3, 6]
    },
    {
      state: 0,
      pos: [2, 3, 6]
    },
    {
      state: 0,
      pos: [3, 3, 6]
    },
    {
      state: 0,
      pos: [4, 3, 6]
    },
    {
      state: 0,
      pos: [5, 3, 6]
    },
    {
      state: 0,
      pos: [6, 3, 6]
    },
    {
      state: 3,
      pos: [1, 0, 0]
    },
    {
      state: 4,
      pos: [2, 0, 0]
    },
    {
      state: 4,
      pos: [3, 0, 0]
    },
    {
      state: 4,
      pos: [4, 0, 0]
    },
    {
      state: 5,
      pos: [5, 0, 0]
    },
    {
      state: 4,
      pos: [3, 2, 0]
    },
    {
      state: 4,
      pos: [0, 0, 1]
    },
    {
      state: 3,
      pos: [1, 0, 1]
    },
    {
      state: 4,
      pos: [5, 0, 1]
    },
    {
      state: 4,
      pos: [6, 0, 1]
    },
    {
      state: 3,
      pos: [0, 0, 2]
    },
    {
      state: 5,
      pos: [6, 0, 2]
    },
    {
      state: 6,
      pos: [3, 1, 2]
    },
    {
      state: 3,
      pos: [0, 0, 3]
    },
    {
      state: 5,
      pos: [6, 0, 3]
    },
    {
      state: 3,
      pos: [0, 2, 3]
    },
    {
      state: 6,
      pos: [4, 2, 3]
    },
    {
      state: 5,
      pos: [6, 2, 3]
    },
    {
      state: 3,
      pos: [0, 0, 4]
    },
    {
      state: 5,
      pos: [6, 0, 4]
    },
    {
      state: 6,
      pos: [3, 3, 4]
    },
    {
      state: 7,
      pos: [0, 0, 5]
    },
    {
      state: 7,
      pos: [1, 0, 5]
    },
    {
      state: 5,
      pos: [5, 0, 5]
    },
    {
      state: 7,
      pos: [6, 0, 5]
    },
    {
      state: 3,
      pos: [1, 0, 6]
    },
    {
      state: 7,
      pos: [2, 0, 6]
    },
    {
      state: 7,
      pos: [3, 0, 6]
    },
    {
      state: 7,
      pos: [4, 0, 6]
    },
    {
      state: 5,
      pos: [5, 0, 6]
    },
    {
      state: 7,
      pos: [3, 2, 6]
    }
  ],
  entities: [],
  version: 1,
  size: [7, 4, 7]
}