{
  author: "ProfMobius",
  palette: [
    {
      Name: "minecraft:coal_ore"
    }
  ],
  blocks: [
    {
      state: 0,
      pos: [1, 1, 0]
    },
    {
      state: 0,
      pos: [4, 1, 0]
    },
    {
      state: 0,
      pos: [1, 2, 0]
    },
    {
      state: 0,
      pos: [2, 2, 0]
    },
    {
      state: 0,
      pos: [3, 2, 0]
    },
    {
      state: 0,
      pos: [4, 2, 0]
    },
    {
      state: 0,
      pos: [2, 3, 0]
    },
    {
      state: 0,
      pos: [3, 3, 0]
    },
    {
      state: 0,
      pos: [1, 0, 1]
    },
    {
      state: 0,
      pos: [2, 0, 1]
    },
    {
      state: 0,
      pos: [3, 0, 1]
    },
    {
      state: 0,
      pos: [4, 0, 1]
    },
    {
      state: 0,
      pos: [0, 1, 1]
    },
    {
      state: 0,
      pos: [5, 1, 1]
    },
    {
      state: 0,
      pos: [0, 2, 1]
    },
    {
      state: 0,
      pos: [5, 2, 1]
    },
    {
      state: 0,
      pos: [0, 3, 1]
    },
    {
      state: 0,
      pos: [5, 3, 1]
    },
    {
      state: 0,
      pos: [1, 4, 1]
    },
    {
      state: 0,
      pos: [2, 4, 1]
    },
    {
      state: 0,
      pos: [3, 4, 1]
    },
    {
      state: 0,
      pos: [4, 4, 1]
    },
    {
      state: 0,
      pos: [1, 0, 2]
    },
    {
      state: 0,
      pos: [2, 0, 2]
    },
    {
      state: 0,
      pos: [3, 0, 2]
    },
    {
      state: 0,
      pos: [4, 0, 2]
    },
    {
      state: 0,
      pos: [0, 1, 2]
    },
    {
      state: 0,
      pos: [5, 1, 2]
    },
    {
      state: 0,
      pos: [0, 2, 2]
    },
    {
      state: 0,
      pos: [5, 2, 2]
    },
    {
      state: 0,
      pos: [0, 3, 2]
    },
    {
      state: 0,
      pos: [5, 3, 2]
    },
    {
      state: 0,
      pos: [1, 4, 2]
    },
    {
      state: 0,
      pos: [2, 4, 2]
    },
    {
      state: 0,
      pos: [3, 4, 2]
    },
    {
      state: 0,
      pos: [4, 4, 2]
    },
    {
      state: 0,
      pos: [1, 0, 3]
    },
    {
      state: 0,
      pos: [2, 0, 3]
    },
    {
      state: 0,
      pos: [3, 0, 3]
    },
    {
      state: 0,
      pos: [4, 0, 3]
    },
    {
      state: 0,
      pos: [0, 1, 3]
    },
    {
      state: 0,
      pos: [5, 1, 3]
    },
    {
      state: 0,
      pos: [0, 2, 3]
    },
    {
      state: 0,
      pos: [5, 2, 3]
    },
    {
      state: 0,
      pos: [0, 3, 3]
    },
    {
      state: 0,
      pos: [5, 3, 3]
    },
    {
      state: 0,
      pos: [1, 4, 3]
    },
    {
      state: 0,
      pos: [2, 4, 3]
    },
    {
      state: 0,
      pos: [3, 4, 3]
    },
    {
      state: 0,
      pos: [4, 4, 3]
    },
    {
      state: 0,
      pos: [1, 0, 4]
    },
    {
      state: 0,
      pos: [4, 0, 4]
    },
    {
      state: 0,
      pos: [0, 1, 4]
    },
    {
      state: 0,
      pos: [5, 1, 4]
    },
    {
      state: 0,
      pos: [0, 2, 4]
    },
    {
      state: 0,
      pos: [5, 2, 4]
    },
    {
      state: 0,
      pos: [0, 3, 4]
    },
    {
      state: 0,
      pos: [5, 3, 4]
    },
    {
      state: 0,
      pos: [1, 4, 4]
    },
    {
      state: 0,
      pos: [2, 4, 4]
    },
    {
      state: 0,
      pos: [3, 4, 4]
    },
    {
      state: 0,
      pos: [4, 4, 4]
    },
    {
      state: 0,
      pos: [1, 0, 5]
    },
    {
      state: 0,
      pos: [4, 0, 5]
    },
    {
      state: 0,
      pos: [0, 1, 5]
    },
    {
      state: 0,
      pos: [5, 1, 5]
    },
    {
      state: 0,
      pos: [0, 2, 5]
    },
    {
      state: 0,
      pos: [5, 2, 5]
    },
    {
      state: 0,
      pos: [0, 3, 5]
    },
    {
      state: 0,
      pos: [5, 3, 5]
    },
    {
      state: 0,
      pos: [1, 4, 5]
    },
    {
      state: 0,
      pos: [2, 4, 5]
    },
    {
      state: 0,
      pos: [3, 4, 5]
    },
    {
      state: 0,
      pos: [4, 4, 5]
    },
    {
      state: 0,
      pos: [1, 1, 6]
    },
    {
      state: 0,
      pos: [2, 1, 6]
    },
    {
      state: 0,
      pos: [3, 1, 6]
    },
    {
      state: 0,
      pos: [4, 1, 6]
    },
    {
      state: 0,
      pos: [1, 2, 6]
    },
    {
      state: 0,
      pos: [2, 2, 6]
    },
    {
      state: 0,
      pos: [3, 2, 6]
    },
    {
      state: 0,
      pos: [4, 2, 6]
    },
    {
      state: 0,
      pos: [1, 3, 6]
    },
    {
      state: 0,
      pos: [2, 3, 6]
    },
    {
      state: 0,
      pos: [3, 3, 6]
    },
    {
      state: 0,
      pos: [4, 3, 6]
    }
  ],
  entities: [],
  version: 1,
  size: [6, 5, 7]
}