{
  author: "ProfMobius",
  palette: [
    {
      Name: "minecraft:coal_ore"
    }
  ],
  blocks: [
    {
      state: 0,
      pos: [1, 2, 0]
    },
    {
      state: 0,
      pos: [0, 0, 1]
    },
    {
      state: 0,
      pos: [2, 0, 1]
    },
    {
      state: 0,
      pos: [0, 1, 1]
    },
    {
      state: 0,
      pos: [2, 1, 1]
    },
    {
      state: 0,
      pos: [1, 2, 1]
    },
    {
      state: 0,
      pos: [1, 2, 2]
    },
    {
      state: 0,
      pos: [0, 0, 3]
    },
    {
      state: 0,
      pos: [2, 0, 3]
    },
    {
      state: 0,
      pos: [0, 1, 3]
    },
    {
      state: 0,
      pos: [2, 1, 3]
    },
    {
      state: 0,
      pos: [1, 2, 3]
    },
    {
      state: 0,
      pos: [1, 2, 4]
    },
    {
      state: 0,
      pos: [0, 0, 5]
    },
    {
      state: 0,
      pos: [2, 0, 5]
    },
    {
      state: 0,
      pos: [0, 1, 5]
    },
    {
      state: 0,
      pos: [2, 1, 5]
    },
    {
      state: 0,
      pos: [1, 2, 5]
    },
    {
      state: 0,
      pos: [1, 2, 6]
    },
    {
      state: 0,
      pos: [0, 0, 7]
    },
    {
      state: 0,
      pos: [2, 0, 7]
    },
    {
      state: 0,
      pos: [0, 1, 7]
    },
    {
      state: 0,
      pos: [2, 1, 7]
    },
    {
      state: 0,
      pos: [1, 2, 7]
    },
    {
      state: 0,
      pos: [1, 2, 8]
    },
    {
      state: 0,
      pos: [0, 0, 9]
    },
    {
      state: 0,
      pos: [2, 0, 9]
    },
    {
      state: 0,
      pos: [0, 1, 9]
    },
    {
      state: 0,
      pos: [2, 1, 9]
    },
    {
      state: 0,
      pos: [1, 2, 9]
    },
    {
      state: 0,
      pos: [1, 2, 10]
    },
    {
      state: 0,
      pos: [0, 0, 11]
    },
    {
      state: 0,
      pos: [2, 0, 11]
    },
    {
      state: 0,
      pos: [0, 1, 11]
    },
    {
      state: 0,
      pos: [2, 1, 11]
    },
    {
      state: 0,
      pos: [1, 2, 11]
    },
    {
      state: 0,
      pos: [1, 2, 12]
    }
  ],
  entities: [],
  version: 1,
  size: [3, 3, 13]
}