{
  size: [7, 11, 15],
  entities: [],
  blocks: [
    {
      pos: [0, 0, 0],
      state: 0
    },
    {
      pos: [1, 0, 0],
      state: 0
    },
    {
      pos: [2, 0, 0],
      state: 0
    },
    {
      pos: [3, 0, 0],
      state: 0
    },
    {
      pos: [4, 0, 0],
      state: 0
    },
    {
      pos: [5, 0, 0],
      state: 0
    },
    {
      pos: [6, 0, 0],
      state: 0
    },
    {
      pos: [1, 1, 0],
      state: 1
    },
    {
      pos: [2, 1, 0],
      state: 1
    },
    {
      pos: [3, 1, 0],
      state: 1
    },
    {
      pos: [4, 1, 0],
      state: 1
    },
    {
      pos: [5, 1, 0],
      state: 1
    },
    {
      pos: [6, 1, 0],
      state: 1
    },
    {
      pos: [6, 2, 0],
      state: 2
    },
    {
      pos: [1, 6, 0],
      state: 1
    },
    {
      pos: [5, 6, 0],
      state: 1
    },
    {
      pos: [0, 0, 1],
      state: 0
    },
    {
      pos: [1, 0, 1],
      state: 0
    },
    {
      pos: [2, 0, 1],
      state: 0
    },
    {
      pos: [3, 0, 1],
      state: 0
    },
    {
      pos: [4, 0, 1],
      state: 0
    },
    {
      pos: [5, 0, 1],
      state: 0
    },
    {
      pos: [6, 0, 1],
      state: 0
    },
    {
      pos: [2, 1, 1],
      state: 3
    },
    {
      pos: [3, 1, 1],
      state: 3
    },
    {
      pos: [4, 1, 1],
      state: 3
    },
    {
      pos: [0, 0, 2],
      state: 0
    },
    {
      pos: [1, 0, 2],
      state: 0
    },
    {
      pos: [2, 0, 2],
      state: 0
    },
    {
      pos: [3, 0, 2],
      state: 0
    },
    {
      pos: [4, 0, 2],
      state: 0
    },
    {
      pos: [5, 0, 2],
      state: 0
    },
    {
      pos: [6, 0, 2],
      state: 0
    },
    {
      pos: [2, 1, 2],
      state: 3
    },
    {
      pos: [3, 1, 2],
      state: 3
    },
    {
      pos: [4, 1, 2],
      state: 3
    },
    {
      pos: [0, 0, 3],
      state: 0
    },
    {
      pos: [1, 0, 3],
      state: 0
    },
    {
      pos: [2, 0, 3],
      state: 0
    },
    {
      pos: [3, 0, 3],
      state: 0
    },
    {
      pos: [4, 0, 3],
      state: 0
    },
    {
      pos: [5, 0, 3],
      state: 0
    },
    {
      pos: [6, 0, 3],
      state: 0
    },
    {
      pos: [2, 1, 3],
      state: 3
    },
    {
      pos: [3, 1, 3],
      state: 3
    },
    {
      pos: [4, 1, 3],
      state: 3
    },
    {
      pos: [0, 0, 4],
      state: 0
    },
    {
      pos: [1, 0, 4],
      state: 0
    },
    {
      pos: [2, 0, 4],
      state: 0
    },
    {
      pos: [3, 0, 4],
      state: 0
    },
    {
      pos: [4, 0, 4],
      state: 0
    },
    {
      pos: [5, 0, 4],
      state: 0
    },
    {
      pos: [6, 0, 4],
      state: 0
    },
    {
      pos: [2, 1, 4],
      state: 3
    },
    {
      pos: [3, 1, 4],
      state: 3
    },
    {
      pos: [4, 1, 4],
      state: 3
    },
    {
      pos: [0, 0, 5],
      state: 0
    },
    {
      pos: [1, 0, 5],
      state: 0
    },
    {
      pos: [2, 0, 5],
      state: 0
    },
    {
      pos: [3, 0, 5],
      state: 0
    },
    {
      pos: [4, 0, 5],
      state: 0
    },
    {
      pos: [5, 0, 5],
      state: 0
    },
    {
      pos: [6, 0, 5],
      state: 0
    },
    {
      pos: [1, 1, 5],
      state: 1
    },
    {
      pos: [5, 1, 5],
      state: 1
    },
    {
      pos: [1, 6, 5],
      state: 1
    },
    {
      pos: [5, 6, 5],
      state: 1
    },
    {
      pos: [0, 0, 6],
      state: 0
    },
    {
      pos: [1, 0, 6],
      state: 0
    },
    {
      pos: [2, 0, 6],
      state: 0
    },
    {
      pos: [3, 0, 6],
      state: 0
    },
    {
      pos: [4, 0, 6],
      state: 0
    },
    {
      pos: [5, 0, 6],
      state: 0
    },
    {
      pos: [6, 0, 6],
      state: 0
    },
    {
      pos: [0, 0, 7],
      state: 0
    },
    {
      pos: [1, 0, 7],
      state: 0
    },
    {
      pos: [2, 0, 7],
      state: 0
    },
    {
      pos: [3, 0, 7],
      state: 0
    },
    {
      pos: [4, 0, 7],
      state: 0
    },
    {
      pos: [5, 0, 7],
      state: 0
    },
    {
      pos: [6, 0, 7],
      state: 0
    },
    {
      pos: [0, 0, 8],
      state: 0
    },
    {
      pos: [1, 0, 8],
      state: 0
    },
    {
      pos: [2, 0, 8],
      state: 0
    },
    {
      pos: [3, 0, 8],
      state: 0
    },
    {
      pos: [4, 0, 8],
      state: 0
    },
    {
      pos: [5, 0, 8],
      state: 0
    },
    {
      pos: [6, 0, 8],
      state: 0
    },
    {
      pos: [0, 0, 9],
      state: 0
    },
    {
      pos: [1, 0, 9],
      state: 0
    },
    {
      pos: [2, 0, 9],
      state: 0
    },
    {
      pos: [3, 0, 9],
      state: 0
    },
    {
      pos: [4, 0, 9],
      state: 0
    },
    {
      pos: [5, 0, 9],
      state: 0
    },
    {
      pos: [6, 0, 9],
      state: 0
    },
    {
      pos: [0, 0, 10],
      state: 0
    },
    {
      pos: [1, 0, 10],
      state: 0
    },
    {
      pos: [2, 0, 10],
      state: 0
    },
    {
      pos: [3, 0, 10],
      state: 0
    },
    {
      pos: [4, 0, 10],
      state: 0
    },
    {
      pos: [5, 0, 10],
      state: 0
    },
    {
      pos: [6, 0, 10],
      state: 0
    },
    {
      pos: [0, 0, 11],
      state: 0
    },
    {
      pos: [1, 0, 11],
      state: 0
    },
    {
      pos: [2, 0, 11],
      state: 0
    },
    {
      pos: [3, 0, 11],
      state: 0
    },
    {
      pos: [4, 0, 11],
      state: 0
    },
    {
      pos: [5, 0, 11],
      state: 0
    },
    {
      pos: [6, 0, 11],
      state: 0
    },
    {
      pos: [6, 1, 11],
      state: 1
    },
    {
      pos: [0, 0, 12],
      state: 0
    },
    {
      pos: [1, 0, 12],
      state: 0
    },
    {
      pos: [2, 0, 12],
      state: 0
    },
    {
      pos: [3, 0, 12],
      state: 0
    },
    {
      pos: [4, 0, 12],
      state: 0
    },
    {
      pos: [5, 0, 12],
      state: 0
    },
    {
      pos: [6, 0, 12],
      state: 0
    },
    {
      pos: [0, 0, 13],
      state: 0
    },
    {
      pos: [1, 0, 13],
      state: 0
    },
    {
      pos: [2, 0, 13],
      state: 0
    },
    {
      pos: [3, 0, 13],
      state: 0
    },
    {
      pos: [4, 0, 13],
      state: 0
    },
    {
      pos: [5, 0, 13],
      state: 0
    },
    {
      pos: [6, 0, 13],
      state: 0
    },
    {
      pos: [0, 0, 14],
      state: 0
    },
    {
      pos: [1, 0, 14],
      state: 0
    },
    {
      pos: [2, 0, 14],
      state: 0
    },
    {
      pos: [3, 0, 14],
      state: 0
    },
    {
      pos: [4, 0, 14],
      state: 0
    },
    {
      pos: [5, 0, 14],
      state: 0
    },
    {
      pos: [6, 0, 14],
      state: 0
    },
    {
      pos: [2, 7, 14],
      state: 0
    },
    {
      pos: [3, 7, 14],
      state: 0
    },
    {
      pos: [4, 7, 14],
      state: 0
    },
    {
      pos: [2, 8, 14],
      state: 0
    },
    {
      pos: [3, 8, 14],
      state: 0
    },
    {
      pos: [4, 8, 14],
      state: 0
    },
    {
      pos: [3, 9, 14],
      state: 0
    },
    {
      nbt: {
        Item: "minecraft:red_flower",
        Data: 8,
        id: "FlowerPot"
      },
      pos: [4, 2, 0],
      state: 4
    },
    {
      nbt: {
        Item: "minecraft:sapling",
        Data: 2,
        id: "FlowerPot"
      },
      pos: [6, 2, 12],
      state: 4
    },
    {
      nbt: {
        id: "Banner",
        Patterns: [
          {
            Pattern: "flo",
            Color: 15
          }
        ],
        Base: 7
      },
      pos: [2, 7, 13],
      state: 5
    },
    {
      nbt: {
        id: "Banner",
        Patterns: [
          {
            Pattern: "flo",
            Color: 15
          }
        ],
        Base: 7
      },
      pos: [4, 7, 13],
      state: 5
    },
    {
      nbt: {
        id: "Banner",
        Patterns: [
          {
            Pattern: "flo",
            Color: 15
          }
        ],
        Base: 7
      },
      pos: [3, 8, 13],
      state: 5
    },
    {
      pos: [0, 1, 0],
      state: 6
    },
    {
      pos: [0, 2, 0],
      state: 6
    },
    {
      pos: [1, 2, 0],
      state: 7
    },
    {
      pos: [2, 2, 0],
      state: 6
    },
    {
      pos: [3, 2, 0],
      state: 6
    },
    {
      pos: [5, 2, 0],
      state: 7
    },
    {
      pos: [0, 3, 0],
      state: 6
    },
    {
      pos: [1, 3, 0],
      state: 7
    },
    {
      pos: [2, 3, 0],
      state: 6
    },
    {
      pos: [3, 3, 0],
      state: 6
    },
    {
      pos: [4, 3, 0],
      state: 6
    },
    {
      pos: [5, 3, 0],
      state: 7
    },
    {
      pos: [6, 3, 0],
      state: 6
    },
    {
      pos: [0, 4, 0],
      state: 6
    },
    {
      pos: [1, 4, 0],
      state: 7
    },
    {
      pos: [2, 4, 0],
      state: 6
    },
    {
      pos: [3, 4, 0],
      state: 6
    },
    {
      pos: [4, 4, 0],
      state: 6
    },
    {
      pos: [5, 4, 0],
      state: 7
    },
    {
      pos: [6, 4, 0],
      state: 6
    },
    {
      pos: [0, 5, 0],
      state: 6
    },
    {
      pos: [1, 5, 0],
      state: 7
    },
    {
      pos: [2, 5, 0],
      state: 6
    },
    {
      pos: [3, 5, 0],
      state: 6
    },
    {
      pos: [4, 5, 0],
      state: 6
    },
    {
      pos: [5, 5, 0],
      state: 7
    },
    {
      pos: [6, 5, 0],
      state: 6
    },
    {
      pos: [0, 6, 0],
      state: 6
    },
    {
      pos: [2, 6, 0],
      state: 8
    },
    {
      pos: [3, 6, 0],
      state: 8
    },
    {
      pos: [4, 6, 0],
      state: 8
    },
    {
      pos: [6, 6, 0],
      state: 6
    },
    {
      pos: [0, 7, 0],
      state: 6
    },
    {
      pos: [1, 7, 0],
      state: 6
    },
    {
      pos: [2, 7, 0],
      state: 6
    },
    {
      pos: [3, 7, 0],
      state: 6
    },
    {
      pos: [4, 7, 0],
      state: 6
    },
    {
      pos: [5, 7, 0],
      state: 6
    },
    {
      pos: [6, 7, 0],
      state: 6
    },
    {
      pos: [0, 8, 0],
      state: 6
    },
    {
      pos: [1, 8, 0],
      state: 6
    },
    {
      pos: [2, 8, 0],
      state: 6
    },
    {
      pos: [3, 8, 0],
      state: 6
    },
    {
      pos: [4, 8, 0],
      state: 6
    },
    {
      pos: [5, 8, 0],
      state: 6
    },
    {
      pos: [6, 8, 0],
      state: 6
    },
    {
      pos: [0, 9, 0],
      state: 6
    },
    {
      pos: [1, 9, 0],
      state: 6
    },
    {
      pos: [2, 9, 0],
      state: 6
    },
    {
      pos: [3, 9, 0],
      state: 6
    },
    {
      pos: [4, 9, 0],
      state: 6
    },
    {
      pos: [5, 9, 0],
      state: 6
    },
    {
      pos: [6, 9, 0],
      state: 6
    },
    {
      pos: [0, 10, 0],
      state: 6
    },
    {
      pos: [1, 10, 0],
      state: 6
    },
    {
      pos: [2, 10, 0],
      state: 6
    },
    {
      pos: [3, 10, 0],
      state: 6
    },
    {
      pos: [4, 10, 0],
      state: 6
    },
    {
      pos: [5, 10, 0],
      state: 6
    },
    {
      pos: [6, 10, 0],
      state: 6
    },
    {
      pos: [0, 1, 1],
      state: 6
    },
    {
      pos: [1, 1, 1],
      state: 9
    },
    {
      pos: [5, 1, 1],
      state: 10
    },
    {
      pos: [6, 1, 1],
      state: 6
    },
    {
      pos: [0, 2, 1],
      state: 6
    },
    {
      pos: [1, 2, 1],
      state: 6
    },
    {
      pos: [2, 2, 1],
      state: 6
    },
    {
      pos: [3, 2, 1],
      state: 6
    },
    {
      pos: [4, 2, 1],
      state: 6
    },
    {
      pos: [5, 2, 1],
      state: 6
    },
    {
      pos: [6, 2, 1],
      state: 6
    },
    {
      pos: [0, 3, 1],
      state: 6
    },
    {
      pos: [1, 3, 1],
      state: 6
    },
    {
      pos: [2, 3, 1],
      state: 6
    },
    {
      pos: [3, 3, 1],
      state: 6
    },
    {
      pos: [4, 3, 1],
      state: 6
    },
    {
      pos: [5, 3, 1],
      state: 6
    },
    {
      pos: [6, 3, 1],
      state: 6
    },
    {
      pos: [0, 4, 1],
      state: 6
    },
    {
      pos: [1, 4, 1],
      state: 6
    },
    {
      pos: [2, 4, 1],
      state: 6
    },
    {
      pos: [3, 4, 1],
      state: 6
    },
    {
      pos: [4, 4, 1],
      state: 6
    },
    {
      pos: [5, 4, 1],
      state: 6
    },
    {
      pos: [6, 4, 1],
      state: 6
    },
    {
      pos: [0, 5, 1],
      state: 6
    },
    {
      pos: [1, 5, 1],
      state: 6
    },
    {
      pos: [2, 5, 1],
      state: 6
    },
    {
      pos: [3, 5, 1],
      state: 6
    },
    {
      pos: [4, 5, 1],
      state: 6
    },
    {
      pos: [5, 5, 1],
      state: 6
    },
    {
      pos: [6, 5, 1],
      state: 6
    },
    {
      pos: [0, 6, 1],
      state: 6
    },
    {
      pos: [1, 6, 1],
      state: 8
    },
    {
      pos: [2, 6, 1],
      state: 8
    },
    {
      pos: [3, 6, 1],
      state: 8
    },
    {
      pos: [4, 6, 1],
      state: 8
    },
    {
      pos: [5, 6, 1],
      state: 8
    },
    {
      pos: [6, 6, 1],
      state: 6
    },
    {
      pos: [0, 7, 1],
      state: 6
    },
    {
      pos: [1, 7, 1],
      state: 6
    },
    {
      pos: [2, 7, 1],
      state: 6
    },
    {
      pos: [3, 7, 1],
      state: 6
    },
    {
      pos: [4, 7, 1],
      state: 6
    },
    {
      pos: [5, 7, 1],
      state: 6
    },
    {
      pos: [6, 7, 1],
      state: 6
    },
    {
      pos: [0, 8, 1],
      state: 6
    },
    {
      pos: [1, 8, 1],
      state: 6
    },
    {
      pos: [2, 8, 1],
      state: 6
    },
    {
      pos: [3, 8, 1],
      state: 6
    },
    {
      pos: [4, 8, 1],
      state: 6
    },
    {
      pos: [5, 8, 1],
      state: 6
    },
    {
      pos: [6, 8, 1],
      state: 6
    },
    {
      pos: [0, 9, 1],
      state: 6
    },
    {
      pos: [1, 9, 1],
      state: 6
    },
    {
      pos: [2, 9, 1],
      state: 6
    },
    {
      pos: [3, 9, 1],
      state: 6
    },
    {
      pos: [4, 9, 1],
      state: 6
    },
    {
      pos: [5, 9, 1],
      state: 6
    },
    {
      pos: [6, 9, 1],
      state: 6
    },
    {
      pos: [0, 10, 1],
      state: 6
    },
    {
      pos: [1, 10, 1],
      state: 6
    },
    {
      pos: [2, 10, 1],
      state: 6
    },
    {
      pos: [3, 10, 1],
      state: 6
    },
    {
      pos: [4, 10, 1],
      state: 6
    },
    {
      pos: [5, 10, 1],
      state: 6
    },
    {
      pos: [6, 10, 1],
      state: 6
    },
    {
      pos: [0, 1, 2],
      state: 6
    },
    {
      pos: [1, 1, 2],
      state: 9
    },
    {
      pos: [5, 1, 2],
      state: 10
    },
    {
      pos: [6, 1, 2],
      state: 6
    },
    {
      pos: [0, 2, 2],
      state: 6
    },
    {
      pos: [1, 2, 2],
      state: 6
    },
    {
      pos: [2, 2, 2],
      state: 11
    },
    {
      pos: [3, 2, 2],
      state: 11
    },
    {
      pos: [4, 2, 2],
      state: 11
    },
    {
      pos: [5, 2, 2],
      state: 6
    },
    {
      pos: [6, 2, 2],
      state: 6
    },
    {
      pos: [0, 3, 2],
      state: 6
    },
    {
      pos: [1, 3, 2],
      state: 6
    },
    {
      pos: [2, 3, 2],
      state: 6
    },
    {
      pos: [3, 3, 2],
      state: 6
    },
    {
      pos: [4, 3, 2],
      state: 6
    },
    {
      pos: [5, 3, 2],
      state: 6
    },
    {
      pos: [6, 3, 2],
      state: 6
    },
    {
      pos: [0, 4, 2],
      state: 6
    },
    {
      pos: [1, 4, 2],
      state: 6
    },
    {
      pos: [2, 4, 2],
      state: 6
    },
    {
      pos: [3, 4, 2],
      state: 6
    },
    {
      pos: [4, 4, 2],
      state: 6
    },
    {
      pos: [5, 4, 2],
      state: 6
    },
    {
      pos: [6, 4, 2],
      state: 6
    },
    {
      pos: [0, 5, 2],
      state: 6
    },
    {
      pos: [1, 5, 2],
      state: 6
    },
    {
      pos: [2, 5, 2],
      state: 6
    },
    {
      pos: [3, 5, 2],
      state: 6
    },
    {
      pos: [4, 5, 2],
      state: 6
    },
    {
      pos: [5, 5, 2],
      state: 6
    },
    {
      pos: [6, 5, 2],
      state: 6
    },
    {
      pos: [0, 6, 2],
      state: 6
    },
    {
      pos: [1, 6, 2],
      state: 8
    },
    {
      pos: [2, 6, 2],
      state: 8
    },
    {
      pos: [3, 6, 2],
      state: 8
    },
    {
      pos: [4, 6, 2],
      state: 8
    },
    {
      pos: [5, 6, 2],
      state: 8
    },
    {
      pos: [6, 6, 2],
      state: 6
    },
    {
      pos: [0, 7, 2],
      state: 6
    },
    {
      pos: [1, 7, 2],
      state: 6
    },
    {
      pos: [2, 7, 2],
      state: 6
    },
    {
      pos: [3, 7, 2],
      state: 6
    },
    {
      pos: [4, 7, 2],
      state: 6
    },
    {
      pos: [5, 7, 2],
      state: 6
    },
    {
      pos: [6, 7, 2],
      state: 6
    },
    {
      pos: [0, 8, 2],
      state: 6
    },
    {
      pos: [1, 8, 2],
      state: 6
    },
    {
      pos: [2, 8, 2],
      state: 6
    },
    {
      pos: [3, 8, 2],
      state: 6
    },
    {
      pos: [4, 8, 2],
      state: 6
    },
    {
      pos: [5, 8, 2],
      state: 6
    },
    {
      pos: [6, 8, 2],
      state: 6
    },
    {
      pos: [0, 9, 2],
      state: 6
    },
    {
      pos: [1, 9, 2],
      state: 6
    },
    {
      pos: [2, 9, 2],
      state: 6
    },
    {
      pos: [3, 9, 2],
      state: 6
    },
    {
      pos: [4, 9, 2],
      state: 6
    },
    {
      pos: [5, 9, 2],
      state: 6
    },
    {
      pos: [6, 9, 2],
      state: 6
    },
    {
      pos: [0, 10, 2],
      state: 6
    },
    {
      pos: [1, 10, 2],
      state: 6
    },
    {
      pos: [2, 10, 2],
      state: 6
    },
    {
      pos: [3, 10, 2],
      state: 6
    },
    {
      pos: [4, 10, 2],
      state: 6
    },
    {
      pos: [5, 10, 2],
      state: 6
    },
    {
      pos: [6, 10, 2],
      state: 6
    },
    {
      pos: [0, 1, 3],
      state: 6
    },
    {
      pos: [1, 1, 3],
      state: 9
    },
    {
      pos: [5, 1, 3],
      state: 10
    },
    {
      pos: [6, 1, 3],
      state: 6
    },
    {
      pos: [0, 2, 3],
      state: 6
    },
    {
      pos: [1, 2, 3],
      state: 6
    },
    {
      pos: [2, 2, 3],
      state: 11
    },
    {
      pos: [3, 2, 3],
      state: 11
    },
    {
      pos: [4, 2, 3],
      state: 11
    },
    {
      pos: [5, 2, 3],
      state: 6
    },
    {
      pos: [6, 2, 3],
      state: 6
    },
    {
      pos: [0, 3, 3],
      state: 6
    },
    {
      pos: [1, 3, 3],
      state: 6
    },
    {
      pos: [2, 3, 3],
      state: 6
    },
    {
      pos: [3, 3, 3],
      state: 6
    },
    {
      pos: [4, 3, 3],
      state: 6
    },
    {
      pos: [5, 3, 3],
      state: 6
    },
    {
      pos: [6, 3, 3],
      state: 6
    },
    {
      pos: [0, 4, 3],
      state: 6
    },
    {
      pos: [1, 4, 3],
      state: 6
    },
    {
      pos: [2, 4, 3],
      state: 6
    },
    {
      pos: [3, 4, 3],
      state: 6
    },
    {
      pos: [4, 4, 3],
      state: 6
    },
    {
      pos: [5, 4, 3],
      state: 6
    },
    {
      pos: [6, 4, 3],
      state: 6
    },
    {
      pos: [0, 5, 3],
      state: 6
    },
    {
      pos: [1, 5, 3],
      state: 6
    },
    {
      pos: [2, 5, 3],
      state: 6
    },
    {
      pos: [3, 5, 3],
      state: 6
    },
    {
      pos: [4, 5, 3],
      state: 6
    },
    {
      pos: [5, 5, 3],
      state: 6
    },
    {
      pos: [6, 5, 3],
      state: 6
    },
    {
      pos: [0, 6, 3],
      state: 6
    },
    {
      pos: [1, 6, 3],
      state: 8
    },
    {
      pos: [2, 6, 3],
      state: 8
    },
    {
      pos: [3, 6, 3],
      state: 8
    },
    {
      pos: [4, 6, 3],
      state: 8
    },
    {
      pos: [5, 6, 3],
      state: 8
    },
    {
      pos: [6, 6, 3],
      state: 6
    },
    {
      pos: [0, 7, 3],
      state: 6
    },
    {
      pos: [1, 7, 3],
      state: 6
    },
    {
      pos: [2, 7, 3],
      state: 6
    },
    {
      pos: [3, 7, 3],
      state: 6
    },
    {
      pos: [4, 7, 3],
      state: 6
    },
    {
      pos: [5, 7, 3],
      state: 6
    },
    {
      pos: [6, 7, 3],
      state: 6
    },
    {
      pos: [0, 8, 3],
      state: 6
    },
    {
      pos: [1, 8, 3],
      state: 6
    },
    {
      pos: [2, 8, 3],
      state: 6
    },
    {
      pos: [3, 8, 3],
      state: 6
    },
    {
      pos: [4, 8, 3],
      state: 6
    },
    {
      pos: [5, 8, 3],
      state: 6
    },
    {
      pos: [6, 8, 3],
      state: 6
    },
    {
      pos: [0, 9, 3],
      state: 6
    },
    {
      pos: [1, 9, 3],
      state: 6
    },
    {
      pos: [2, 9, 3],
      state: 6
    },
    {
      pos: [3, 9, 3],
      state: 6
    },
    {
      pos: [4, 9, 3],
      state: 6
    },
    {
      pos: [5, 9, 3],
      state: 6
    },
    {
      pos: [6, 9, 3],
      state: 6
    },
    {
      pos: [0, 10, 3],
      state: 6
    },
    {
      pos: [1, 10, 3],
      state: 6
    },
    {
      pos: [2, 10, 3],
      state: 6
    },
    {
      pos: [3, 10, 3],
      state: 6
    },
    {
      pos: [4, 10, 3],
      state: 6
    },
    {
      pos: [5, 10, 3],
      state: 6
    },
    {
      pos: [6, 10, 3],
      state: 6
    },
    {
      pos: [0, 1, 4],
      state: 6
    },
    {
      pos: [1, 1, 4],
      state: 9
    },
    {
      pos: [5, 1, 4],
      state: 10
    },
    {
      pos: [6, 1, 4],
      state: 6
    },
    {
      pos: [0, 2, 4],
      state: 6
    },
    {
      pos: [1, 2, 4],
      state: 6
    },
    {
      pos: [2, 2, 4],
      state: 11
    },
    {
      pos: [3, 2, 4],
      state: 11
    },
    {
      pos: [4, 2, 4],
      state: 11
    },
    {
      pos: [5, 2, 4],
      state: 6
    },
    {
      pos: [6, 2, 4],
      state: 6
    },
    {
      pos: [0, 3, 4],
      state: 6
    },
    {
      pos: [1, 3, 4],
      state: 6
    },
    {
      pos: [2, 3, 4],
      state: 6
    },
    {
      pos: [3, 3, 4],
      state: 6
    },
    {
      pos: [4, 3, 4],
      state: 6
    },
    {
      pos: [5, 3, 4],
      state: 6
    },
    {
      pos: [6, 3, 4],
      state: 6
    },
    {
      pos: [0, 4, 4],
      state: 6
    },
    {
      pos: [1, 4, 4],
      state: 6
    },
    {
      pos: [2, 4, 4],
      state: 6
    },
    {
      pos: [3, 4, 4],
      state: 6
    },
    {
      pos: [4, 4, 4],
      state: 6
    },
    {
      pos: [5, 4, 4],
      state: 6
    },
    {
      pos: [6, 4, 4],
      state: 6
    },
    {
      pos: [0, 5, 4],
      state: 6
    },
    {
      pos: [1, 5, 4],
      state: 6
    },
    {
      pos: [2, 5, 4],
      state: 6
    },
    {
      pos: [3, 5, 4],
      state: 6
    },
    {
      pos: [4, 5, 4],
      state: 6
    },
    {
      pos: [5, 5, 4],
      state: 6
    },
    {
      pos: [6, 5, 4],
      state: 6
    },
    {
      pos: [0, 6, 4],
      state: 6
    },
    {
      pos: [1, 6, 4],
      state: 8
    },
    {
      pos: [2, 6, 4],
      state: 8
    },
    {
      pos: [3, 6, 4],
      state: 8
    },
    {
      pos: [4, 6, 4],
      state: 8
    },
    {
      pos: [5, 6, 4],
      state: 8
    },
    {
      pos: [6, 6, 4],
      state: 6
    },
    {
      pos: [0, 7, 4],
      state: 6
    },
    {
      pos: [1, 7, 4],
      state: 6
    },
    {
      pos: [2, 7, 4],
      state: 6
    },
    {
      pos: [3, 7, 4],
      state: 6
    },
    {
      pos: [4, 7, 4],
      state: 6
    },
    {
      pos: [5, 7, 4],
      state: 6
    },
    {
      pos: [6, 7, 4],
      state: 6
    },
    {
      pos: [0, 8, 4],
      state: 6
    },
    {
      pos: [1, 8, 4],
      state: 6
    },
    {
      pos: [2, 8, 4],
      state: 6
    },
    {
      pos: [3, 8, 4],
      state: 6
    },
    {
      pos: [4, 8, 4],
      state: 6
    },
    {
      pos: [5, 8, 4],
      state: 6
    },
    {
      pos: [6, 8, 4],
      state: 6
    },
    {
      pos: [0, 9, 4],
      state: 6
    },
    {
      pos: [1, 9, 4],
      state: 6
    },
    {
      pos: [2, 9, 4],
      state: 6
    },
    {
      pos: [3, 9, 4],
      state: 6
    },
    {
      pos: [4, 9, 4],
      state: 6
    },
    {
      pos: [5, 9, 4],
      state: 6
    },
    {
      pos: [6, 9, 4],
      state: 6
    },
    {
      pos: [0, 10, 4],
      state: 6
    },
    {
      pos: [1, 10, 4],
      state: 6
    },
    {
      pos: [2, 10, 4],
      state: 6
    },
    {
      pos: [3, 10, 4],
      state: 6
    },
    {
      pos: [4, 10, 4],
      state: 6
    },
    {
      pos: [5, 10, 4],
      state: 6
    },
    {
      pos: [6, 10, 4],
      state: 6
    },
    {
      pos: [0, 1, 5],
      state: 6
    },
    {
      pos: [2, 1, 5],
      state: 12
    },
    {
      pos: [3, 1, 5],
      state: 12
    },
    {
      pos: [4, 1, 5],
      state: 12
    },
    {
      pos: [6, 1, 5],
      state: 6
    },
    {
      pos: [0, 2, 5],
      state: 6
    },
    {
      pos: [1, 2, 5],
      state: 7
    },
    {
      pos: [2, 2, 5],
      state: 6
    },
    {
      pos: [3, 2, 5],
      state: 6
    },
    {
      pos: [4, 2, 5],
      state: 6
    },
    {
      pos: [5, 2, 5],
      state: 7
    },
    {
      pos: [6, 2, 5],
      state: 6
    },
    {
      pos: [0, 3, 5],
      state: 6
    },
    {
      pos: [1, 3, 5],
      state: 7
    },
    {
      pos: [2, 3, 5],
      state: 6
    },
    {
      pos: [3, 3, 5],
      state: 6
    },
    {
      pos: [4, 3, 5],
      state: 6
    },
    {
      pos: [5, 3, 5],
      state: 7
    },
    {
      pos: [6, 3, 5],
      state: 6
    },
    {
      pos: [0, 4, 5],
      state: 6
    },
    {
      pos: [1, 4, 5],
      state: 7
    },
    {
      pos: [2, 4, 5],
      state: 6
    },
    {
      pos: [3, 4, 5],
      state: 6
    },
    {
      pos: [4, 4, 5],
      state: 6
    },
    {
      pos: [5, 4, 5],
      state: 7
    },
    {
      pos: [6, 4, 5],
      state: 6
    },
    {
      pos: [0, 5, 5],
      state: 6
    },
    {
      pos: [1, 5, 5],
      state: 7
    },
    {
      pos: [2, 5, 5],
      state: 6
    },
    {
      pos: [3, 5, 5],
      state: 6
    },
    {
      pos: [4, 5, 5],
      state: 6
    },
    {
      pos: [5, 5, 5],
      state: 7
    },
    {
      pos: [6, 5, 5],
      state: 6
    },
    {
      pos: [0, 6, 5],
      state: 6
    },
    {
      pos: [2, 6, 5],
      state: 8
    },
    {
      pos: [3, 6, 5],
      state: 8
    },
    {
      pos: [4, 6, 5],
      state: 8
    },
    {
      pos: [6, 6, 5],
      state: 6
    },
    {
      pos: [0, 7, 5],
      state: 6
    },
    {
      pos: [1, 7, 5],
      state: 6
    },
    {
      pos: [2, 7, 5],
      state: 6
    },
    {
      pos: [3, 7, 5],
      state: 6
    },
    {
      pos: [4, 7, 5],
      state: 6
    },
    {
      pos: [5, 7, 5],
      state: 6
    },
    {
      pos: [6, 7, 5],
      state: 6
    },
    {
      pos: [0, 8, 5],
      state: 6
    },
    {
      pos: [1, 8, 5],
      state: 6
    },
    {
      pos: [2, 8, 5],
      state: 6
    },
    {
      pos: [3, 8, 5],
      state: 6
    },
    {
      pos: [4, 8, 5],
      state: 6
    },
    {
      pos: [5, 8, 5],
      state: 6
    },
    {
      pos: [6, 8, 5],
      state: 6
    },
    {
      pos: [0, 9, 5],
      state: 6
    },
    {
      pos: [1, 9, 5],
      state: 6
    },
    {
      pos: [2, 9, 5],
      state: 6
    },
    {
      pos: [3, 9, 5],
      state: 6
    },
    {
      pos: [4, 9, 5],
      state: 6
    },
    {
      pos: [5, 9, 5],
      state: 6
    },
    {
      pos: [6, 9, 5],
      state: 6
    },
    {
      pos: [0, 10, 5],
      state: 6
    },
    {
      pos: [1, 10, 5],
      state: 6
    },
    {
      pos: [2, 10, 5],
      state: 6
    },
    {
      pos: [3, 10, 5],
      state: 6
    },
    {
      pos: [4, 10, 5],
      state: 6
    },
    {
      pos: [5, 10, 5],
      state: 6
    },
    {
      pos: [6, 10, 5],
      state: 6
    },
    {
      pos: [0, 1, 6],
      state: 6
    },
    {
      pos: [1, 1, 6],
      state: 6
    },
    {
      pos: [2, 1, 6],
      state: 6
    },
    {
      pos: [3, 1, 6],
      state: 6
    },
    {
      pos: [4, 1, 6],
      state: 6
    },
    {
      pos: [5, 1, 6],
      state: 6
    },
    {
      pos: [6, 1, 6],
      state: 6
    },
    {
      pos: [0, 2, 6],
      state: 6
    },
    {
      pos: [1, 2, 6],
      state: 6
    },
    {
      pos: [2, 2, 6],
      state: 6
    },
    {
      pos: [3, 2, 6],
      state: 6
    },
    {
      pos: [4, 2, 6],
      state: 6
    },
    {
      pos: [5, 2, 6],
      state: 6
    },
    {
      pos: [6, 2, 6],
      state: 6
    },
    {
      pos: [0, 3, 6],
      state: 6
    },
    {
      pos: [1, 3, 6],
      state: 6
    },
    {
      pos: [2, 3, 6],
      state: 6
    },
    {
      pos: [3, 3, 6],
      state: 6
    },
    {
      pos: [4, 3, 6],
      state: 6
    },
    {
      pos: [5, 3, 6],
      state: 6
    },
    {
      pos: [6, 3, 6],
      state: 6
    },
    {
      pos: [0, 4, 6],
      state: 6
    },
    {
      pos: [1, 4, 6],
      state: 6
    },
    {
      pos: [2, 4, 6],
      state: 6
    },
    {
      pos: [3, 4, 6],
      state: 6
    },
    {
      pos: [4, 4, 6],
      state: 6
    },
    {
      pos: [5, 4, 6],
      state: 6
    },
    {
      pos: [6, 4, 6],
      state: 6
    },
    {
      pos: [0, 5, 6],
      state: 6
    },
    {
      pos: [1, 5, 6],
      state: 6
    },
    {
      pos: [2, 5, 6],
      state: 6
    },
    {
      pos: [3, 5, 6],
      state: 6
    },
    {
      pos: [4, 5, 6],
      state: 6
    },
    {
      pos: [5, 5, 6],
      state: 6
    },
    {
      pos: [6, 5, 6],
      state: 6
    },
    {
      pos: [0, 6, 6],
      state: 6
    },
    {
      pos: [1, 6, 6],
      state: 6
    },
    {
      pos: [2, 6, 6],
      state: 6
    },
    {
      pos: [3, 6, 6],
      state: 6
    },
    {
      pos: [4, 6, 6],
      state: 6
    },
    {
      pos: [5, 6, 6],
      state: 6
    },
    {
      pos: [6, 6, 6],
      state: 6
    },
    {
      pos: [0, 7, 6],
      state: 6
    },
    {
      pos: [1, 7, 6],
      state: 6
    },
    {
      pos: [2, 7, 6],
      state: 6
    },
    {
      pos: [3, 7, 6],
      state: 6
    },
    {
      pos: [4, 7, 6],
      state: 6
    },
    {
      pos: [5, 7, 6],
      state: 6
    },
    {
      pos: [6, 7, 6],
      state: 6
    },
    {
      pos: [0, 8, 6],
      state: 6
    },
    {
      pos: [1, 8, 6],
      state: 6
    },
    {
      pos: [2, 8, 6],
      state: 6
    },
    {
      pos: [3, 8, 6],
      state: 6
    },
    {
      pos: [4, 8, 6],
      state: 6
    },
    {
      pos: [5, 8, 6],
      state: 6
    },
    {
      pos: [6, 8, 6],
      state: 6
    },
    {
      pos: [0, 9, 6],
      state: 6
    },
    {
      pos: [1, 9, 6],
      state: 6
    },
    {
      pos: [2, 9, 6],
      state: 6
    },
    {
      pos: [3, 9, 6],
      state: 6
    },
    {
      pos: [4, 9, 6],
      state: 6
    },
    {
      pos: [5, 9, 6],
      state: 6
    },
    {
      pos: [6, 9, 6],
      state: 6
    },
    {
      pos: [0, 10, 6],
      state: 6
    },
    {
      pos: [1, 10, 6],
      state: 6
    },
    {
      pos: [2, 10, 6],
      state: 6
    },
    {
      pos: [3, 10, 6],
      state: 6
    },
    {
      pos: [4, 10, 6],
      state: 6
    },
    {
      pos: [5, 10, 6],
      state: 6
    },
    {
      pos: [6, 10, 6],
      state: 6
    },
    {
      pos: [0, 1, 7],
      state: 6
    },
    {
      pos: [1, 1, 7],
      state: 6
    },
    {
      pos: [2, 1, 7],
      state: 6
    },
    {
      pos: [3, 1, 7],
      state: 6
    },
    {
      pos: [4, 1, 7],
      state: 6
    },
    {
      pos: [5, 1, 7],
      state: 6
    },
    {
      pos: [6, 1, 7],
      state: 6
    },
    {
      pos: [0, 2, 7],
      state: 6
    },
    {
      pos: [1, 2, 7],
      state: 6
    },
    {
      pos: [2, 2, 7],
      state: 6
    },
    {
      pos: [3, 2, 7],
      state: 6
    },
    {
      pos: [4, 2, 7],
      state: 6
    },
    {
      pos: [5, 2, 7],
      state: 6
    },
    {
      pos: [6, 2, 7],
      state: 6
    },
    {
      pos: [0, 3, 7],
      state: 6
    },
    {
      pos: [1, 3, 7],
      state: 6
    },
    {
      pos: [2, 3, 7],
      state: 6
    },
    {
      pos: [3, 3, 7],
      state: 6
    },
    {
      pos: [4, 3, 7],
      state: 6
    },
    {
      pos: [5, 3, 7],
      state: 6
    },
    {
      pos: [6, 3, 7],
      state: 6
    },
    {
      pos: [0, 4, 7],
      state: 6
    },
    {
      pos: [1, 4, 7],
      state: 6
    },
    {
      pos: [2, 4, 7],
      state: 6
    },
    {
      pos: [3, 4, 7],
      state: 6
    },
    {
      pos: [4, 4, 7],
      state: 6
    },
    {
      pos: [5, 4, 7],
      state: 6
    },
    {
      pos: [6, 4, 7],
      state: 6
    },
    {
      pos: [0, 5, 7],
      state: 6
    },
    {
      pos: [1, 5, 7],
      state: 6
    },
    {
      pos: [2, 5, 7],
      state: 6
    },
    {
      pos: [3, 5, 7],
      state: 6
    },
    {
      pos: [4, 5, 7],
      state: 6
    },
    {
      pos: [5, 5, 7],
      state: 6
    },
    {
      pos: [6, 5, 7],
      state: 6
    },
    {
      pos: [0, 6, 7],
      state: 6
    },
    {
      pos: [1, 6, 7],
      state: 6
    },
    {
      pos: [2, 6, 7],
      state: 6
    },
    {
      pos: [3, 6, 7],
      state: 6
    },
    {
      pos: [4, 6, 7],
      state: 6
    },
    {
      pos: [5, 6, 7],
      state: 6
    },
    {
      pos: [6, 6, 7],
      state: 6
    },
    {
      pos: [0, 7, 7],
      state: 6
    },
    {
      pos: [1, 7, 7],
      state: 6
    },
    {
      pos: [2, 7, 7],
      state: 6
    },
    {
      pos: [3, 7, 7],
      state: 6
    },
    {
      pos: [4, 7, 7],
      state: 6
    },
    {
      pos: [5, 7, 7],
      state: 6
    },
    {
      pos: [6, 7, 7],
      state: 6
    },
    {
      pos: [0, 8, 7],
      state: 6
    },
    {
      pos: [1, 8, 7],
      state: 6
    },
    {
      pos: [2, 8, 7],
      state: 6
    },
    {
      pos: [3, 8, 7],
      state: 6
    },
    {
      pos: [4, 8, 7],
      state: 6
    },
    {
      pos: [5, 8, 7],
      state: 6
    },
    {
      pos: [6, 8, 7],
      state: 6
    },
    {
      pos: [0, 9, 7],
      state: 6
    },
    {
      pos: [1, 9, 7],
      state: 6
    },
    {
      pos: [2, 9, 7],
      state: 6
    },
    {
      pos: [3, 9, 7],
      state: 6
    },
    {
      pos: [4, 9, 7],
      state: 6
    },
    {
      pos: [5, 9, 7],
      state: 6
    },
    {
      pos: [6, 9, 7],
      state: 6
    },
    {
      pos: [0, 10, 7],
      state: 6
    },
    {
      pos: [1, 10, 7],
      state: 6
    },
    {
      pos: [2, 10, 7],
      state: 6
    },
    {
      pos: [3, 10, 7],
      state: 6
    },
    {
      pos: [4, 10, 7],
      state: 6
    },
    {
      pos: [5, 10, 7],
      state: 6
    },
    {
      pos: [6, 10, 7],
      state: 6
    },
    {
      pos: [0, 1, 8],
      state: 6
    },
    {
      pos: [1, 1, 8],
      state: 6
    },
    {
      pos: [2, 1, 8],
      state: 6
    },
    {
      pos: [3, 1, 8],
      state: 6
    },
    {
      pos: [4, 1, 8],
      state: 6
    },
    {
      pos: [5, 1, 8],
      state: 6
    },
    {
      pos: [6, 1, 8],
      state: 6
    },
    {
      pos: [0, 2, 8],
      state: 6
    },
    {
      pos: [1, 2, 8],
      state: 6
    },
    {
      pos: [2, 2, 8],
      state: 6
    },
    {
      pos: [3, 2, 8],
      state: 6
    },
    {
      pos: [4, 2, 8],
      state: 6
    },
    {
      pos: [5, 2, 8],
      state: 6
    },
    {
      pos: [6, 2, 8],
      state: 6
    },
    {
      pos: [0, 3, 8],
      state: 6
    },
    {
      pos: [1, 3, 8],
      state: 6
    },
    {
      pos: [2, 3, 8],
      state: 6
    },
    {
      pos: [3, 3, 8],
      state: 6
    },
    {
      pos: [4, 3, 8],
      state: 6
    },
    {
      pos: [5, 3, 8],
      state: 6
    },
    {
      pos: [6, 3, 8],
      state: 6
    },
    {
      pos: [0, 4, 8],
      state: 6
    },
    {
      pos: [1, 4, 8],
      state: 6
    },
    {
      pos: [2, 4, 8],
      state: 6
    },
    {
      pos: [3, 4, 8],
      state: 6
    },
    {
      pos: [4, 4, 8],
      state: 6
    },
    {
      pos: [5, 4, 8],
      state: 6
    },
    {
      pos: [6, 4, 8],
      state: 6
    },
    {
      pos: [0, 5, 8],
      state: 6
    },
    {
      pos: [1, 5, 8],
      state: 6
    },
    {
      pos: [2, 5, 8],
      state: 6
    },
    {
      pos: [3, 5, 8],
      state: 6
    },
    {
      pos: [4, 5, 8],
      state: 6
    },
    {
      pos: [5, 5, 8],
      state: 6
    },
    {
      pos: [6, 5, 8],
      state: 6
    },
    {
      pos: [0, 6, 8],
      state: 6
    },
    {
      pos: [1, 6, 8],
      state: 6
    },
    {
      pos: [2, 6, 8],
      state: 6
    },
    {
      pos: [3, 6, 8],
      state: 6
    },
    {
      pos: [4, 6, 8],
      state: 6
    },
    {
      pos: [5, 6, 8],
      state: 6
    },
    {
      pos: [6, 6, 8],
      state: 6
    },
    {
      pos: [0, 7, 8],
      state: 6
    },
    {
      pos: [1, 7, 8],
      state: 6
    },
    {
      pos: [2, 7, 8],
      state: 6
    },
    {
      pos: [3, 7, 8],
      state: 6
    },
    {
      pos: [4, 7, 8],
      state: 6
    },
    {
      pos: [5, 7, 8],
      state: 6
    },
    {
      pos: [6, 7, 8],
      state: 6
    },
    {
      pos: [0, 8, 8],
      state: 6
    },
    {
      pos: [1, 8, 8],
      state: 6
    },
    {
      pos: [2, 8, 8],
      state: 6
    },
    {
      pos: [3, 8, 8],
      state: 6
    },
    {
      pos: [4, 8, 8],
      state: 6
    },
    {
      pos: [5, 8, 8],
      state: 6
    },
    {
      pos: [6, 8, 8],
      state: 6
    },
    {
      pos: [0, 9, 8],
      state: 6
    },
    {
      pos: [1, 9, 8],
      state: 6
    },
    {
      pos: [2, 9, 8],
      state: 6
    },
    {
      pos: [3, 9, 8],
      state: 6
    },
    {
      pos: [4, 9, 8],
      state: 6
    },
    {
      pos: [5, 9, 8],
      state: 6
    },
    {
      pos: [6, 9, 8],
      state: 6
    },
    {
      pos: [0, 10, 8],
      state: 6
    },
    {
      pos: [1, 10, 8],
      state: 6
    },
    {
      pos: [2, 10, 8],
      state: 6
    },
    {
      pos: [3, 10, 8],
      state: 6
    },
    {
      pos: [4, 10, 8],
      state: 6
    },
    {
      pos: [5, 10, 8],
      state: 6
    },
    {
      pos: [6, 10, 8],
      state: 6
    },
    {
      pos: [0, 1, 9],
      state: 6
    },
    {
      pos: [1, 1, 9],
      state: 6
    },
    {
      pos: [2, 1, 9],
      state: 6
    },
    {
      pos: [3, 1, 9],
      state: 6
    },
    {
      pos: [4, 1, 9],
      state: 6
    },
    {
      pos: [5, 1, 9],
      state: 6
    },
    {
      pos: [6, 1, 9],
      state: 6
    },
    {
      pos: [0, 2, 9],
      state: 6
    },
    {
      pos: [1, 2, 9],
      state: 6
    },
    {
      pos: [2, 2, 9],
      state: 6
    },
    {
      pos: [3, 2, 9],
      state: 6
    },
    {
      pos: [4, 2, 9],
      state: 6
    },
    {
      pos: [5, 2, 9],
      state: 6
    },
    {
      pos: [6, 2, 9],
      state: 6
    },
    {
      pos: [0, 3, 9],
      state: 6
    },
    {
      pos: [1, 3, 9],
      state: 6
    },
    {
      pos: [2, 3, 9],
      state: 6
    },
    {
      pos: [3, 3, 9],
      state: 6
    },
    {
      pos: [4, 3, 9],
      state: 6
    },
    {
      pos: [5, 3, 9],
      state: 6
    },
    {
      pos: [6, 3, 9],
      state: 6
    },
    {
      pos: [0, 4, 9],
      state: 6
    },
    {
      pos: [1, 4, 9],
      state: 6
    },
    {
      pos: [2, 4, 9],
      state: 6
    },
    {
      pos: [3, 4, 9],
      state: 6
    },
    {
      pos: [4, 4, 9],
      state: 6
    },
    {
      pos: [5, 4, 9],
      state: 6
    },
    {
      pos: [6, 4, 9],
      state: 6
    },
    {
      pos: [0, 5, 9],
      state: 6
    },
    {
      pos: [1, 5, 9],
      state: 6
    },
    {
      pos: [2, 5, 9],
      state: 6
    },
    {
      pos: [3, 5, 9],
      state: 6
    },
    {
      pos: [4, 5, 9],
      state: 6
    },
    {
      pos: [5, 5, 9],
      state: 6
    },
    {
      pos: [6, 5, 9],
      state: 6
    },
    {
      pos: [0, 6, 9],
      state: 6
    },
    {
      pos: [1, 6, 9],
      state: 6
    },
    {
      pos: [2, 6, 9],
      state: 6
    },
    {
      pos: [3, 6, 9],
      state: 6
    },
    {
      pos: [4, 6, 9],
      state: 6
    },
    {
      pos: [5, 6, 9],
      state: 6
    },
    {
      pos: [6, 6, 9],
      state: 6
    },
    {
      pos: [0, 7, 9],
      state: 6
    },
    {
      pos: [1, 7, 9],
      state: 6
    },
    {
      pos: [2, 7, 9],
      state: 6
    },
    {
      pos: [3, 7, 9],
      state: 6
    },
    {
      pos: [4, 7, 9],
      state: 6
    },
    {
      pos: [5, 7, 9],
      state: 6
    },
    {
      pos: [6, 7, 9],
      state: 6
    },
    {
      pos: [0, 8, 9],
      state: 6
    },
    {
      pos: [1, 8, 9],
      state: 6
    },
    {
      pos: [2, 8, 9],
      state: 6
    },
    {
      pos: [3, 8, 9],
      state: 6
    },
    {
      pos: [4, 8, 9],
      state: 6
    },
    {
      pos: [5, 8, 9],
      state: 6
    },
    {
      pos: [6, 8, 9],
      state: 6
    },
    {
      pos: [0, 9, 9],
      state: 6
    },
    {
      pos: [1, 9, 9],
      state: 6
    },
    {
      pos: [2, 9, 9],
      state: 6
    },
    {
      pos: [3, 9, 9],
      state: 6
    },
    {
      pos: [4, 9, 9],
      state: 6
    },
    {
      pos: [5, 9, 9],
      state: 6
    },
    {
      pos: [6, 9, 9],
      state: 6
    },
    {
      pos: [0, 10, 9],
      state: 6
    },
    {
      pos: [1, 10, 9],
      state: 6
    },
    {
      pos: [2, 10, 9],
      state: 6
    },
    {
      pos: [3, 10, 9],
      state: 6
    },
    {
      pos: [4, 10, 9],
      state: 6
    },
    {
      pos: [5, 10, 9],
      state: 6
    },
    {
      pos: [6, 10, 9],
      state: 6
    },
    {
      pos: [0, 1, 10],
      state: 6
    },
    {
      pos: [1, 1, 10],
      state: 6
    },
    {
      pos: [2, 1, 10],
      state: 6
    },
    {
      pos: [3, 1, 10],
      state: 6
    },
    {
      pos: [4, 1, 10],
      state: 6
    },
    {
      pos: [5, 1, 10],
      state: 13
    },
    {
      pos: [6, 1, 10],
      state: 14
    },
    {
      pos: [0, 2, 10],
      state: 6
    },
    {
      pos: [1, 2, 10],
      state: 6
    },
    {
      pos: [2, 2, 10],
      state: 6
    },
    {
      pos: [3, 2, 10],
      state: 6
    },
    {
      pos: [4, 2, 10],
      state: 6
    },
    {
      pos: [5, 2, 10],
      state: 6
    },
    {
      pos: [6, 2, 10],
      state: 6
    },
    {
      pos: [0, 3, 10],
      state: 6
    },
    {
      pos: [1, 3, 10],
      state: 6
    },
    {
      pos: [2, 3, 10],
      state: 6
    },
    {
      pos: [3, 3, 10],
      state: 6
    },
    {
      pos: [4, 3, 10],
      state: 6
    },
    {
      pos: [5, 3, 10],
      state: 6
    },
    {
      pos: [6, 3, 10],
      state: 6
    },
    {
      pos: [0, 4, 10],
      state: 6
    },
    {
      pos: [1, 4, 10],
      state: 6
    },
    {
      pos: [2, 4, 10],
      state: 6
    },
    {
      pos: [3, 4, 10],
      state: 6
    },
    {
      pos: [4, 4, 10],
      state: 6
    },
    {
      pos: [5, 4, 10],
      state: 6
    },
    {
      pos: [6, 4, 10],
      state: 6
    },
    {
      pos: [0, 5, 10],
      state: 6
    },
    {
      pos: [1, 5, 10],
      state: 6
    },
    {
      pos: [2, 5, 10],
      state: 6
    },
    {
      pos: [3, 5, 10],
      state: 6
    },
    {
      pos: [4, 5, 10],
      state: 6
    },
    {
      pos: [5, 5, 10],
      state: 6
    },
    {
      pos: [6, 5, 10],
      state: 6
    },
    {
      pos: [0, 6, 10],
      state: 6
    },
    {
      pos: [1, 6, 10],
      state: 6
    },
    {
      pos: [2, 6, 10],
      state: 6
    },
    {
      pos: [3, 6, 10],
      state: 6
    },
    {
      pos: [4, 6, 10],
      state: 6
    },
    {
      pos: [5, 6, 10],
      state: 6
    },
    {
      pos: [6, 6, 10],
      state: 6
    },
    {
      pos: [0, 7, 10],
      state: 6
    },
    {
      pos: [1, 7, 10],
      state: 6
    },
    {
      pos: [2, 7, 10],
      state: 6
    },
    {
      pos: [3, 7, 10],
      state: 6
    },
    {
      pos: [4, 7, 10],
      state: 6
    },
    {
      pos: [5, 7, 10],
      state: 6
    },
    {
      pos: [6, 7, 10],
      state: 6
    },
    {
      pos: [0, 8, 10],
      state: 6
    },
    {
      pos: [1, 8, 10],
      state: 6
    },
    {
      pos: [2, 8, 10],
      state: 6
    },
    {
      pos: [3, 8, 10],
      state: 6
    },
    {
      pos: [4, 8, 10],
      state: 6
    },
    {
      pos: [5, 8, 10],
      state: 6
    },
    {
      pos: [6, 8, 10],
      state: 6
    },
    {
      pos: [0, 9, 10],
      state: 6
    },
    {
      pos: [1, 9, 10],
      state: 6
    },
    {
      pos: [2, 9, 10],
      state: 6
    },
    {
      pos: [3, 9, 10],
      state: 6
    },
    {
      pos: [4, 9, 10],
      state: 6
    },
    {
      pos: [5, 9, 10],
      state: 6
    },
    {
      pos: [6, 9, 10],
      state: 6
    },
    {
      pos: [0, 10, 10],
      state: 6
    },
    {
      pos: [1, 10, 10],
      state: 6
    },
    {
      pos: [2, 10, 10],
      state: 6
    },
    {
      pos: [3, 10, 10],
      state: 6
    },
    {
      pos: [4, 10, 10],
      state: 6
    },
    {
      pos: [5, 10, 10],
      state: 6
    },
    {
      pos: [6, 10, 10],
      state: 6
    },
    {
      pos: [0, 1, 11],
      state: 6
    },
    {
      pos: [1, 1, 11],
      state: 6
    },
    {
      pos: [2, 1, 11],
      state: 6
    },
    {
      pos: [3, 1, 11],
      state: 10
    },
    {
      pos: [4, 1, 11],
      state: 6
    },
    {
      pos: [5, 1, 11],
      state: 13
    },
    {
      pos: [0, 2, 11],
      state: 6
    },
    {
      pos: [1, 2, 11],
      state: 6
    },
    {
      pos: [2, 2, 11],
      state: 6
    },
    {
      pos: [3, 2, 11],
      state: 6
    },
    {
      pos: [4, 2, 11],
      state: 6
    },
    {
      pos: [5, 2, 11],
      state: 15
    },
    {
      pos: [6, 2, 11],
      state: 6
    },
    {
      pos: [0, 3, 11],
      state: 6
    },
    {
      pos: [1, 3, 11],
      state: 6
    },
    {
      pos: [2, 3, 11],
      state: 6
    },
    {
      pos: [3, 3, 11],
      state: 6
    },
    {
      pos: [4, 3, 11],
      state: 6
    },
    {
      pos: [5, 3, 11],
      state: 6
    },
    {
      pos: [6, 3, 11],
      state: 6
    },
    {
      pos: [0, 4, 11],
      state: 6
    },
    {
      pos: [1, 4, 11],
      state: 6
    },
    {
      pos: [2, 4, 11],
      state: 6
    },
    {
      pos: [3, 4, 11],
      state: 6
    },
    {
      pos: [4, 4, 11],
      state: 6
    },
    {
      pos: [5, 4, 11],
      state: 6
    },
    {
      pos: [6, 4, 11],
      state: 6
    },
    {
      pos: [0, 5, 11],
      state: 6
    },
    {
      pos: [1, 5, 11],
      state: 6
    },
    {
      pos: [2, 5, 11],
      state: 6
    },
    {
      pos: [3, 5, 11],
      state: 6
    },
    {
      pos: [4, 5, 11],
      state: 6
    },
    {
      pos: [5, 5, 11],
      state: 6
    },
    {
      pos: [6, 5, 11],
      state: 6
    },
    {
      pos: [0, 6, 11],
      state: 6
    },
    {
      pos: [1, 6, 11],
      state: 6
    },
    {
      pos: [2, 6, 11],
      state: 6
    },
    {
      pos: [3, 6, 11],
      state: 6
    },
    {
      pos: [4, 6, 11],
      state: 6
    },
    {
      pos: [5, 6, 11],
      state: 6
    },
    {
      pos: [6, 6, 11],
      state: 6
    },
    {
      pos: [0, 7, 11],
      state: 6
    },
    {
      pos: [1, 7, 11],
      state: 6
    },
    {
      pos: [2, 7, 11],
      state: 6
    },
    {
      pos: [3, 7, 11],
      state: 6
    },
    {
      pos: [4, 7, 11],
      state: 6
    },
    {
      pos: [5, 7, 11],
      state: 6
    },
    {
      pos: [6, 7, 11],
      state: 6
    },
    {
      pos: [0, 8, 11],
      state: 6
    },
    {
      pos: [1, 8, 11],
      state: 6
    },
    {
      pos: [2, 8, 11],
      state: 6
    },
    {
      pos: [3, 8, 11],
      state: 6
    },
    {
      pos: [4, 8, 11],
      state: 6
    },
    {
      pos: [5, 8, 11],
      state: 6
    },
    {
      pos: [6, 8, 11],
      state: 6
    },
    {
      pos: [0, 9, 11],
      state: 6
    },
    {
      pos: [1, 9, 11],
      state: 6
    },
    {
      pos: [2, 9, 11],
      state: 6
    },
    {
      pos: [3, 9, 11],
      state: 6
    },
    {
      pos: [4, 9, 11],
      state: 6
    },
    {
      pos: [5, 9, 11],
      state: 6
    },
    {
      pos: [6, 9, 11],
      state: 6
    },
    {
      pos: [0, 10, 11],
      state: 6
    },
    {
      pos: [1, 10, 11],
      state: 6
    },
    {
      pos: [2, 10, 11],
      state: 6
    },
    {
      pos: [3, 10, 11],
      state: 6
    },
    {
      pos: [4, 10, 11],
      state: 6
    },
    {
      pos: [5, 10, 11],
      state: 6
    },
    {
      pos: [6, 10, 11],
      state: 6
    },
    {
      pos: [0, 1, 12],
      state: 6
    },
    {
      pos: [1, 1, 12],
      state: 6
    },
    {
      pos: [2, 1, 12],
      state: 6
    },
    {
      pos: [3, 1, 12],
      state: 6
    },
    {
      pos: [4, 1, 12],
      state: 6
    },
    {
      pos: [5, 1, 12],
      state: 16
    },
    {
      pos: [6, 1, 12],
      state: 16
    },
    {
      pos: [0, 2, 12],
      state: 6
    },
    {
      pos: [1, 2, 12],
      state: 6
    },
    {
      pos: [2, 2, 12],
      state: 6
    },
    {
      pos: [3, 2, 12],
      state: 6
    },
    {
      pos: [4, 2, 12],
      state: 6
    },
    {
      pos: [5, 2, 12],
      state: 6
    },
    {
      pos: [0, 3, 12],
      state: 6
    },
    {
      pos: [1, 3, 12],
      state: 6
    },
    {
      pos: [2, 3, 12],
      state: 6
    },
    {
      pos: [3, 3, 12],
      state: 6
    },
    {
      pos: [4, 3, 12],
      state: 6
    },
    {
      pos: [5, 3, 12],
      state: 6
    },
    {
      pos: [6, 3, 12],
      state: 6
    },
    {
      pos: [0, 4, 12],
      state: 6
    },
    {
      pos: [1, 4, 12],
      state: 6
    },
    {
      pos: [2, 4, 12],
      state: 6
    },
    {
      pos: [3, 4, 12],
      state: 6
    },
    {
      pos: [4, 4, 12],
      state: 6
    },
    {
      pos: [5, 4, 12],
      state: 6
    },
    {
      pos: [6, 4, 12],
      state: 6
    },
    {
      pos: [0, 5, 12],
      state: 6
    },
    {
      pos: [1, 5, 12],
      state: 6
    },
    {
      pos: [2, 5, 12],
      state: 6
    },
    {
      pos: [3, 5, 12],
      state: 6
    },
    {
      pos: [4, 5, 12],
      state: 6
    },
    {
      pos: [5, 5, 12],
      state: 6
    },
    {
      pos: [6, 5, 12],
      state: 6
    },
    {
      pos: [0, 6, 12],
      state: 6
    },
    {
      pos: [1, 6, 12],
      state: 6
    },
    {
      pos: [2, 6, 12],
      state: 6
    },
    {
      pos: [3, 6, 12],
      state: 6
    },
    {
      pos: [4, 6, 12],
      state: 6
    },
    {
      pos: [5, 6, 12],
      state: 6
    },
    {
      pos: [6, 6, 12],
      state: 6
    },
    {
      pos: [0, 7, 12],
      state: 6
    },
    {
      pos: [1, 7, 12],
      state: 6
    },
    {
      pos: [2, 7, 12],
      state: 6
    },
    {
      pos: [3, 7, 12],
      state: 6
    },
    {
      pos: [4, 7, 12],
      state: 6
    },
    {
      pos: [5, 7, 12],
      state: 6
    },
    {
      pos: [6, 7, 12],
      state: 6
    },
    {
      pos: [0, 8, 12],
      state: 6
    },
    {
      pos: [1, 8, 12],
      state: 6
    },
    {
      pos: [2, 8, 12],
      state: 6
    },
    {
      pos: [3, 8, 12],
      state: 6
    },
    {
      pos: [4, 8, 12],
      state: 6
    },
    {
      pos: [5, 8, 12],
      state: 6
    },
    {
      pos: [6, 8, 12],
      state: 6
    },
    {
      pos: [0, 9, 12],
      state: 6
    },
    {
      pos: [1, 9, 12],
      state: 6
    },
    {
      pos: [2, 9, 12],
      state: 6
    },
    {
      pos: [3, 9, 12],
      state: 6
    },
    {
      pos: [4, 9, 12],
      state: 6
    },
    {
      pos: [5, 9, 12],
      state: 6
    },
    {
      pos: [6, 9, 12],
      state: 6
    },
    {
      pos: [0, 10, 12],
      state: 6
    },
    {
      pos: [1, 10, 12],
      state: 6
    },
    {
      pos: [2, 10, 12],
      state: 6
    },
    {
      pos: [3, 10, 12],
      state: 6
    },
    {
      pos: [4, 10, 12],
      state: 6
    },
    {
      pos: [5, 10, 12],
      state: 6
    },
    {
      pos: [6, 10, 12],
      state: 6
    },
    {
      pos: [0, 1, 13],
      state: 6
    },
    {
      pos: [1, 1, 13],
      state: 6
    },
    {
      pos: [2, 1, 13],
      state: 6
    },
    {
      pos: [3, 1, 13],
      state: 6
    },
    {
      pos: [4, 1, 13],
      state: 6
    },
    {
      pos: [5, 1, 13],
      state: 6
    },
    {
      pos: [6, 1, 13],
      state: 6
    },
    {
      pos: [0, 2, 13],
      state: 6
    },
    {
      pos: [1, 2, 13],
      state: 6
    },
    {
      pos: [2, 2, 13],
      state: 6
    },
    {
      pos: [3, 2, 13],
      state: 6
    },
    {
      pos: [4, 2, 13],
      state: 6
    },
    {
      pos: [5, 2, 13],
      state: 6
    },
    {
      pos: [6, 2, 13],
      state: 6
    },
    {
      pos: [0, 3, 13],
      state: 6
    },
    {
      pos: [1, 3, 13],
      state: 6
    },
    {
      pos: [2, 3, 13],
      state: 6
    },
    {
      pos: [3, 3, 13],
      state: 6
    },
    {
      pos: [4, 3, 13],
      state: 6
    },
    {
      pos: [5, 3, 13],
      state: 6
    },
    {
      pos: [6, 3, 13],
      state: 6
    },
    {
      pos: [0, 4, 13],
      state: 6
    },
    {
      pos: [1, 4, 13],
      state: 6
    },
    {
      pos: [2, 4, 13],
      state: 6
    },
    {
      pos: [3, 4, 13],
      state: 6
    },
    {
      pos: [4, 4, 13],
      state: 6
    },
    {
      pos: [5, 4, 13],
      state: 6
    },
    {
      pos: [6, 4, 13],
      state: 6
    },
    {
      pos: [0, 5, 13],
      state: 6
    },
    {
      pos: [1, 5, 13],
      state: 6
    },
    {
      pos: [2, 5, 13],
      state: 6
    },
    {
      pos: [3, 5, 13],
      state: 6
    },
    {
      pos: [4, 5, 13],
      state: 6
    },
    {
      pos: [5, 5, 13],
      state: 6
    },
    {
      pos: [6, 5, 13],
      state: 6
    },
    {
      pos: [0, 6, 13],
      state: 6
    },
    {
      pos: [1, 6, 13],
      state: 6
    },
    {
      pos: [2, 6, 13],
      state: 6
    },
    {
      pos: [3, 6, 13],
      state: 6
    },
    {
      pos: [4, 6, 13],
      state: 6
    },
    {
      pos: [5, 6, 13],
      state: 6
    },
    {
      pos: [6, 6, 13],
      state: 6
    },
    {
      pos: [0, 7, 13],
      state: 6
    },
    {
      pos: [1, 7, 13],
      state: 6
    },
    {
      pos: [3, 7, 13],
      state: 6
    },
    {
      pos: [5, 7, 13],
      state: 6
    },
    {
      pos: [6, 7, 13],
      state: 6
    },
    {
      pos: [0, 8, 13],
      state: 6
    },
    {
      pos: [1, 8, 13],
      state: 6
    },
    {
      pos: [2, 8, 13],
      state: 6
    },
    {
      pos: [4, 8, 13],
      state: 6
    },
    {
      pos: [5, 8, 13],
      state: 6
    },
    {
      pos: [6, 8, 13],
      state: 6
    },
    {
      pos: [0, 9, 13],
      state: 6
    },
    {
      pos: [1, 9, 13],
      state: 6
    },
    {
      pos: [2, 9, 13],
      state: 6
    },
    {
      pos: [3, 9, 13],
      state: 6
    },
    {
      pos: [4, 9, 13],
      state: 6
    },
    {
      pos: [5, 9, 13],
      state: 6
    },
    {
      pos: [6, 9, 13],
      state: 6
    },
    {
      pos: [0, 10, 13],
      state: 6
    },
    {
      pos: [1, 10, 13],
      state: 6
    },
    {
      pos: [2, 10, 13],
      state: 6
    },
    {
      pos: [3, 10, 13],
      state: 6
    },
    {
      pos: [4, 10, 13],
      state: 6
    },
    {
      pos: [5, 10, 13],
      state: 6
    },
    {
      pos: [6, 10, 13],
      state: 6
    },
    {
      pos: [0, 1, 14],
      state: 6
    },
    {
      pos: [1, 1, 14],
      state: 6
    },
    {
      pos: [2, 1, 14],
      state: 6
    },
    {
      pos: [3, 1, 14],
      state: 6
    },
    {
      pos: [4, 1, 14],
      state: 6
    },
    {
      pos: [5, 1, 14],
      state: 6
    },
    {
      pos: [6, 1, 14],
      state: 6
    },
    {
      pos: [0, 2, 14],
      state: 6
    },
    {
      pos: [1, 2, 14],
      state: 6
    },
    {
      pos: [2, 2, 14],
      state: 6
    },
    {
      pos: [3, 2, 14],
      state: 6
    },
    {
      pos: [4, 2, 14],
      state: 6
    },
    {
      pos: [5, 2, 14],
      state: 6
    },
    {
      pos: [6, 2, 14],
      state: 6
    },
    {
      pos: [0, 3, 14],
      state: 6
    },
    {
      pos: [1, 3, 14],
      state: 6
    },
    {
      pos: [2, 3, 14],
      state: 6
    },
    {
      pos: [3, 3, 14],
      state: 6
    },
    {
      pos: [4, 3, 14],
      state: 6
    },
    {
      pos: [5, 3, 14],
      state: 6
    },
    {
      pos: [6, 3, 14],
      state: 6
    },
    {
      pos: [0, 4, 14],
      state: 6
    },
    {
      pos: [1, 4, 14],
      state: 6
    },
    {
      pos: [2, 4, 14],
      state: 6
    },
    {
      pos: [3, 4, 14],
      state: 6
    },
    {
      pos: [4, 4, 14],
      state: 6
    },
    {
      pos: [5, 4, 14],
      state: 6
    },
    {
      pos: [6, 4, 14],
      state: 6
    },
    {
      pos: [0, 5, 14],
      state: 6
    },
    {
      pos: [1, 5, 14],
      state: 6
    },
    {
      pos: [2, 5, 14],
      state: 6
    },
    {
      pos: [3, 5, 14],
      state: 6
    },
    {
      pos: [4, 5, 14],
      state: 6
    },
    {
      pos: [5, 5, 14],
      state: 6
    },
    {
      pos: [6, 5, 14],
      state: 6
    },
    {
      pos: [0, 6, 14],
      state: 6
    },
    {
      pos: [1, 6, 14],
      state: 6
    },
    {
      pos: [2, 6, 14],
      state: 6
    },
    {
      pos: [3, 6, 14],
      state: 17
    },
    {
      pos: [4, 6, 14],
      state: 6
    },
    {
      pos: [5, 6, 14],
      state: 6
    },
    {
      pos: [6, 6, 14],
      state: 6
    },
    {
      pos: [0, 7, 14],
      state: 6
    },
    {
      pos: [1, 7, 14],
      state: 6
    },
    {
      pos: [5, 7, 14],
      state: 6
    },
    {
      pos: [6, 7, 14],
      state: 6
    },
    {
      pos: [0, 8, 14],
      state: 6
    },
    {
      pos: [1, 8, 14],
      state: 6
    },
    {
      pos: [5, 8, 14],
      state: 6
    },
    {
      pos: [6, 8, 14],
      state: 6
    },
    {
      pos: [0, 9, 14],
      state: 6
    },
    {
      pos: [1, 9, 14],
      state: 6
    },
    {
      pos: [2, 9, 14],
      state: 18
    },
    {
      pos: [4, 9, 14],
      state: 18
    },
    {
      pos: [5, 9, 14],
      state: 6
    },
    {
      pos: [6, 9, 14],
      state: 6
    },
    {
      pos: [0, 10, 14],
      state: 6
    },
    {
      pos: [1, 10, 14],
      state: 6
    },
    {
      pos: [2, 10, 14],
      state: 6
    },
    {
      pos: [3, 10, 14],
      state: 18
    },
    {
      pos: [4, 10, 14],
      state: 6
    },
    {
      pos: [5, 10, 14],
      state: 6
    },
    {
      pos: [6, 10, 14],
      state: 6
    }
  ],
  author: "Player997",
  palette: [
    {
      Properties: {
        variant: "birch"
      },
      Name: "minecraft:planks"
    },
    {
      Properties: {
        variant: "oak"
      },
      Name: "minecraft:planks"
    },
    {
      Name: "minecraft:bookshelf"
    },
    {
      Properties: {
        color: "white"
      },
      Name: "minecraft:wool"
    },
    {
      Properties: {
        contents: "empty",
        legacy_data: "0"
      },
      Name: "minecraft:flower_pot"
    },
    {
      Properties: {
        facing: "north"
      },
      Name: "minecraft:wall_banner"
    },
    {
      Name: "minecraft:air"
    },
    {
      Properties: {
        east: "false",
        south: "false",
        north: "false",
        west: "false"
      },
      Name: "minecraft:fence"
    },
    {
      Properties: {
        half: "top",
        variant: "oak"
      },
      Name: "minecraft:wooden_slab"
    },
    {
      Properties: {
        half: "bottom",
        shape: "straight",
        facing: "east"
      },
      Name: "minecraft:oak_stairs"
    },
    {
      Properties: {
        half: "bottom",
        shape: "straight",
        facing: "west"
      },
      Name: "minecraft:oak_stairs"
    },
    {
      Properties: {
        color: "red"
      },
      Name: "minecraft:carpet"
    },
    {
      Properties: {
        half: "bottom",
        shape: "straight",
        facing: "north"
      },
      Name: "minecraft:oak_stairs"
    },
    {
      Properties: {
        half: "top",
        shape: "straight",
        facing: "east"
      },
      Name: "minecraft:oak_stairs"
    },
    {
      Properties: {
        half: "top",
        shape: "straight",
        facing: "south"
      },
      Name: "minecraft:oak_stairs"
    },
    {
      Properties: {
        color: "silver"
      },
      Name: "minecraft:carpet"
    },
    {
      Properties: {
        half: "top",
        shape: "straight",
        facing: "north"
      },
      Name: "minecraft:oak_stairs"
    },
    {
      Properties: {
        half: "top",
        shape: "straight",
        facing: "south"
      },
      Name: "minecraft:birch_stairs"
    },
    {
      Properties: {
        half: "bottom",
        shape: "straight",
        facing: "south"
      },
      Name: "minecraft:birch_stairs"
    }
  ],
  version: 1
}