{
  author: "Searge_DP",
  palette: [
    {
      Name: "minecraft:stone",
      Properties: {
        variant: "stone"
      }
    },
    {
      Name: "minecraft:stonebrick",
      Properties: {
        variant: "stonebrick"
      }
    },
    {
      Name: "minecraft:stonebrick",
      Properties: {
        variant: "cracked_stonebrick"
      }
    },
    {
      Name: "minecraft:air"
    },
    {
      Name: "minecraft:stonebrick",
      Properties: {
        variant: "mossy_stonebrick"
      }
    },
    {
      Name: "minecraft:stone",
      Properties: {
        variant: "smooth_andesite"
      }
    },
    {
      Name: "minecraft:stonebrick",
      Properties: {
        variant: "chiseled_stonebrick"
      }
    },
    {
      Name: "minecraft:monster_egg",
      Properties: {
        variant: "chiseled_brick"
      }
    },
    {
      Name: "minecraft:monster_egg",
      Properties: {
        variant: "stone_brick"
      }
    },
    {
      Name: "minecraft:monster_egg",
      Properties: {
        variant: "mossy_brick"
      }
    },
    {
      Name: "minecraft:wall_sign",
      Properties: {
        facing: "south"
      }
    },
    {
      Name: "minecraft:chest",
      Properties: {
        facing: "east"
      }
    },
    {
      Name: "minecraft:structure_block",
      Properties: {
        mode: "data"
      }
    },
    {
      Name: "minecraft:brewing_stand",
      Properties: {
        has_bottle_2: "false",
        has_bottle_1: "true",
        has_bottle_0: "false"
      }
    },
    {
      Name: "minecraft:flower_pot",
      Properties: {
        legacy_data: "0",
        contents: "empty"
      }
    },
    {
      Name: "minecraft:iron_bars",
      Properties: {
        south: "false",
        north: "false",
        east: "false",
        west: "false"
      }
    },
    {
      Name: "minecraft:carpet",
      Properties: {
        color: "red"
      }
    },
    {
      Name: "minecraft:web"
    },
    {
      Name: "minecraft:torch",
      Properties: {
        facing: "south"
      }
    },
    {
      Name: "minecraft:cauldron",
      Properties: {
        level: "2"
      }
    },
    {
      Name: "minecraft:spruce_stairs",
      Properties: {
        half: "top",
        facing: "north",
        shape: "straight"
      }
    },
    {
      Name: "minecraft:wooden_slab",
      Properties: {
        half: "top",
        variant: "spruce"
      }
    },
    {
      Name: "minecraft:spruce_stairs",
      Properties: {
        half: "top",
        facing: "south",
        shape: "straight"
      }
    },
    {
      Name: "minecraft:ladder",
      Properties: {
        facing: "north"
      }
    },
    {
      Name: "minecraft:torch",
      Properties: {
        facing: "north"
      }
    }
  ],
  blocks: [
    {
      state: 0,
      pos: [1, 0, 0]
    },
    {
      state: 0,
      pos: [2, 0, 0]
    },
    {
      state: 0,
      pos: [3, 0, 0]
    },
    {
      state: 0,
      pos: [4, 0, 0]
    },
    {
      state: 0,
      pos: [5, 0, 0]
    },
    {
      state: 1,
      pos: [1, 1, 0]
    },
    {
      state: 1,
      pos: [2, 1, 0]
    },
    {
      state: 1,
      pos: [3, 1, 0]
    },
    {
      state: 1,
      pos: [4, 1, 0]
    },
    {
      state: 1,
      pos: [5, 1, 0]
    },
    {
      state: 1,
      pos: [1, 2, 0]
    },
    {
      state: 1,
      pos: [2, 2, 0]
    },
    {
      state: 1,
      pos: [3, 2, 0]
    },
    {
      state: 1,
      pos: [4, 2, 0]
    },
    {
      state: 1,
      pos: [5, 2, 0]
    },
    {
      state: 1,
      pos: [1, 3, 0]
    },
    {
      state: 1,
      pos: [2, 3, 0]
    },
    {
      state: 1,
      pos: [3, 3, 0]
    },
    {
      state: 1,
      pos: [4, 3, 0]
    },
    {
      state: 1,
      pos: [5, 3, 0]
    },
    {
      state: 0,
      pos: [1, 0, 1]
    },
    {
      state: 2,
      pos: [2, 0, 1]
    },
    {
      state: 0,
      pos: [3, 0, 1]
    },
    {
      state: 2,
      pos: [4, 0, 1]
    },
    {
      state: 0,
      pos: [5, 0, 1]
    },
    {
      state: 1,
      pos: [1, 1, 1]
    },
    {
      state: 3,
      pos: [2, 1, 1]
    },
    {
      state: 1,
      pos: [3, 1, 1]
    },
    {
      state: 3,
      pos: [4, 1, 1]
    },
    {
      state: 1,
      pos: [5, 1, 1]
    },
    {
      state: 1,
      pos: [1, 2, 1]
    },
    {
      state: 3,
      pos: [2, 2, 1]
    },
    {
      state: 1,
      pos: [3, 2, 1]
    },
    {
      state: 3,
      pos: [4, 2, 1]
    },
    {
      state: 1,
      pos: [5, 2, 1]
    },
    {
      state: 1,
      pos: [1, 3, 1]
    },
    {
      state: 3,
      pos: [2, 3, 1]
    },
    {
      state: 1,
      pos: [3, 3, 1]
    },
    {
      state: 3,
      pos: [4, 3, 1]
    },
    {
      state: 1,
      pos: [5, 3, 1]
    },
    {
      state: 1,
      pos: [2, 4, 1]
    },
    {
      state: 1,
      pos: [3, 4, 1]
    },
    {
      state: 1,
      pos: [4, 4, 1]
    },
    {
      state: 0,
      pos: [1, 0, 2]
    },
    {
      state: 1,
      pos: [2, 0, 2]
    },
    {
      state: 0,
      pos: [3, 0, 2]
    },
    {
      state: 1,
      pos: [4, 0, 2]
    },
    {
      state: 0,
      pos: [5, 0, 2]
    },
    {
      state: 4,
      pos: [1, 1, 2]
    },
    {
      state: 4,
      pos: [3, 1, 2]
    },
    {
      state: 4,
      pos: [5, 1, 2]
    },
    {
      state: 1,
      pos: [1, 2, 2]
    },
    {
      state: 2,
      pos: [3, 2, 2]
    },
    {
      state: 1,
      pos: [5, 2, 2]
    },
    {
      state: 1,
      pos: [1, 3, 2]
    },
    {
      state: 1,
      pos: [2, 3, 2]
    },
    {
      state: 1,
      pos: [3, 3, 2]
    },
    {
      state: 1,
      pos: [4, 3, 2]
    },
    {
      state: 1,
      pos: [5, 3, 2]
    },
    {
      state: 1,
      pos: [2, 4, 2]
    },
    {
      state: 1,
      pos: [3, 4, 2]
    },
    {
      state: 1,
      pos: [4, 4, 2]
    },
    {
      state: 5,
      pos: [1, 0, 3]
    },
    {
      state: 1,
      pos: [2, 0, 3]
    },
    {
      state: 6,
      pos: [3, 0, 3]
    },
    {
      state: 1,
      pos: [4, 0, 3]
    },
    {
      state: 7,
      pos: [5, 0, 3]
    },
    {
      state: 4,
      pos: [0, 1, 3]
    },
    {
      state: 3,
      pos: [2, 1, 3]
    },
    {
      state: 3,
      pos: [3, 1, 3]
    },
    {
      state: 3,
      pos: [4, 1, 3]
    },
    {
      state: 3,
      pos: [5, 1, 3]
    },
    {
      state: 4,
      pos: [6, 1, 3]
    },
    {
      state: 2,
      pos: [0, 2, 3]
    },
    {
      state: 3,
      pos: [1, 2, 3]
    },
    {
      state: 3,
      pos: [2, 2, 3]
    },
    {
      state: 3,
      pos: [4, 2, 3]
    },
    {
      state: 3,
      pos: [5, 2, 3]
    },
    {
      state: 1,
      pos: [6, 2, 3]
    },
    {
      state: 1,
      pos: [0, 3, 3]
    },
    {
      state: 3,
      pos: [2, 3, 3]
    },
    {
      state: 3,
      pos: [4, 3, 3]
    },
    {
      state: 3,
      pos: [5, 3, 3]
    },
    {
      state: 1,
      pos: [6, 3, 3]
    },
    {
      state: 1,
      pos: [1, 4, 3]
    },
    {
      state: 1,
      pos: [2, 4, 3]
    },
    {
      state: 1,
      pos: [3, 4, 3]
    },
    {
      state: 1,
      pos: [4, 4, 3]
    },
    {
      state: 1,
      pos: [5, 4, 3]
    },
    {
      state: 1,
      pos: [1, 0, 4]
    },
    {
      state: 8,
      pos: [2, 0, 4]
    },
    {
      state: 1,
      pos: [3, 0, 4]
    },
    {
      state: 1,
      pos: [4, 0, 4]
    },
    {
      state: 1,
      pos: [5, 0, 4]
    },
    {
      state: 4,
      pos: [0, 1, 4]
    },
    {
      state: 3,
      pos: [2, 1, 4]
    },
    {
      state: 3,
      pos: [3, 1, 4]
    },
    {
      state: 3,
      pos: [4, 1, 4]
    },
    {
      state: 4,
      pos: [6, 1, 4]
    },
    {
      state: 1,
      pos: [0, 2, 4]
    },
    {
      state: 3,
      pos: [1, 2, 4]
    },
    {
      state: 3,
      pos: [2, 2, 4]
    },
    {
      state: 3,
      pos: [3, 2, 4]
    },
    {
      state: 3,
      pos: [4, 2, 4]
    },
    {
      state: 3,
      pos: [5, 2, 4]
    },
    {
      state: 1,
      pos: [6, 2, 4]
    },
    {
      state: 8,
      pos: [0, 3, 4]
    },
    {
      state: 3,
      pos: [1, 3, 4]
    },
    {
      state: 3,
      pos: [2, 3, 4]
    },
    {
      state: 3,
      pos: [3, 3, 4]
    },
    {
      state: 3,
      pos: [4, 3, 4]
    },
    {
      state: 3,
      pos: [5, 3, 4]
    },
    {
      state: 1,
      pos: [6, 3, 4]
    },
    {
      state: 1,
      pos: [1, 4, 4]
    },
    {
      state: 1,
      pos: [2, 4, 4]
    },
    {
      state: 1,
      pos: [3, 4, 4]
    },
    {
      state: 1,
      pos: [4, 4, 4]
    },
    {
      state: 1,
      pos: [5, 4, 4]
    },
    {
      state: 6,
      pos: [1, 0, 5]
    },
    {
      state: 1,
      pos: [2, 0, 5]
    },
    {
      state: 6,
      pos: [3, 0, 5]
    },
    {
      state: 1,
      pos: [4, 0, 5]
    },
    {
      state: 6,
      pos: [5, 0, 5]
    },
    {
      state: 4,
      pos: [0, 1, 5]
    },
    {
      state: 3,
      pos: [1, 1, 5]
    },
    {
      state: 3,
      pos: [2, 1, 5]
    },
    {
      state: 3,
      pos: [3, 1, 5]
    },
    {
      state: 3,
      pos: [4, 1, 5]
    },
    {
      state: 4,
      pos: [6, 1, 5]
    },
    {
      state: 1,
      pos: [0, 2, 5]
    },
    {
      state: 3,
      pos: [1, 2, 5]
    },
    {
      state: 3,
      pos: [2, 2, 5]
    },
    {
      state: 3,
      pos: [3, 2, 5]
    },
    {
      state: 3,
      pos: [4, 2, 5]
    },
    {
      state: 3,
      pos: [5, 2, 5]
    },
    {
      state: 2,
      pos: [6, 2, 5]
    },
    {
      state: 1,
      pos: [0, 3, 5]
    },
    {
      state: 3,
      pos: [1, 3, 5]
    },
    {
      state: 3,
      pos: [2, 3, 5]
    },
    {
      state: 3,
      pos: [3, 3, 5]
    },
    {
      state: 3,
      pos: [4, 3, 5]
    },
    {
      state: 3,
      pos: [5, 3, 5]
    },
    {
      state: 1,
      pos: [6, 3, 5]
    },
    {
      state: 1,
      pos: [1, 4, 5]
    },
    {
      state: 1,
      pos: [2, 4, 5]
    },
    {
      state: 7,
      pos: [3, 4, 5]
    },
    {
      state: 1,
      pos: [4, 4, 5]
    },
    {
      state: 1,
      pos: [5, 4, 5]
    },
    {
      state: 1,
      pos: [1, 0, 6]
    },
    {
      state: 1,
      pos: [2, 0, 6]
    },
    {
      state: 1,
      pos: [3, 0, 6]
    },
    {
      state: 1,
      pos: [4, 0, 6]
    },
    {
      state: 8,
      pos: [5, 0, 6]
    },
    {
      state: 4,
      pos: [0, 1, 6]
    },
    {
      state: 3,
      pos: [2, 1, 6]
    },
    {
      state: 3,
      pos: [3, 1, 6]
    },
    {
      state: 3,
      pos: [4, 1, 6]
    },
    {
      state: 4,
      pos: [6, 1, 6]
    },
    {
      state: 2,
      pos: [0, 2, 6]
    },
    {
      state: 3,
      pos: [2, 2, 6]
    },
    {
      state: 3,
      pos: [3, 2, 6]
    },
    {
      state: 3,
      pos: [4, 2, 6]
    },
    {
      state: 8,
      pos: [6, 2, 6]
    },
    {
      state: 1,
      pos: [0, 3, 6]
    },
    {
      state: 3,
      pos: [1, 3, 6]
    },
    {
      state: 3,
      pos: [2, 3, 6]
    },
    {
      state: 3,
      pos: [3, 3, 6]
    },
    {
      state: 3,
      pos: [4, 3, 6]
    },
    {
      state: 3,
      pos: [5, 3, 6]
    },
    {
      state: 1,
      pos: [6, 3, 6]
    },
    {
      state: 1,
      pos: [1, 4, 6]
    },
    {
      state: 8,
      pos: [2, 4, 6]
    },
    {
      state: 1,
      pos: [3, 4, 6]
    },
    {
      state: 1,
      pos: [4, 4, 6]
    },
    {
      state: 1,
      pos: [5, 4, 6]
    },
    {
      state: 1,
      pos: [3, 5, 6]
    },
    {
      state: 6,
      pos: [1, 0, 7]
    },
    {
      state: 1,
      pos: [2, 0, 7]
    },
    {
      state: 6,
      pos: [3, 0, 7]
    },
    {
      state: 1,
      pos: [4, 0, 7]
    },
    {
      state: 6,
      pos: [5, 0, 7]
    },
    {
      state: 4,
      pos: [0, 1, 7]
    },
    {
      state: 3,
      pos: [1, 1, 7]
    },
    {
      state: 3,
      pos: [2, 1, 7]
    },
    {
      state: 3,
      pos: [3, 1, 7]
    },
    {
      state: 3,
      pos: [4, 1, 7]
    },
    {
      state: 4,
      pos: [6, 1, 7]
    },
    {
      state: 1,
      pos: [0, 2, 7]
    },
    {
      state: 3,
      pos: [1, 2, 7]
    },
    {
      state: 3,
      pos: [2, 2, 7]
    },
    {
      state: 3,
      pos: [4, 2, 7]
    },
    {
      state: 1,
      pos: [6, 2, 7]
    },
    {
      state: 1,
      pos: [0, 3, 7]
    },
    {
      state: 3,
      pos: [1, 3, 7]
    },
    {
      state: 3,
      pos: [5, 3, 7]
    },
    {
      state: 1,
      pos: [6, 3, 7]
    },
    {
      state: 1,
      pos: [1, 4, 7]
    },
    {
      state: 1,
      pos: [2, 4, 7]
    },
    {
      state: 1,
      pos: [4, 4, 7]
    },
    {
      state: 1,
      pos: [5, 4, 7]
    },
    {
      state: 1,
      pos: [2, 5, 7]
    },
    {
      state: 1,
      pos: [4, 5, 7]
    },
    {
      state: 4,
      pos: [1, 1, 8]
    },
    {
      state: 9,
      pos: [2, 1, 8]
    },
    {
      state: 4,
      pos: [3, 1, 8]
    },
    {
      state: 4,
      pos: [4, 1, 8]
    },
    {
      state: 4,
      pos: [5, 1, 8]
    },
    {
      state: 8,
      pos: [1, 2, 8]
    },
    {
      state: 1,
      pos: [2, 2, 8]
    },
    {
      state: 2,
      pos: [3, 2, 8]
    },
    {
      state: 1,
      pos: [4, 2, 8]
    },
    {
      state: 2,
      pos: [5, 2, 8]
    },
    {
      state: 1,
      pos: [1, 3, 8]
    },
    {
      state: 1,
      pos: [2, 3, 8]
    },
    {
      state: 1,
      pos: [3, 3, 8]
    },
    {
      state: 1,
      pos: [4, 3, 8]
    },
    {
      state: 1,
      pos: [5, 3, 8]
    },
    {
      state: 1,
      pos: [2, 4, 8]
    },
    {
      state: 1,
      pos: [3, 4, 8]
    },
    {
      state: 1,
      pos: [4, 4, 8]
    },
    {
      state: 1,
      pos: [3, 5, 8]
    },
    {
      state: 10,
      nbt: {
        id: "Sign",
        Text1: "{\"text\":\"\"}",
        Text2: "{\"text\":\"\\u003c----\"}",
        Text3: "{\"text\":\"----\\u003e\"}",
        Text4: "{\"text\":\"\"}"
      },
      pos: [3, 2, 3]
    },
    {
      state: 11,
      nbt: {
        id: "Chest",
        Items: [],
        Lock: ""
      },
      pos: [1, 1, 6]
    },
    {
      state: 12,
      nbt: {
        sizeZ: 0,
        posY: 1,
        sizeY: 0,
        posX: 1,
        posZ: 1,
        sizeX: 0,
        mode: "DATA",
        mirror: "NONE",
        id: "Structure",
        author: "Searge",
        rotation: "NONE",
        name: "",
        ignoreEntities: 0b,
        metadata: "chest"
      },
      pos: [1, 2, 6]
    },
    {
      state: 13,
      nbt: {
        id: "Cauldron",
        Items: [
          {
            id: "minecraft:splash_potion",
            Damage: 0s,
            Count: 1b,
            tag: {
              Potion: "minecraft:weakness"
            },
            Slot: 1b
          }
        ],
        BrewTime: 0s,
        Lock: "",
        Fuel: 0b
      },
      pos: [5, 2, 6]
    },
    {
      state: 14,
      nbt: {
        id: "FlowerPot",
        Data: 0,
        Item: "minecraft:cactus"
      },
      pos: [5, 2, 7]
    },
    {
      state: 15,
      pos: [2, 1, 2]
    },
    {
      state: 15,
      pos: [4, 1, 2]
    },
    {
      state: 15,
      pos: [2, 2, 2]
    },
    {
      state: 15,
      pos: [4, 2, 2]
    },
    {
      state: 16,
      pos: [1, 1, 3]
    },
    {
      state: 17,
      pos: [1, 3, 3]
    },
    {
      state: 18,
      pos: [3, 3, 3]
    },
    {
      state: 16,
      pos: [1, 1, 4]
    },
    {
      state: 19,
      pos: [5, 1, 4]
    },
    {
      state: 20,
      pos: [5, 1, 5]
    },
    {
      state: 21,
      pos: [5, 1, 6]
    },
    {
      state: 22,
      pos: [5, 1, 7]
    },
    {
      state: 23,
      pos: [3, 2, 7]
    },
    {
      state: 24,
      pos: [2, 3, 7]
    },
    {
      state: 23,
      pos: [3, 3, 7]
    },
    {
      state: 24,
      pos: [4, 3, 7]
    },
    {
      state: 23,
      pos: [3, 4, 7]
    },
    {
      state: 23,
      pos: [3, 5, 7]
    }
  ],
  entities: [
    {
      blockPos: [2, 1, 1],
      nbt: {
        Attributes: [
          {
            Name: "generic.maxHealth",
            Base: 20.0d
          },
          {
            Name: "generic.knockbackResistance",
            Base: 0.0d
          },
          {
            Name: "generic.movementSpeed",
            Base: 0.5d
          },
          {
            Name: "generic.armor",
            Base: 0.0d
          },
          {
            Name: "generic.followRange",
            Base: 16.0d,
            Modifiers: [
              {
                Name: "Random spawn bonus",
                Operation: 1,
                Amount: -0.07807250298271795d,
                UUIDLeast: -9042289162618353532L,
                UUIDMost: -8050404301371587461L
              }
            ]
          }
        ],
        Age: 0,
        UUIDLeast: -8404016208519177543L,
        Motion: [0.0d, -0.0784000015258789d, 0.0d],
        Health: 20.0f,
        Inventory: [],
        HandItems: [
          {},
          {}
        ],
        Offers: {
          Recipes: [
            {
              maxUses: 7,
              sell: {
                id: "minecraft:emerald",
                Damage: 0s,
                Count: 1b
              },
              buy: {
                id: "minecraft:rotten_flesh",
                Damage: 0s,
                Count: 36b
              },
              rewardExp: 1b,
              uses: 0
            },
            {
              maxUses: 7,
              sell: {
                id: "minecraft:emerald",
                Damage: 0s,
                Count: 1b
              },
              buy: {
                id: "minecraft:gold_ingot",
                Damage: 0s,
                Count: 9b
              },
              rewardExp: 1b,
              uses: 0
            }
          ]
        },
        Riches: 15,
        id: "minecraft:villager",
        CareerLevel: 1,
        Career: 1,
        ArmorItems: [
          {},
          {},
          {},
          {}
        ],
        Fire: -1s,
        Invulnerable: 0b,
        DeathTime: 0s,
        ForcedAge: 0,
        AbsorptionAmount: 0.0f,
        HurtTime: 0s,
        OnGround: 1b,
        UUIDMost: 1009044389481761978L,
        Profession: 2,
        ArmorDropChances: [0.08500000089406967f, 0.08500000089406967f, 0.08500000089406967f, 0.08500000089406967f],
        HurtByTimestamp: 0,
        Dimension: 0,
        Air: 300s,
        Willing: 0b,
        CanPickUpLoot: 1b,
        Pos: [-72.5d, 62.0d, -120.5d],
        PortalCooldown: 0,
        PersistenceRequired: 1b,
        HandDropChances: [0.08500000089406967f, 0.08500000089406967f],
        Leashed: 0b,
        LeftHanded: 0b,
        FallDistance: 0.0f,
        Rotation: [-4.32769775390625f, -3.4165501594543457f]
      },
      pos: [2.5d, 1.0d, 1.5d]
    },
    {
      blockPos: [4, 1, 1],
      nbt: {
        ConversionTime: -1,
        Attributes: [
          {
            Name: "generic.maxHealth",
            Base: 20.0d
          },
          {
            Name: "generic.knockbackResistance",
            Base: 0.0d,
            Modifiers: [
              {
                Name: "Random spawn bonus",
                Operation: 0,
                Amount: 0.033586338385064834d,
                UUIDLeast: -9185924421726330189L,
                UUIDMost: -1136549371827500916L
              }
            ]
          },
          {
            Name: "generic.movementSpeed",
            Base: 0.23000000417232513d
          },
          {
            Name: "generic.armor",
            Base: 2.0d
          },
          {
            Name: "generic.followRange",
            Base: 35.0d,
            Modifiers: [
              {
                Name: "Random spawn bonus",
                Operation: 1,
                Amount: -0.013882809459502736d,
                UUIDLeast: -4972655095452447334L,
                UUIDMost: -7187282525081156696L
              }
            ]
          },
          {
            Name: "generic.attackDamage",
            Base: 3.0d
          },
          {
            Name: "zombie.spawnReinforcements",
            Base: 0.08507647017248195d
          }
        ],
        UUIDLeast: -6631449421406796428L,
        Motion: [0.0d, -0.0784000015258789d, 0.0d],
        Health: 19.049999237060547f,
        HandItems: [
          {},
          {}
        ],
        Profession: 2,
        id: "minecraft:zombie_villager",
        ArmorItems: [
          {},
          {},
          {},
          {}
        ],
        Fire: -1s,
        Invulnerable: 0b,
        DeathTime: 0s,
        CanBreakDoors: 0b,
        AbsorptionAmount: 0.0f,
        HurtTime: 0s,
        OnGround: 1b,
        UUIDMost: 9169347718178752431L,
        ArmorDropChances: [0.08500000089406967f, 0.08500000089406967f, 0.08500000089406967f, 0.08500000089406967f],
        HurtByTimestamp: 125,
        Dimension: 0,
        Air: 300s,
        CanPickUpLoot: 0b,
        Pos: [-70.5d, 62.0d, -120.69999998807907d],
        PortalCooldown: 0,
        PersistenceRequired: 1b,
        HandDropChances: [0.08500000089406967f, 0.08500000089406967f],
        Leashed: 0b,
        LeftHanded: 0b,
        FallDistance: 0.0f,
        Rotation: [-95.78887939453125f, 0.0f]
      },
      pos: [4.5d, 1.0d, 1.300000011920929d]
    }
  ],
  version: 1,
  size: [7, 6, 9]
}