{
  author: "Searge",
  palette: [
    {
      Name: "minecraft:snow"
    },
    {
      Name: "minecraft:air"
    },
    {
      Name: "minecraft:ice"
    },
    {
      Name: "minecraft:crafting_table"
    },
    {
      Name: "minecraft:furnace",
      Properties: {
        facing: "east"
      }
    },
    {
      Name: "minecraft:carpet",
      Properties: {
        color: "white"
      }
    },
    {
      Name: "minecraft:redstone_torch",
      Properties: {
        facing: "up"
      }
    },
    {
      Name: "minecraft:bed",
      Properties: {
        occupied: "false",
        facing: "south",
        part: "foot"
      }
    },
    {
      Name: "minecraft:trapdoor",
      Properties: {
        open: "false",
        half: "top",
        facing: "north"
      }
    },
    {
      Name: "minecraft:bed",
      Properties: {
        occupied: "false",
        facing: "south",
        part: "head"
      }
    },
    {
      Name: "minecraft:carpet",
      Properties: {
        color: "silver"
      }
    }
  ],
  blocks: [
    {
      state: 0,
      pos: [2, 0, 0]
    },
    {
      state: 0,
      pos: [3, 0, 0]
    },
    {
      state: 0,
      pos: [4, 0, 0]
    },
    {
      state: 0,
      pos: [2, 1, 0]
    },
    {
      state: 1,
      pos: [3, 1, 0]
    },
    {
      state: 0,
      pos: [4, 1, 0]
    },
    {
      state: 0,
      pos: [2, 2, 0]
    },
    {
      state: 1,
      pos: [3, 2, 0]
    },
    {
      state: 0,
      pos: [4, 2, 0]
    },
    {
      state: 0,
      pos: [3, 3, 0]
    },
    {
      state: 0,
      pos: [2, 0, 1]
    },
    {
      state: 0,
      pos: [3, 0, 1]
    },
    {
      state: 0,
      pos: [4, 0, 1]
    },
    {
      state: 0,
      pos: [2, 1, 1]
    },
    {
      state: 1,
      pos: [3, 1, 1]
    },
    {
      state: 0,
      pos: [4, 1, 1]
    },
    {
      state: 0,
      pos: [2, 2, 1]
    },
    {
      state: 1,
      pos: [3, 2, 1]
    },
    {
      state: 0,
      pos: [4, 2, 1]
    },
    {
      state: 0,
      pos: [3, 3, 1]
    },
    {
      state: 0,
      pos: [1, 0, 2]
    },
    {
      state: 0,
      pos: [2, 0, 2]
    },
    {
      state: 0,
      pos: [3, 0, 2]
    },
    {
      state: 0,
      pos: [4, 0, 2]
    },
    {
      state: 0,
      pos: [5, 0, 2]
    },
    {
      state: 0,
      pos: [1, 1, 2]
    },
    {
      state: 1,
      pos: [2, 1, 2]
    },
    {
      state: 1,
      pos: [3, 1, 2]
    },
    {
      state: 1,
      pos: [4, 1, 2]
    },
    {
      state: 0,
      pos: [5, 1, 2]
    },
    {
      state: 0,
      pos: [1, 2, 2]
    },
    {
      state: 1,
      pos: [2, 2, 2]
    },
    {
      state: 1,
      pos: [3, 2, 2]
    },
    {
      state: 1,
      pos: [4, 2, 2]
    },
    {
      state: 0,
      pos: [5, 2, 2]
    },
    {
      state: 0,
      pos: [2, 3, 2]
    },
    {
      state: 0,
      pos: [3, 3, 2]
    },
    {
      state: 0,
      pos: [4, 3, 2]
    },
    {
      state: 0,
      pos: [0, 0, 3]
    },
    {
      state: 0,
      pos: [1, 0, 3]
    },
    {
      state: 0,
      pos: [2, 0, 3]
    },
    {
      state: 0,
      pos: [3, 0, 3]
    },
    {
      state: 0,
      pos: [4, 0, 3]
    },
    {
      state: 0,
      pos: [5, 0, 3]
    },
    {
      state: 0,
      pos: [6, 0, 3]
    },
    {
      state: 0,
      pos: [0, 1, 3]
    },
    {
      state: 1,
      pos: [5, 1, 3]
    },
    {
      state: 0,
      pos: [6, 1, 3]
    },
    {
      state: 0,
      pos: [0, 2, 3]
    },
    {
      state: 1,
      pos: [1, 2, 3]
    },
    {
      state: 1,
      pos: [2, 2, 3]
    },
    {
      state: 1,
      pos: [3, 2, 3]
    },
    {
      state: 1,
      pos: [4, 2, 3]
    },
    {
      state: 1,
      pos: [5, 2, 3]
    },
    {
      state: 0,
      pos: [6, 2, 3]
    },
    {
      state: 0,
      pos: [1, 3, 3]
    },
    {
      state: 1,
      pos: [2, 3, 3]
    },
    {
      state: 1,
      pos: [3, 3, 3]
    },
    {
      state: 1,
      pos: [4, 3, 3]
    },
    {
      state: 0,
      pos: [5, 3, 3]
    },
    {
      state: 0,
      pos: [2, 4, 3]
    },
    {
      state: 0,
      pos: [3, 4, 3]
    },
    {
      state: 0,
      pos: [4, 4, 3]
    },
    {
      state: 0,
      pos: [0, 0, 4]
    },
    {
      state: 0,
      pos: [1, 0, 4]
    },
    {
      state: 0,
      pos: [2, 0, 4]
    },
    {
      state: 0,
      pos: [3, 0, 4]
    },
    {
      state: 0,
      pos: [4, 0, 4]
    },
    {
      state: 0,
      pos: [5, 0, 4]
    },
    {
      state: 0,
      pos: [6, 0, 4]
    },
    {
      state: 2,
      pos: [0, 1, 4]
    },
    {
      state: 2,
      pos: [6, 1, 4]
    },
    {
      state: 0,
      pos: [0, 2, 4]
    },
    {
      state: 1,
      pos: [1, 2, 4]
    },
    {
      state: 1,
      pos: [2, 2, 4]
    },
    {
      state: 1,
      pos: [3, 2, 4]
    },
    {
      state: 1,
      pos: [4, 2, 4]
    },
    {
      state: 1,
      pos: [5, 2, 4]
    },
    {
      state: 0,
      pos: [6, 2, 4]
    },
    {
      state: 0,
      pos: [1, 3, 4]
    },
    {
      state: 1,
      pos: [2, 3, 4]
    },
    {
      state: 1,
      pos: [3, 3, 4]
    },
    {
      state: 1,
      pos: [4, 3, 4]
    },
    {
      state: 0,
      pos: [5, 3, 4]
    },
    {
      state: 0,
      pos: [2, 4, 4]
    },
    {
      state: 0,
      pos: [3, 4, 4]
    },
    {
      state: 0,
      pos: [4, 4, 4]
    },
    {
      state: 0,
      pos: [0, 0, 5]
    },
    {
      state: 0,
      pos: [1, 0, 5]
    },
    {
      state: 0,
      pos: [2, 0, 5]
    },
    {
      state: 0,
      pos: [4, 0, 5]
    },
    {
      state: 0,
      pos: [5, 0, 5]
    },
    {
      state: 0,
      pos: [6, 0, 5]
    },
    {
      state: 0,
      pos: [0, 1, 5]
    },
    {
      state: 3,
      pos: [1, 1, 5]
    },
    {
      state: 0,
      pos: [6, 1, 5]
    },
    {
      state: 0,
      pos: [0, 2, 5]
    },
    {
      state: 1,
      pos: [1, 2, 5]
    },
    {
      state: 1,
      pos: [2, 2, 5]
    },
    {
      state: 1,
      pos: [3, 2, 5]
    },
    {
      state: 1,
      pos: [4, 2, 5]
    },
    {
      state: 1,
      pos: [5, 2, 5]
    },
    {
      state: 0,
      pos: [6, 2, 5]
    },
    {
      state: 0,
      pos: [1, 3, 5]
    },
    {
      state: 1,
      pos: [2, 3, 5]
    },
    {
      state: 1,
      pos: [3, 3, 5]
    },
    {
      state: 1,
      pos: [4, 3, 5]
    },
    {
      state: 0,
      pos: [5, 3, 5]
    },
    {
      state: 0,
      pos: [2, 4, 5]
    },
    {
      state: 0,
      pos: [3, 4, 5]
    },
    {
      state: 0,
      pos: [4, 4, 5]
    },
    {
      state: 0,
      pos: [1, 0, 6]
    },
    {
      state: 0,
      pos: [2, 0, 6]
    },
    {
      state: 0,
      pos: [3, 0, 6]
    },
    {
      state: 0,
      pos: [4, 0, 6]
    },
    {
      state: 0,
      pos: [5, 0, 6]
    },
    {
      state: 0,
      pos: [1, 1, 6]
    },
    {
      state: 0,
      pos: [5, 1, 6]
    },
    {
      state: 0,
      pos: [1, 2, 6]
    },
    {
      state: 1,
      pos: [2, 2, 6]
    },
    {
      state: 1,
      pos: [3, 2, 6]
    },
    {
      state: 1,
      pos: [4, 2, 6]
    },
    {
      state: 0,
      pos: [5, 2, 6]
    },
    {
      state: 0,
      pos: [2, 3, 6]
    },
    {
      state: 0,
      pos: [3, 3, 6]
    },
    {
      state: 0,
      pos: [4, 3, 6]
    },
    {
      state: 0,
      pos: [2, 0, 7]
    },
    {
      state: 0,
      pos: [3, 0, 7]
    },
    {
      state: 0,
      pos: [4, 0, 7]
    },
    {
      state: 0,
      pos: [2, 1, 7]
    },
    {
      state: 0,
      pos: [3, 1, 7]
    },
    {
      state: 0,
      pos: [4, 1, 7]
    },
    {
      state: 0,
      pos: [2, 2, 7]
    },
    {
      state: 0,
      pos: [3, 2, 7]
    },
    {
      state: 0,
      pos: [4, 2, 7]
    },
    {
      state: 4,
      nbt: {
        id: "Furnace",
        Items: [],
        BurnTime: 0s,
        CookTimeTotal: 0s,
        Lock: "",
        CookTime: 0s
      },
      pos: [1, 1, 3]
    },
    {
      state: 5,
      pos: [2, 1, 3]
    },
    {
      state: 5,
      pos: [3, 1, 3]
    },
    {
      state: 5,
      pos: [4, 1, 3]
    },
    {
      state: 6,
      pos: [1, 1, 4]
    },
    {
      state: 5,
      pos: [2, 1, 4]
    },
    {
      state: 5,
      pos: [3, 1, 4]
    },
    {
      state: 5,
      pos: [4, 1, 4]
    },
    {
      state: 7,
      pos: [5, 1, 4]
    },
    {
      state: 8,
      pos: [3, 0, 5]
    },
    {
      state: 5,
      pos: [2, 1, 5]
    },
    {
      state: 5,
      pos: [3, 1, 5]
    },
    {
      state: 5,
      pos: [4, 1, 5]
    },
    {
      state: 9,
      pos: [5, 1, 5]
    },
    {
      state: 10,
      pos: [2, 1, 6]
    },
    {
      state: 10,
      pos: [3, 1, 6]
    },
    {
      state: 10,
      pos: [4, 1, 6]
    }
  ],
  entities: [],
  version: 1,
  size: [7, 5, 8]
}