{
  author: "jeb_",
  palette: [
    {
      Name: "minecraft:air"
    },
    {
      Name: "minecraft:purpur_pillar",
      Properties: {
        axis: "z"
      }
    },
    {
      Name: "minecraft:purpur_block"
    },
    {
      Name: "minecraft:purpur_stairs",
      Properties: {
        half: "top",
        facing: "east",
        shape: "straight"
      }
    },
    {
      Name: "minecraft:purpur_stairs",
      Properties: {
        half: "top",
        facing: "west",
        shape: "straight"
      }
    },
    {
      Name: "minecraft:purpur_slab",
      Properties: {
        half: "bottom",
        variant: "default"
      }
    },
    {
      Name: "minecraft:purpur_stairs",
      Properties: {
        half: "bottom",
        facing: "east",
        shape: "straight"
      }
    },
    {
      Name: "minecraft:purpur_stairs",
      Properties: {
        half: "bottom",
        facing: "west",
        shape: "straight"
      }
    }
  ],
  blocks: [
    {
      state: 0,
      pos: [0, 0, 0]
    },
    {
      state: 0,
      pos: [1, 0, 0]
    },
    {
      state: 0,
      pos: [2, 0, 0]
    },
    {
      state: 0,
      pos: [3, 0, 0]
    },
    {
      state: 0,
      pos: [4, 0, 0]
    },
    {
      state: 0,
      pos: [0, 1, 0]
    },
    {
      state: 0,
      pos: [1, 1, 0]
    },
    {
      state: 0,
      pos: [2, 1, 0]
    },
    {
      state: 0,
      pos: [3, 1, 0]
    },
    {
      state: 0,
      pos: [4, 1, 0]
    },
    {
      state: 0,
      pos: [0, 2, 0]
    },
    {
      state: 0,
      pos: [1, 2, 0]
    },
    {
      state: 0,
      pos: [2, 2, 0]
    },
    {
      state: 0,
      pos: [3, 2, 0]
    },
    {
      state: 0,
      pos: [4, 2, 0]
    },
    {
      state: 0,
      pos: [0, 3, 0]
    },
    {
      state: 0,
      pos: [1, 3, 0]
    },
    {
      state: 0,
      pos: [2, 3, 0]
    },
    {
      state: 0,
      pos: [3, 3, 0]
    },
    {
      state: 0,
      pos: [4, 3, 0]
    },
    {
      state: 0,
      pos: [0, 4, 0]
    },
    {
      state: 0,
      pos: [1, 4, 0]
    },
    {
      state: 1,
      pos: [2, 4, 0]
    },
    {
      state: 0,
      pos: [3, 4, 0]
    },
    {
      state: 0,
      pos: [4, 4, 0]
    },
    {
      state: 2,
      pos: [0, 5, 0]
    },
    {
      state: 2,
      pos: [1, 5, 0]
    },
    {
      state: 2,
      pos: [2, 5, 0]
    },
    {
      state: 2,
      pos: [3, 5, 0]
    },
    {
      state: 2,
      pos: [4, 5, 0]
    },
    {
      state: 2,
      pos: [0, 6, 0]
    },
    {
      state: 0,
      pos: [1, 6, 0]
    },
    {
      state: 0,
      pos: [2, 6, 0]
    },
    {
      state: 0,
      pos: [3, 6, 0]
    },
    {
      state: 2,
      pos: [4, 6, 0]
    },
    {
      state: 0,
      pos: [0, 0, 1]
    },
    {
      state: 0,
      pos: [1, 0, 1]
    },
    {
      state: 0,
      pos: [2, 0, 1]
    },
    {
      state: 0,
      pos: [3, 0, 1]
    },
    {
      state: 0,
      pos: [4, 0, 1]
    },
    {
      state: 0,
      pos: [0, 1, 1]
    },
    {
      state: 0,
      pos: [1, 1, 1]
    },
    {
      state: 0,
      pos: [2, 1, 1]
    },
    {
      state: 0,
      pos: [3, 1, 1]
    },
    {
      state: 0,
      pos: [4, 1, 1]
    },
    {
      state: 0,
      pos: [0, 2, 1]
    },
    {
      state: 0,
      pos: [1, 2, 1]
    },
    {
      state: 0,
      pos: [2, 2, 1]
    },
    {
      state: 0,
      pos: [3, 2, 1]
    },
    {
      state: 0,
      pos: [4, 2, 1]
    },
    {
      state: 0,
      pos: [0, 3, 1]
    },
    {
      state: 0,
      pos: [1, 3, 1]
    },
    {
      state: 0,
      pos: [2, 3, 1]
    },
    {
      state: 0,
      pos: [3, 3, 1]
    },
    {
      state: 0,
      pos: [4, 3, 1]
    },
    {
      state: 2,
      pos: [1, 4, 1]
    },
    {
      state: 2,
      pos: [2, 4, 1]
    },
    {
      state: 2,
      pos: [3, 4, 1]
    },
    {
      state: 2,
      pos: [0, 5, 1]
    },
    {
      state: 2,
      pos: [4, 5, 1]
    },
    {
      state: 0,
      pos: [1, 6, 1]
    },
    {
      state: 0,
      pos: [2, 6, 1]
    },
    {
      state: 0,
      pos: [3, 6, 1]
    },
    {
      state: 0,
      pos: [0, 0, 2]
    },
    {
      state: 0,
      pos: [1, 0, 2]
    },
    {
      state: 0,
      pos: [2, 0, 2]
    },
    {
      state: 0,
      pos: [3, 0, 2]
    },
    {
      state: 0,
      pos: [4, 0, 2]
    },
    {
      state: 0,
      pos: [0, 1, 2]
    },
    {
      state: 0,
      pos: [1, 1, 2]
    },
    {
      state: 0,
      pos: [2, 1, 2]
    },
    {
      state: 0,
      pos: [3, 1, 2]
    },
    {
      state: 0,
      pos: [4, 1, 2]
    },
    {
      state: 0,
      pos: [0, 2, 2]
    },
    {
      state: 0,
      pos: [1, 2, 2]
    },
    {
      state: 0,
      pos: [2, 2, 2]
    },
    {
      state: 0,
      pos: [3, 2, 2]
    },
    {
      state: 0,
      pos: [4, 2, 2]
    },
    {
      state: 0,
      pos: [0, 3, 2]
    },
    {
      state: 0,
      pos: [1, 3, 2]
    },
    {
      state: 0,
      pos: [2, 3, 2]
    },
    {
      state: 0,
      pos: [3, 3, 2]
    },
    {
      state: 0,
      pos: [4, 3, 2]
    },
    {
      state: 2,
      pos: [0, 4, 2]
    },
    {
      state: 2,
      pos: [1, 4, 2]
    },
    {
      state: 2,
      pos: [2, 4, 2]
    },
    {
      state: 2,
      pos: [3, 4, 2]
    },
    {
      state: 2,
      pos: [4, 4, 2]
    },
    {
      state: 0,
      pos: [1, 5, 2]
    },
    {
      state: 0,
      pos: [2, 5, 2]
    },
    {
      state: 0,
      pos: [3, 5, 2]
    },
    {
      state: 0,
      pos: [0, 6, 2]
    },
    {
      state: 0,
      pos: [1, 6, 2]
    },
    {
      state: 0,
      pos: [2, 6, 2]
    },
    {
      state: 0,
      pos: [3, 6, 2]
    },
    {
      state: 0,
      pos: [4, 6, 2]
    },
    {
      state: 0,
      pos: [0, 0, 3]
    },
    {
      state: 0,
      pos: [1, 0, 3]
    },
    {
      state: 0,
      pos: [2, 0, 3]
    },
    {
      state: 0,
      pos: [3, 0, 3]
    },
    {
      state: 0,
      pos: [4, 0, 3]
    },
    {
      state: 0,
      pos: [0, 1, 3]
    },
    {
      state: 0,
      pos: [1, 1, 3]
    },
    {
      state: 0,
      pos: [2, 1, 3]
    },
    {
      state: 0,
      pos: [3, 1, 3]
    },
    {
      state: 0,
      pos: [4, 1, 3]
    },
    {
      state: 0,
      pos: [0, 2, 3]
    },
    {
      state: 0,
      pos: [1, 2, 3]
    },
    {
      state: 0,
      pos: [2, 2, 3]
    },
    {
      state: 0,
      pos: [3, 2, 3]
    },
    {
      state: 0,
      pos: [4, 2, 3]
    },
    {
      state: 2,
      pos: [1, 3, 3]
    },
    {
      state: 2,
      pos: [2, 3, 3]
    },
    {
      state: 2,
      pos: [3, 3, 3]
    },
    {
      state: 2,
      pos: [0, 4, 3]
    },
    {
      state: 2,
      pos: [4, 4, 3]
    },
    {
      state: 0,
      pos: [1, 5, 3]
    },
    {
      state: 0,
      pos: [2, 5, 3]
    },
    {
      state: 0,
      pos: [3, 5, 3]
    },
    {
      state: 0,
      pos: [0, 6, 3]
    },
    {
      state: 0,
      pos: [1, 6, 3]
    },
    {
      state: 0,
      pos: [2, 6, 3]
    },
    {
      state: 0,
      pos: [3, 6, 3]
    },
    {
      state: 0,
      pos: [4, 6, 3]
    },
    {
      state: 0,
      pos: [0, 0, 4]
    },
    {
      state: 0,
      pos: [1, 0, 4]
    },
    {
      state: 0,
      pos: [2, 0, 4]
    },
    {
      state: 0,
      pos: [3, 0, 4]
    },
    {
      state: 0,
      pos: [4, 0, 4]
    },
    {
      state: 0,
      pos: [0, 1, 4]
    },
    {
      state: 0,
      pos: [1, 1, 4]
    },
    {
      state: 0,
      pos: [2, 1, 4]
    },
    {
      state: 0,
      pos: [3, 1, 4]
    },
    {
      state: 0,
      pos: [4, 1, 4]
    },
    {
      state: 0,
      pos: [0, 2, 4]
    },
    {
      state: 0,
      pos: [1, 2, 4]
    },
    {
      state: 0,
      pos: [2, 2, 4]
    },
    {
      state: 0,
      pos: [3, 2, 4]
    },
    {
      state: 0,
      pos: [4, 2, 4]
    },
    {
      state: 2,
      pos: [0, 3, 4]
    },
    {
      state: 2,
      pos: [1, 3, 4]
    },
    {
      state: 2,
      pos: [2, 3, 4]
    },
    {
      state: 2,
      pos: [3, 3, 4]
    },
    {
      state: 2,
      pos: [4, 3, 4]
    },
    {
      state: 0,
      pos: [1, 4, 4]
    },
    {
      state: 0,
      pos: [2, 4, 4]
    },
    {
      state: 0,
      pos: [3, 4, 4]
    },
    {
      state: 0,
      pos: [0, 5, 4]
    },
    {
      state: 0,
      pos: [1, 5, 4]
    },
    {
      state: 0,
      pos: [2, 5, 4]
    },
    {
      state: 0,
      pos: [3, 5, 4]
    },
    {
      state: 0,
      pos: [4, 5, 4]
    },
    {
      state: 0,
      pos: [0, 6, 4]
    },
    {
      state: 0,
      pos: [1, 6, 4]
    },
    {
      state: 0,
      pos: [2, 6, 4]
    },
    {
      state: 0,
      pos: [3, 6, 4]
    },
    {
      state: 0,
      pos: [4, 6, 4]
    },
    {
      state: 0,
      pos: [0, 0, 5]
    },
    {
      state: 0,
      pos: [1, 0, 5]
    },
    {
      state: 0,
      pos: [2, 0, 5]
    },
    {
      state: 0,
      pos: [3, 0, 5]
    },
    {
      state: 0,
      pos: [4, 0, 5]
    },
    {
      state: 0,
      pos: [0, 1, 5]
    },
    {
      state: 0,
      pos: [1, 1, 5]
    },
    {
      state: 0,
      pos: [2, 1, 5]
    },
    {
      state: 0,
      pos: [3, 1, 5]
    },
    {
      state: 0,
      pos: [4, 1, 5]
    },
    {
      state: 2,
      pos: [1, 2, 5]
    },
    {
      state: 2,
      pos: [2, 2, 5]
    },
    {
      state: 2,
      pos: [3, 2, 5]
    },
    {
      state: 2,
      pos: [0, 3, 5]
    },
    {
      state: 2,
      pos: [4, 3, 5]
    },
    {
      state: 0,
      pos: [1, 4, 5]
    },
    {
      state: 0,
      pos: [2, 4, 5]
    },
    {
      state: 0,
      pos: [3, 4, 5]
    },
    {
      state: 0,
      pos: [0, 5, 5]
    },
    {
      state: 0,
      pos: [1, 5, 5]
    },
    {
      state: 0,
      pos: [2, 5, 5]
    },
    {
      state: 0,
      pos: [3, 5, 5]
    },
    {
      state: 0,
      pos: [4, 5, 5]
    },
    {
      state: 0,
      pos: [0, 6, 5]
    },
    {
      state: 0,
      pos: [1, 6, 5]
    },
    {
      state: 0,
      pos: [2, 6, 5]
    },
    {
      state: 0,
      pos: [3, 6, 5]
    },
    {
      state: 0,
      pos: [4, 6, 5]
    },
    {
      state: 0,
      pos: [0, 0, 6]
    },
    {
      state: 0,
      pos: [1, 0, 6]
    },
    {
      state: 0,
      pos: [2, 0, 6]
    },
    {
      state: 0,
      pos: [3, 0, 6]
    },
    {
      state: 0,
      pos: [4, 0, 6]
    },
    {
      state: 0,
      pos: [0, 1, 6]
    },
    {
      state: 0,
      pos: [1, 1, 6]
    },
    {
      state: 0,
      pos: [2, 1, 6]
    },
    {
      state: 0,
      pos: [3, 1, 6]
    },
    {
      state: 0,
      pos: [4, 1, 6]
    },
    {
      state: 2,
      pos: [0, 2, 6]
    },
    {
      state: 2,
      pos: [1, 2, 6]
    },
    {
      state: 2,
      pos: [2, 2, 6]
    },
    {
      state: 2,
      pos: [3, 2, 6]
    },
    {
      state: 2,
      pos: [4, 2, 6]
    },
    {
      state: 0,
      pos: [1, 3, 6]
    },
    {
      state: 0,
      pos: [2, 3, 6]
    },
    {
      state: 0,
      pos: [3, 3, 6]
    },
    {
      state: 0,
      pos: [0, 4, 6]
    },
    {
      state: 0,
      pos: [1, 4, 6]
    },
    {
      state: 0,
      pos: [2, 4, 6]
    },
    {
      state: 0,
      pos: [3, 4, 6]
    },
    {
      state: 0,
      pos: [4, 4, 6]
    },
    {
      state: 0,
      pos: [0, 5, 6]
    },
    {
      state: 0,
      pos: [1, 5, 6]
    },
    {
      state: 0,
      pos: [2, 5, 6]
    },
    {
      state: 0,
      pos: [3, 5, 6]
    },
    {
      state: 0,
      pos: [4, 5, 6]
    },
    {
      state: 0,
      pos: [0, 6, 6]
    },
    {
      state: 0,
      pos: [1, 6, 6]
    },
    {
      state: 0,
      pos: [2, 6, 6]
    },
    {
      state: 0,
      pos: [3, 6, 6]
    },
    {
      state: 0,
      pos: [4, 6, 6]
    },
    {
      state: 0,
      pos: [0, 0, 7]
    },
    {
      state: 0,
      pos: [1, 0, 7]
    },
    {
      state: 1,
      pos: [2, 0, 7]
    },
    {
      state: 0,
      pos: [3, 0, 7]
    },
    {
      state: 0,
      pos: [4, 0, 7]
    },
    {
      state: 2,
      pos: [1, 1, 7]
    },
    {
      state: 2,
      pos: [2, 1, 7]
    },
    {
      state: 2,
      pos: [3, 1, 7]
    },
    {
      state: 2,
      pos: [0, 2, 7]
    },
    {
      state: 2,
      pos: [4, 2, 7]
    },
    {
      state: 0,
      pos: [1, 3, 7]
    },
    {
      state: 0,
      pos: [2, 3, 7]
    },
    {
      state: 0,
      pos: [3, 3, 7]
    },
    {
      state: 0,
      pos: [0, 4, 7]
    },
    {
      state: 0,
      pos: [1, 4, 7]
    },
    {
      state: 0,
      pos: [2, 4, 7]
    },
    {
      state: 0,
      pos: [3, 4, 7]
    },
    {
      state: 0,
      pos: [4, 4, 7]
    },
    {
      state: 0,
      pos: [0, 5, 7]
    },
    {
      state: 0,
      pos: [1, 5, 7]
    },
    {
      state: 0,
      pos: [2, 5, 7]
    },
    {
      state: 0,
      pos: [3, 5, 7]
    },
    {
      state: 0,
      pos: [4, 5, 7]
    },
    {
      state: 0,
      pos: [0, 6, 7]
    },
    {
      state: 0,
      pos: [1, 6, 7]
    },
    {
      state: 0,
      pos: [2, 6, 7]
    },
    {
      state: 0,
      pos: [3, 6, 7]
    },
    {
      state: 0,
      pos: [4, 6, 7]
    },
    {
      state: 3,
      pos: [0, 4, 1]
    },
    {
      state: 4,
      pos: [4, 4, 1]
    },
    {
      state: 5,
      pos: [1, 5, 1]
    },
    {
      state: 5,
      pos: [2, 5, 1]
    },
    {
      state: 5,
      pos: [3, 5, 1]
    },
    {
      state: 6,
      pos: [0, 6, 1]
    },
    {
      state: 7,
      pos: [4, 6, 1]
    },
    {
      state: 6,
      pos: [0, 5, 2]
    },
    {
      state: 7,
      pos: [4, 5, 2]
    },
    {
      state: 3,
      pos: [0, 3, 3]
    },
    {
      state: 4,
      pos: [4, 3, 3]
    },
    {
      state: 5,
      pos: [1, 4, 3]
    },
    {
      state: 5,
      pos: [2, 4, 3]
    },
    {
      state: 5,
      pos: [3, 4, 3]
    },
    {
      state: 6,
      pos: [0, 5, 3]
    },
    {
      state: 7,
      pos: [4, 5, 3]
    },
    {
      state: 6,
      pos: [0, 4, 4]
    },
    {
      state: 7,
      pos: [4, 4, 4]
    },
    {
      state: 3,
      pos: [0, 2, 5]
    },
    {
      state: 4,
      pos: [4, 2, 5]
    },
    {
      state: 5,
      pos: [1, 3, 5]
    },
    {
      state: 5,
      pos: [2, 3, 5]
    },
    {
      state: 5,
      pos: [3, 3, 5]
    },
    {
      state: 6,
      pos: [0, 4, 5]
    },
    {
      state: 7,
      pos: [4, 4, 5]
    },
    {
      state: 6,
      pos: [0, 3, 6]
    },
    {
      state: 7,
      pos: [4, 3, 6]
    },
    {
      state: 3,
      pos: [0, 1, 7]
    },
    {
      state: 4,
      pos: [4, 1, 7]
    },
    {
      state: 5,
      pos: [1, 2, 7]
    },
    {
      state: 5,
      pos: [2, 2, 7]
    },
    {
      state: 5,
      pos: [3, 2, 7]
    },
    {
      state: 6,
      pos: [0, 3, 7]
    },
    {
      state: 7,
      pos: [4, 3, 7]
    }
  ],
  entities: [],
  version: 1,
  size: [5, 7, 8]
}