{
  author: "jeb_",
  palette: [
    {
      Name: "minecraft:air"
    },
    {
      Name: "minecraft:purpur_block"
    },
    {
      Name: "minecraft:purpur_pillar",
      Properties: {
        axis: "y"
      }
    },
    {
      Name: "minecraft:end_bricks"
    },
    {
      Name: "minecraft:wall_banner",
      Properties: {
        facing: "north"
      }
    },
    {
      Name: "minecraft:wall_banner",
      Properties: {
        facing: "west"
      }
    },
    {
      Name: "minecraft:wall_banner",
      Properties: {
        facing: "east"
      }
    },
    {
      Name: "minecraft:structure_block",
      Properties: {
        mode: "save"
      }
    },
    {
      Name: "minecraft:wall_banner",
      Properties: {
        facing: "south"
      }
    },
    {
      Name: "minecraft:purpur_stairs",
      Properties: {
        half: "top",
        facing: "east",
        shape: "straight"
      }
    },
    {
      Name: "minecraft:purpur_stairs",
      Properties: {
        half: "top",
        facing: "south",
        shape: "straight"
      }
    },
    {
      Name: "minecraft:purpur_stairs",
      Properties: {
        half: "bottom",
        facing: "south",
        shape: "straight"
      }
    },
    {
      Name: "minecraft:purpur_stairs",
      Properties: {
        half: "top",
        facing: "west",
        shape: "straight"
      }
    },
    {
      Name: "minecraft:end_rod",
      Properties: {
        facing: "up"
      }
    },
    {
      Name: "minecraft:stained_glass",
      Properties: {
        color: "magenta"
      }
    },
    {
      Name: "minecraft:purpur_stairs",
      Properties: {
        half: "bottom",
        facing: "east",
        shape: "straight"
      }
    },
    {
      Name: "minecraft:purpur_stairs",
      Properties: {
        half: "bottom",
        facing: "west",
        shape: "straight"
      }
    },
    {
      Name: "minecraft:purpur_slab",
      Properties: {
        half: "bottom",
        variant: "default"
      }
    },
    {
      Name: "minecraft:purpur_stairs",
      Properties: {
        half: "top",
        facing: "north",
        shape: "straight"
      }
    },
    {
      Name: "minecraft:purpur_stairs",
      Properties: {
        half: "bottom",
        facing: "north",
        shape: "straight"
      }
    }
  ],
  blocks: [
    {
      state: 0,
      pos: [0, 0, 0]
    },
    {
      state: 0,
      pos: [1, 0, 0]
    },
    {
      state: 0,
      pos: [3, 0, 0]
    },
    {
      state: 0,
      pos: [4, 0, 0]
    },
    {
      state: 0,
      pos: [5, 0, 0]
    },
    {
      state: 0,
      pos: [7, 0, 0]
    },
    {
      state: 0,
      pos: [8, 0, 0]
    },
    {
      state: 0,
      pos: [0, 1, 0]
    },
    {
      state: 0,
      pos: [1, 1, 0]
    },
    {
      state: 0,
      pos: [2, 1, 0]
    },
    {
      state: 0,
      pos: [3, 1, 0]
    },
    {
      state: 0,
      pos: [4, 1, 0]
    },
    {
      state: 0,
      pos: [5, 1, 0]
    },
    {
      state: 0,
      pos: [6, 1, 0]
    },
    {
      state: 0,
      pos: [7, 1, 0]
    },
    {
      state: 0,
      pos: [8, 1, 0]
    },
    {
      state: 0,
      pos: [0, 2, 0]
    },
    {
      state: 0,
      pos: [1, 2, 0]
    },
    {
      state: 0,
      pos: [2, 2, 0]
    },
    {
      state: 0,
      pos: [3, 2, 0]
    },
    {
      state: 0,
      pos: [4, 2, 0]
    },
    {
      state: 0,
      pos: [5, 2, 0]
    },
    {
      state: 0,
      pos: [6, 2, 0]
    },
    {
      state: 0,
      pos: [7, 2, 0]
    },
    {
      state: 0,
      pos: [8, 2, 0]
    },
    {
      state: 0,
      pos: [0, 3, 0]
    },
    {
      state: 0,
      pos: [1, 3, 0]
    },
    {
      state: 0,
      pos: [2, 3, 0]
    },
    {
      state: 0,
      pos: [3, 3, 0]
    },
    {
      state: 0,
      pos: [4, 3, 0]
    },
    {
      state: 0,
      pos: [5, 3, 0]
    },
    {
      state: 0,
      pos: [6, 3, 0]
    },
    {
      state: 0,
      pos: [7, 3, 0]
    },
    {
      state: 0,
      pos: [8, 3, 0]
    },
    {
      state: 0,
      pos: [0, 0, 1]
    },
    {
      state: 0,
      pos: [8, 0, 1]
    },
    {
      state: 0,
      pos: [0, 1, 1]
    },
    {
      state: 0,
      pos: [2, 1, 1]
    },
    {
      state: 0,
      pos: [3, 1, 1]
    },
    {
      state: 0,
      pos: [4, 1, 1]
    },
    {
      state: 0,
      pos: [5, 1, 1]
    },
    {
      state: 0,
      pos: [6, 1, 1]
    },
    {
      state: 0,
      pos: [8, 1, 1]
    },
    {
      state: 0,
      pos: [0, 2, 1]
    },
    {
      state: 0,
      pos: [1, 2, 1]
    },
    {
      state: 0,
      pos: [2, 2, 1]
    },
    {
      state: 0,
      pos: [3, 2, 1]
    },
    {
      state: 0,
      pos: [4, 2, 1]
    },
    {
      state: 0,
      pos: [5, 2, 1]
    },
    {
      state: 0,
      pos: [6, 2, 1]
    },
    {
      state: 0,
      pos: [7, 2, 1]
    },
    {
      state: 0,
      pos: [8, 2, 1]
    },
    {
      state: 0,
      pos: [0, 3, 1]
    },
    {
      state: 0,
      pos: [1, 3, 1]
    },
    {
      state: 0,
      pos: [2, 3, 1]
    },
    {
      state: 0,
      pos: [3, 3, 1]
    },
    {
      state: 0,
      pos: [4, 3, 1]
    },
    {
      state: 0,
      pos: [5, 3, 1]
    },
    {
      state: 0,
      pos: [6, 3, 1]
    },
    {
      state: 0,
      pos: [7, 3, 1]
    },
    {
      state: 0,
      pos: [8, 3, 1]
    },
    {
      state: 1,
      pos: [1, 4, 1]
    },
    {
      state: 1,
      pos: [2, 4, 1]
    },
    {
      state: 1,
      pos: [3, 4, 1]
    },
    {
      state: 1,
      pos: [4, 4, 1]
    },
    {
      state: 1,
      pos: [5, 4, 1]
    },
    {
      state: 1,
      pos: [6, 4, 1]
    },
    {
      state: 1,
      pos: [7, 4, 1]
    },
    {
      state: 1,
      pos: [2, 0, 2]
    },
    {
      state: 1,
      pos: [3, 0, 2]
    },
    {
      state: 1,
      pos: [4, 0, 2]
    },
    {
      state: 1,
      pos: [5, 0, 2]
    },
    {
      state: 1,
      pos: [6, 0, 2]
    },
    {
      state: 0,
      pos: [0, 1, 2]
    },
    {
      state: 0,
      pos: [1, 1, 2]
    },
    {
      state: 2,
      pos: [2, 1, 2]
    },
    {
      state: 3,
      pos: [3, 1, 2]
    },
    {
      state: 3,
      pos: [4, 1, 2]
    },
    {
      state: 3,
      pos: [5, 1, 2]
    },
    {
      state: 2,
      pos: [6, 1, 2]
    },
    {
      state: 0,
      pos: [7, 1, 2]
    },
    {
      state: 0,
      pos: [8, 1, 2]
    },
    {
      state: 0,
      pos: [0, 2, 2]
    },
    {
      state: 0,
      pos: [1, 2, 2]
    },
    {
      state: 2,
      pos: [2, 2, 2]
    },
    {
      state: 3,
      pos: [3, 2, 2]
    },
    {
      state: 3,
      pos: [5, 2, 2]
    },
    {
      state: 2,
      pos: [6, 2, 2]
    },
    {
      state: 0,
      pos: [7, 2, 2]
    },
    {
      state: 0,
      pos: [8, 2, 2]
    },
    {
      state: 0,
      pos: [0, 3, 2]
    },
    {
      state: 0,
      pos: [1, 3, 2]
    },
    {
      state: 2,
      pos: [2, 3, 2]
    },
    {
      state: 3,
      pos: [3, 3, 2]
    },
    {
      state: 3,
      pos: [5, 3, 2]
    },
    {
      state: 2,
      pos: [6, 3, 2]
    },
    {
      state: 0,
      pos: [7, 3, 2]
    },
    {
      state: 0,
      pos: [8, 3, 2]
    },
    {
      state: 1,
      pos: [1, 4, 2]
    },
    {
      state: 1,
      pos: [2, 4, 2]
    },
    {
      state: 1,
      pos: [3, 4, 2]
    },
    {
      state: 1,
      pos: [4, 4, 2]
    },
    {
      state: 1,
      pos: [5, 4, 2]
    },
    {
      state: 1,
      pos: [6, 4, 2]
    },
    {
      state: 1,
      pos: [7, 4, 2]
    },
    {
      state: 0,
      pos: [0, 0, 3]
    },
    {
      state: 1,
      pos: [2, 0, 3]
    },
    {
      state: 1,
      pos: [5, 0, 3]
    },
    {
      state: 1,
      pos: [6, 0, 3]
    },
    {
      state: 0,
      pos: [8, 0, 3]
    },
    {
      state: 0,
      pos: [0, 1, 3]
    },
    {
      state: 0,
      pos: [1, 1, 3]
    },
    {
      state: 3,
      pos: [2, 1, 3]
    },
    {
      state: 0,
      pos: [3, 1, 3]
    },
    {
      state: 0,
      pos: [4, 1, 3]
    },
    {
      state: 0,
      pos: [5, 1, 3]
    },
    {
      state: 0,
      pos: [6, 1, 3]
    },
    {
      state: 0,
      pos: [7, 1, 3]
    },
    {
      state: 0,
      pos: [8, 1, 3]
    },
    {
      state: 0,
      pos: [0, 2, 3]
    },
    {
      state: 0,
      pos: [1, 2, 3]
    },
    {
      state: 3,
      pos: [2, 2, 3]
    },
    {
      state: 0,
      pos: [3, 2, 3]
    },
    {
      state: 0,
      pos: [4, 2, 3]
    },
    {
      state: 0,
      pos: [5, 2, 3]
    },
    {
      state: 0,
      pos: [6, 2, 3]
    },
    {
      state: 0,
      pos: [7, 2, 3]
    },
    {
      state: 0,
      pos: [8, 2, 3]
    },
    {
      state: 0,
      pos: [0, 3, 3]
    },
    {
      state: 0,
      pos: [1, 3, 3]
    },
    {
      state: 3,
      pos: [2, 3, 3]
    },
    {
      state: 0,
      pos: [3, 3, 3]
    },
    {
      state: 0,
      pos: [4, 3, 3]
    },
    {
      state: 0,
      pos: [5, 3, 3]
    },
    {
      state: 3,
      pos: [6, 3, 3]
    },
    {
      state: 0,
      pos: [7, 3, 3]
    },
    {
      state: 0,
      pos: [8, 3, 3]
    },
    {
      state: 1,
      pos: [1, 4, 3]
    },
    {
      state: 1,
      pos: [2, 4, 3]
    },
    {
      state: 1,
      pos: [3, 4, 3]
    },
    {
      state: 1,
      pos: [4, 4, 3]
    },
    {
      state: 1,
      pos: [5, 4, 3]
    },
    {
      state: 1,
      pos: [6, 4, 3]
    },
    {
      state: 1,
      pos: [7, 4, 3]
    },
    {
      state: 0,
      pos: [0, 0, 4]
    },
    {
      state: 1,
      pos: [2, 0, 4]
    },
    {
      state: 0,
      pos: [3, 0, 4]
    },
    {
      state: 0,
      pos: [4, 0, 4]
    },
    {
      state: 0,
      pos: [5, 0, 4]
    },
    {
      state: 1,
      pos: [6, 0, 4]
    },
    {
      state: 0,
      pos: [8, 0, 4]
    },
    {
      state: 0,
      pos: [0, 1, 4]
    },
    {
      state: 0,
      pos: [1, 1, 4]
    },
    {
      state: 3,
      pos: [2, 1, 4]
    },
    {
      state: 0,
      pos: [3, 1, 4]
    },
    {
      state: 0,
      pos: [4, 1, 4]
    },
    {
      state: 0,
      pos: [5, 1, 4]
    },
    {
      state: 0,
      pos: [6, 1, 4]
    },
    {
      state: 0,
      pos: [7, 1, 4]
    },
    {
      state: 0,
      pos: [8, 1, 4]
    },
    {
      state: 0,
      pos: [0, 2, 4]
    },
    {
      state: 0,
      pos: [1, 2, 4]
    },
    {
      state: 0,
      pos: [3, 2, 4]
    },
    {
      state: 0,
      pos: [4, 2, 4]
    },
    {
      state: 0,
      pos: [5, 2, 4]
    },
    {
      state: 0,
      pos: [6, 2, 4]
    },
    {
      state: 0,
      pos: [7, 2, 4]
    },
    {
      state: 0,
      pos: [8, 2, 4]
    },
    {
      state: 0,
      pos: [0, 3, 4]
    },
    {
      state: 0,
      pos: [1, 3, 4]
    },
    {
      state: 0,
      pos: [3, 3, 4]
    },
    {
      state: 0,
      pos: [5, 3, 4]
    },
    {
      state: 3,
      pos: [6, 3, 4]
    },
    {
      state: 0,
      pos: [7, 3, 4]
    },
    {
      state: 0,
      pos: [8, 3, 4]
    },
    {
      state: 1,
      pos: [1, 4, 4]
    },
    {
      state: 1,
      pos: [2, 4, 4]
    },
    {
      state: 1,
      pos: [3, 4, 4]
    },
    {
      state: 1,
      pos: [4, 4, 4]
    },
    {
      state: 1,
      pos: [5, 4, 4]
    },
    {
      state: 1,
      pos: [6, 4, 4]
    },
    {
      state: 1,
      pos: [7, 4, 4]
    },
    {
      state: 0,
      pos: [0, 0, 5]
    },
    {
      state: 1,
      pos: [2, 0, 5]
    },
    {
      state: 0,
      pos: [3, 0, 5]
    },
    {
      state: 0,
      pos: [4, 0, 5]
    },
    {
      state: 0,
      pos: [5, 0, 5]
    },
    {
      state: 1,
      pos: [6, 0, 5]
    },
    {
      state: 0,
      pos: [8, 0, 5]
    },
    {
      state: 0,
      pos: [0, 1, 5]
    },
    {
      state: 0,
      pos: [1, 1, 5]
    },
    {
      state: 3,
      pos: [2, 1, 5]
    },
    {
      state: 0,
      pos: [3, 1, 5]
    },
    {
      state: 0,
      pos: [4, 1, 5]
    },
    {
      state: 0,
      pos: [5, 1, 5]
    },
    {
      state: 3,
      pos: [6, 1, 5]
    },
    {
      state: 0,
      pos: [7, 1, 5]
    },
    {
      state: 0,
      pos: [8, 1, 5]
    },
    {
      state: 0,
      pos: [0, 2, 5]
    },
    {
      state: 0,
      pos: [1, 2, 5]
    },
    {
      state: 3,
      pos: [2, 2, 5]
    },
    {
      state: 0,
      pos: [3, 2, 5]
    },
    {
      state: 0,
      pos: [4, 2, 5]
    },
    {
      state: 0,
      pos: [5, 2, 5]
    },
    {
      state: 3,
      pos: [6, 2, 5]
    },
    {
      state: 0,
      pos: [7, 2, 5]
    },
    {
      state: 0,
      pos: [8, 2, 5]
    },
    {
      state: 0,
      pos: [0, 3, 5]
    },
    {
      state: 0,
      pos: [1, 3, 5]
    },
    {
      state: 3,
      pos: [2, 3, 5]
    },
    {
      state: 0,
      pos: [3, 3, 5]
    },
    {
      state: 0,
      pos: [4, 3, 5]
    },
    {
      state: 0,
      pos: [5, 3, 5]
    },
    {
      state: 3,
      pos: [6, 3, 5]
    },
    {
      state: 0,
      pos: [7, 3, 5]
    },
    {
      state: 0,
      pos: [8, 3, 5]
    },
    {
      state: 1,
      pos: [1, 4, 5]
    },
    {
      state: 1,
      pos: [2, 4, 5]
    },
    {
      state: 1,
      pos: [3, 4, 5]
    },
    {
      state: 1,
      pos: [4, 4, 5]
    },
    {
      state: 1,
      pos: [5, 4, 5]
    },
    {
      state: 1,
      pos: [6, 4, 5]
    },
    {
      state: 1,
      pos: [7, 4, 5]
    },
    {
      state: 1,
      pos: [2, 0, 6]
    },
    {
      state: 1,
      pos: [3, 0, 6]
    },
    {
      state: 1,
      pos: [4, 0, 6]
    },
    {
      state: 1,
      pos: [5, 0, 6]
    },
    {
      state: 1,
      pos: [6, 0, 6]
    },
    {
      state: 0,
      pos: [0, 1, 6]
    },
    {
      state: 0,
      pos: [1, 1, 6]
    },
    {
      state: 2,
      pos: [2, 1, 6]
    },
    {
      state: 3,
      pos: [3, 1, 6]
    },
    {
      state: 3,
      pos: [4, 1, 6]
    },
    {
      state: 3,
      pos: [5, 1, 6]
    },
    {
      state: 2,
      pos: [6, 1, 6]
    },
    {
      state: 0,
      pos: [7, 1, 6]
    },
    {
      state: 0,
      pos: [8, 1, 6]
    },
    {
      state: 0,
      pos: [0, 2, 6]
    },
    {
      state: 0,
      pos: [1, 2, 6]
    },
    {
      state: 2,
      pos: [2, 2, 6]
    },
    {
      state: 3,
      pos: [3, 2, 6]
    },
    {
      state: 3,
      pos: [5, 2, 6]
    },
    {
      state: 2,
      pos: [6, 2, 6]
    },
    {
      state: 0,
      pos: [7, 2, 6]
    },
    {
      state: 0,
      pos: [8, 2, 6]
    },
    {
      state: 0,
      pos: [0, 3, 6]
    },
    {
      state: 0,
      pos: [1, 3, 6]
    },
    {
      state: 2,
      pos: [2, 3, 6]
    },
    {
      state: 3,
      pos: [3, 3, 6]
    },
    {
      state: 3,
      pos: [5, 3, 6]
    },
    {
      state: 2,
      pos: [6, 3, 6]
    },
    {
      state: 0,
      pos: [7, 3, 6]
    },
    {
      state: 0,
      pos: [8, 3, 6]
    },
    {
      state: 1,
      pos: [1, 4, 6]
    },
    {
      state: 1,
      pos: [2, 4, 6]
    },
    {
      state: 1,
      pos: [3, 4, 6]
    },
    {
      state: 1,
      pos: [4, 4, 6]
    },
    {
      state: 1,
      pos: [5, 4, 6]
    },
    {
      state: 1,
      pos: [6, 4, 6]
    },
    {
      state: 1,
      pos: [7, 4, 6]
    },
    {
      state: 0,
      pos: [0, 0, 7]
    },
    {
      state: 0,
      pos: [8, 0, 7]
    },
    {
      state: 0,
      pos: [0, 1, 7]
    },
    {
      state: 0,
      pos: [2, 1, 7]
    },
    {
      state: 0,
      pos: [3, 1, 7]
    },
    {
      state: 0,
      pos: [4, 1, 7]
    },
    {
      state: 0,
      pos: [5, 1, 7]
    },
    {
      state: 0,
      pos: [6, 1, 7]
    },
    {
      state: 0,
      pos: [8, 1, 7]
    },
    {
      state: 0,
      pos: [0, 2, 7]
    },
    {
      state: 0,
      pos: [1, 2, 7]
    },
    {
      state: 0,
      pos: [2, 2, 7]
    },
    {
      state: 0,
      pos: [3, 2, 7]
    },
    {
      state: 0,
      pos: [4, 2, 7]
    },
    {
      state: 0,
      pos: [5, 2, 7]
    },
    {
      state: 0,
      pos: [6, 2, 7]
    },
    {
      state: 0,
      pos: [7, 2, 7]
    },
    {
      state: 0,
      pos: [8, 2, 7]
    },
    {
      state: 0,
      pos: [0, 3, 7]
    },
    {
      state: 0,
      pos: [1, 3, 7]
    },
    {
      state: 0,
      pos: [2, 3, 7]
    },
    {
      state: 0,
      pos: [3, 3, 7]
    },
    {
      state: 0,
      pos: [4, 3, 7]
    },
    {
      state: 0,
      pos: [5, 3, 7]
    },
    {
      state: 0,
      pos: [6, 3, 7]
    },
    {
      state: 0,
      pos: [7, 3, 7]
    },
    {
      state: 0,
      pos: [8, 3, 7]
    },
    {
      state: 1,
      pos: [1, 4, 7]
    },
    {
      state: 1,
      pos: [2, 4, 7]
    },
    {
      state: 1,
      pos: [3, 4, 7]
    },
    {
      state: 1,
      pos: [4, 4, 7]
    },
    {
      state: 1,
      pos: [5, 4, 7]
    },
    {
      state: 1,
      pos: [6, 4, 7]
    },
    {
      state: 1,
      pos: [7, 4, 7]
    },
    {
      state: 0,
      pos: [0, 0, 8]
    },
    {
      state: 0,
      pos: [1, 0, 8]
    },
    {
      state: 0,
      pos: [3, 0, 8]
    },
    {
      state: 0,
      pos: [4, 0, 8]
    },
    {
      state: 0,
      pos: [5, 0, 8]
    },
    {
      state: 0,
      pos: [7, 0, 8]
    },
    {
      state: 0,
      pos: [8, 0, 8]
    },
    {
      state: 0,
      pos: [0, 1, 8]
    },
    {
      state: 0,
      pos: [1, 1, 8]
    },
    {
      state: 0,
      pos: [2, 1, 8]
    },
    {
      state: 0,
      pos: [3, 1, 8]
    },
    {
      state: 0,
      pos: [4, 1, 8]
    },
    {
      state: 0,
      pos: [5, 1, 8]
    },
    {
      state: 0,
      pos: [6, 1, 8]
    },
    {
      state: 0,
      pos: [7, 1, 8]
    },
    {
      state: 0,
      pos: [8, 1, 8]
    },
    {
      state: 0,
      pos: [0, 2, 8]
    },
    {
      state: 0,
      pos: [1, 2, 8]
    },
    {
      state: 0,
      pos: [2, 2, 8]
    },
    {
      state: 0,
      pos: [3, 2, 8]
    },
    {
      state: 0,
      pos: [4, 2, 8]
    },
    {
      state: 0,
      pos: [5, 2, 8]
    },
    {
      state: 0,
      pos: [6, 2, 8]
    },
    {
      state: 0,
      pos: [7, 2, 8]
    },
    {
      state: 0,
      pos: [8, 2, 8]
    },
    {
      state: 0,
      pos: [0, 3, 8]
    },
    {
      state: 0,
      pos: [1, 3, 8]
    },
    {
      state: 0,
      pos: [2, 3, 8]
    },
    {
      state: 0,
      pos: [3, 3, 8]
    },
    {
      state: 0,
      pos: [4, 3, 8]
    },
    {
      state: 0,
      pos: [5, 3, 8]
    },
    {
      state: 0,
      pos: [6, 3, 8]
    },
    {
      state: 0,
      pos: [7, 3, 8]
    },
    {
      state: 0,
      pos: [8, 3, 8]
    },
    {
      state: 4,
      nbt: {
        id: "Banner",
        Patterns: [
          {
            Pattern: "tt",
            Color: 0
          },
          {
            Pattern: "bt",
            Color: 0
          }
        ],
        Base: 13
      },
      pos: [2, 0, 0]
    },
    {
      state: 4,
      nbt: {
        id: "Banner",
        Patterns: [
          {
            Pattern: "tt",
            Color: 0
          },
          {
            Pattern: "bt",
            Color: 0
          }
        ],
        Base: 13
      },
      pos: [6, 0, 0]
    },
    {
      state: 5,
      nbt: {
        id: "Banner",
        Patterns: [
          {
            Pattern: "tt",
            Color: 0
          },
          {
            Pattern: "bt",
            Color: 0
          }
        ],
        Base: 13
      },
      pos: [0, 0, 2]
    },
    {
      state: 6,
      nbt: {
        id: "Banner",
        Patterns: [
          {
            Pattern: "tt",
            Color: 0
          },
          {
            Pattern: "bt",
            Color: 0
          }
        ],
        Base: 13
      },
      pos: [8, 0, 2]
    },
    {
      state: 7,
      nbt: {
        sizeZ: 0,
        posY: 1,
        posX: 1,
        sizeY: 0,
        posZ: 1,
        sizeX: 0,
        mode: "DATA",
        mirror: "NONE",
        id: "Structure",
        author: "jeb_",
        rotation: "NONE",
        name: "",
        ignoreEntities: 0b,
        metadata: "Sentry"
      },
      pos: [4, 3, 4]
    },
    {
      state: 5,
      nbt: {
        id: "Banner",
        Patterns: [
          {
            Pattern: "tt",
            Color: 0
          },
          {
            Pattern: "bt",
            Color: 0
          }
        ],
        Base: 13
      },
      pos: [0, 0, 6]
    },
    {
      state: 6,
      nbt: {
        id: "Banner",
        Patterns: [
          {
            Pattern: "tt",
            Color: 0
          },
          {
            Pattern: "bt",
            Color: 0
          }
        ],
        Base: 13
      },
      pos: [8, 0, 6]
    },
    {
      state: 8,
      nbt: {
        id: "Banner",
        Patterns: [
          {
            Pattern: "tt",
            Color: 0
          },
          {
            Pattern: "bt",
            Color: 0
          }
        ],
        Base: 13
      },
      pos: [2, 0, 8]
    },
    {
      state: 8,
      nbt: {
        id: "Banner",
        Patterns: [
          {
            Pattern: "tt",
            Color: 0
          },
          {
            Pattern: "bt",
            Color: 0
          }
        ],
        Base: 13
      },
      pos: [6, 0, 8]
    },
    {
      state: 9,
      pos: [0, 4, 0]
    },
    {
      state: 10,
      pos: [1, 4, 0]
    },
    {
      state: 11,
      pos: [2, 4, 0]
    },
    {
      state: 11,
      pos: [3, 4, 0]
    },
    {
      state: 10,
      pos: [4, 4, 0]
    },
    {
      state: 11,
      pos: [5, 4, 0]
    },
    {
      state: 11,
      pos: [6, 4, 0]
    },
    {
      state: 10,
      pos: [7, 4, 0]
    },
    {
      state: 10,
      pos: [8, 4, 0]
    },
    {
      state: 9,
      pos: [1, 0, 1]
    },
    {
      state: 10,
      pos: [2, 0, 1]
    },
    {
      state: 11,
      pos: [3, 0, 1]
    },
    {
      state: 10,
      pos: [4, 0, 1]
    },
    {
      state: 11,
      pos: [5, 0, 1]
    },
    {
      state: 10,
      pos: [6, 0, 1]
    },
    {
      state: 12,
      pos: [7, 0, 1]
    },
    {
      state: 13,
      pos: [1, 1, 1]
    },
    {
      state: 13,
      pos: [7, 1, 1]
    },
    {
      state: 9,
      pos: [0, 4, 1]
    },
    {
      state: 12,
      pos: [8, 4, 1]
    },
    {
      state: 9,
      pos: [1, 0, 2]
    },
    {
      state: 12,
      pos: [7, 0, 2]
    },
    {
      state: 14,
      pos: [4, 2, 2]
    },
    {
      state: 14,
      pos: [4, 3, 2]
    },
    {
      state: 15,
      pos: [0, 4, 2]
    },
    {
      state: 16,
      pos: [8, 4, 2]
    },
    {
      state: 15,
      pos: [1, 0, 3]
    },
    {
      state: 17,
      pos: [3, 0, 3]
    },
    {
      state: 17,
      pos: [4, 0, 3]
    },
    {
      state: 16,
      pos: [7, 0, 3]
    },
    {
      state: 15,
      pos: [0, 4, 3]
    },
    {
      state: 16,
      pos: [8, 4, 3]
    },
    {
      state: 9,
      pos: [1, 0, 4]
    },
    {
      state: 12,
      pos: [7, 0, 4]
    },
    {
      state: 14,
      pos: [2, 2, 4]
    },
    {
      state: 14,
      pos: [2, 3, 4]
    },
    {
      state: 9,
      pos: [0, 4, 4]
    },
    {
      state: 12,
      pos: [8, 4, 4]
    },
    {
      state: 15,
      pos: [1, 0, 5]
    },
    {
      state: 16,
      pos: [7, 0, 5]
    },
    {
      state: 15,
      pos: [0, 4, 5]
    },
    {
      state: 16,
      pos: [8, 4, 5]
    },
    {
      state: 9,
      pos: [1, 0, 6]
    },
    {
      state: 12,
      pos: [7, 0, 6]
    },
    {
      state: 14,
      pos: [4, 2, 6]
    },
    {
      state: 14,
      pos: [4, 3, 6]
    },
    {
      state: 15,
      pos: [0, 4, 6]
    },
    {
      state: 16,
      pos: [8, 4, 6]
    },
    {
      state: 9,
      pos: [1, 0, 7]
    },
    {
      state: 18,
      pos: [2, 0, 7]
    },
    {
      state: 19,
      pos: [3, 0, 7]
    },
    {
      state: 18,
      pos: [4, 0, 7]
    },
    {
      state: 19,
      pos: [5, 0, 7]
    },
    {
      state: 18,
      pos: [6, 0, 7]
    },
    {
      state: 18,
      pos: [7, 0, 7]
    },
    {
      state: 13,
      pos: [1, 1, 7]
    },
    {
      state: 13,
      pos: [7, 1, 7]
    },
    {
      state: 9,
      pos: [0, 4, 7]
    },
    {
      state: 12,
      pos: [8, 4, 7]
    },
    {
      state: 18,
      pos: [0, 4, 8]
    },
    {
      state: 18,
      pos: [1, 4, 8]
    },
    {
      state: 19,
      pos: [2, 4, 8]
    },
    {
      state: 19,
      pos: [3, 4, 8]
    },
    {
      state: 18,
      pos: [4, 4, 8]
    },
    {
      state: 19,
      pos: [5, 4, 8]
    },
    {
      state: 19,
      pos: [6, 4, 8]
    },
    {
      state: 18,
      pos: [7, 4, 8]
    },
    {
      state: 12,
      pos: [8, 4, 8]
    }
  ],
  entities: [],
  version: 1,
  size: [9, 5, 9]
}