{
  author: "jeb_",
  palette: [
    {
      Name: "minecraft:air"
    },
    {
      Name: "minecraft:purpur_pillar",
      Properties: {
        axis: "z"
      }
    },
    {
      Name: "minecraft:purpur_block"
    },
    {
      Name: "minecraft:purpur_stairs",
      Properties: {
        half: "top",
        facing: "east",
        shape: "straight"
      }
    },
    {
      Name: "minecraft:purpur_stairs",
      Properties: {
        half: "top",
        facing: "west",
        shape: "straight"
      }
    },
    {
      Name: "minecraft:purpur_stairs",
      Properties: {
        half: "bottom",
        facing: "east",
        shape: "straight"
      }
    },
    {
      Name: "minecraft:purpur_stairs",
      Properties: {
        half: "bottom",
        facing: "west",
        shape: "straight"
      }
    }
  ],
  blocks: [
    {
      state: 0,
      pos: [0, 0, 0]
    },
    {
      state: 1,
      pos: [2, 0, 0]
    },
    {
      state: 0,
      pos: [4, 0, 0]
    },
    {
      state: 2,
      pos: [1, 1, 0]
    },
    {
      state: 2,
      pos: [2, 1, 0]
    },
    {
      state: 2,
      pos: [3, 1, 0]
    },
    {
      state: 2,
      pos: [0, 2, 0]
    },
    {
      state: 0,
      pos: [1, 2, 0]
    },
    {
      state: 0,
      pos: [2, 2, 0]
    },
    {
      state: 0,
      pos: [3, 2, 0]
    },
    {
      state: 2,
      pos: [4, 2, 0]
    },
    {
      state: 0,
      pos: [0, 3, 0]
    },
    {
      state: 0,
      pos: [1, 3, 0]
    },
    {
      state: 0,
      pos: [2, 3, 0]
    },
    {
      state: 0,
      pos: [3, 3, 0]
    },
    {
      state: 0,
      pos: [4, 3, 0]
    },
    {
      state: 0,
      pos: [0, 4, 0]
    },
    {
      state: 0,
      pos: [1, 4, 0]
    },
    {
      state: 0,
      pos: [2, 4, 0]
    },
    {
      state: 0,
      pos: [3, 4, 0]
    },
    {
      state: 0,
      pos: [4, 4, 0]
    },
    {
      state: 0,
      pos: [0, 5, 0]
    },
    {
      state: 0,
      pos: [1, 5, 0]
    },
    {
      state: 0,
      pos: [2, 5, 0]
    },
    {
      state: 0,
      pos: [3, 5, 0]
    },
    {
      state: 0,
      pos: [4, 5, 0]
    },
    {
      state: 0,
      pos: [0, 0, 1]
    },
    {
      state: 0,
      pos: [1, 0, 1]
    },
    {
      state: 1,
      pos: [2, 0, 1]
    },
    {
      state: 0,
      pos: [3, 0, 1]
    },
    {
      state: 0,
      pos: [4, 0, 1]
    },
    {
      state: 2,
      pos: [0, 1, 1]
    },
    {
      state: 2,
      pos: [1, 1, 1]
    },
    {
      state: 2,
      pos: [2, 1, 1]
    },
    {
      state: 2,
      pos: [3, 1, 1]
    },
    {
      state: 2,
      pos: [4, 1, 1]
    },
    {
      state: 0,
      pos: [1, 2, 1]
    },
    {
      state: 0,
      pos: [2, 2, 1]
    },
    {
      state: 0,
      pos: [3, 2, 1]
    },
    {
      state: 0,
      pos: [0, 3, 1]
    },
    {
      state: 0,
      pos: [1, 3, 1]
    },
    {
      state: 0,
      pos: [2, 3, 1]
    },
    {
      state: 0,
      pos: [3, 3, 1]
    },
    {
      state: 0,
      pos: [4, 3, 1]
    },
    {
      state: 0,
      pos: [0, 4, 1]
    },
    {
      state: 0,
      pos: [1, 4, 1]
    },
    {
      state: 0,
      pos: [2, 4, 1]
    },
    {
      state: 0,
      pos: [3, 4, 1]
    },
    {
      state: 0,
      pos: [4, 4, 1]
    },
    {
      state: 0,
      pos: [0, 5, 1]
    },
    {
      state: 0,
      pos: [1, 5, 1]
    },
    {
      state: 0,
      pos: [2, 5, 1]
    },
    {
      state: 0,
      pos: [3, 5, 1]
    },
    {
      state: 0,
      pos: [4, 5, 1]
    },
    {
      state: 0,
      pos: [0, 0, 2]
    },
    {
      state: 0,
      pos: [1, 0, 2]
    },
    {
      state: 1,
      pos: [2, 0, 2]
    },
    {
      state: 0,
      pos: [3, 0, 2]
    },
    {
      state: 0,
      pos: [4, 0, 2]
    },
    {
      state: 2,
      pos: [0, 1, 2]
    },
    {
      state: 2,
      pos: [1, 1, 2]
    },
    {
      state: 2,
      pos: [2, 1, 2]
    },
    {
      state: 2,
      pos: [3, 1, 2]
    },
    {
      state: 2,
      pos: [4, 1, 2]
    },
    {
      state: 0,
      pos: [1, 2, 2]
    },
    {
      state: 0,
      pos: [2, 2, 2]
    },
    {
      state: 0,
      pos: [3, 2, 2]
    },
    {
      state: 0,
      pos: [0, 3, 2]
    },
    {
      state: 0,
      pos: [1, 3, 2]
    },
    {
      state: 0,
      pos: [2, 3, 2]
    },
    {
      state: 0,
      pos: [3, 3, 2]
    },
    {
      state: 0,
      pos: [4, 3, 2]
    },
    {
      state: 0,
      pos: [0, 4, 2]
    },
    {
      state: 0,
      pos: [1, 4, 2]
    },
    {
      state: 0,
      pos: [2, 4, 2]
    },
    {
      state: 0,
      pos: [3, 4, 2]
    },
    {
      state: 0,
      pos: [4, 4, 2]
    },
    {
      state: 0,
      pos: [0, 5, 2]
    },
    {
      state: 0,
      pos: [1, 5, 2]
    },
    {
      state: 0,
      pos: [2, 5, 2]
    },
    {
      state: 0,
      pos: [3, 5, 2]
    },
    {
      state: 0,
      pos: [4, 5, 2]
    },
    {
      state: 0,
      pos: [0, 0, 3]
    },
    {
      state: 0,
      pos: [1, 0, 3]
    },
    {
      state: 1,
      pos: [2, 0, 3]
    },
    {
      state: 0,
      pos: [3, 0, 3]
    },
    {
      state: 0,
      pos: [4, 0, 3]
    },
    {
      state: 2,
      pos: [0, 1, 3]
    },
    {
      state: 2,
      pos: [1, 1, 3]
    },
    {
      state: 2,
      pos: [2, 1, 3]
    },
    {
      state: 2,
      pos: [3, 1, 3]
    },
    {
      state: 2,
      pos: [4, 1, 3]
    },
    {
      state: 0,
      pos: [1, 2, 3]
    },
    {
      state: 0,
      pos: [2, 2, 3]
    },
    {
      state: 0,
      pos: [3, 2, 3]
    },
    {
      state: 0,
      pos: [0, 3, 3]
    },
    {
      state: 0,
      pos: [1, 3, 3]
    },
    {
      state: 0,
      pos: [2, 3, 3]
    },
    {
      state: 0,
      pos: [3, 3, 3]
    },
    {
      state: 0,
      pos: [4, 3, 3]
    },
    {
      state: 0,
      pos: [0, 4, 3]
    },
    {
      state: 0,
      pos: [1, 4, 3]
    },
    {
      state: 0,
      pos: [2, 4, 3]
    },
    {
      state: 0,
      pos: [3, 4, 3]
    },
    {
      state: 0,
      pos: [4, 4, 3]
    },
    {
      state: 0,
      pos: [0, 5, 3]
    },
    {
      state: 0,
      pos: [1, 5, 3]
    },
    {
      state: 0,
      pos: [2, 5, 3]
    },
    {
      state: 0,
      pos: [3, 5, 3]
    },
    {
      state: 0,
      pos: [4, 5, 3]
    },
    {
      state: 3,
      pos: [1, 0, 0]
    },
    {
      state: 4,
      pos: [3, 0, 0]
    },
    {
      state: 3,
      pos: [0, 1, 0]
    },
    {
      state: 4,
      pos: [4, 1, 0]
    },
    {
      state: 5,
      pos: [0, 2, 1]
    },
    {
      state: 6,
      pos: [4, 2, 1]
    },
    {
      state: 5,
      pos: [0, 2, 2]
    },
    {
      state: 6,
      pos: [4, 2, 2]
    },
    {
      state: 5,
      pos: [0, 2, 3]
    },
    {
      state: 6,
      pos: [4, 2, 3]
    }
  ],
  entities: [],
  version: 1,
  size: [5, 6, 4]
}