{
  author: "jeb_",
  palette: [
    {
      Name: "minecraft:air"
    },
    {
      Name: "minecraft:purpur_block"
    },
    {
      Name: "minecraft:purpur_pillar",
      Properties: {
        axis: "y"
      }
    },
    {
      Name: "minecraft:purpur_pillar",
      Properties: {
        axis: "z"
      }
    },
    {
      Name: "minecraft:purpur_pillar",
      Properties: {
        axis: "x"
      }
    },
    {
      Name: "minecraft:purpur_stairs",
      Properties: {
        half: "top",
        facing: "south",
        shape: "straight"
      }
    },
    {
      Name: "minecraft:end_rod",
      Properties: {
        facing: "south"
      }
    },
    {
      Name: "minecraft:end_rod",
      Properties: {
        facing: "east"
      }
    },
    {
      Name: "minecraft:purpur_slab",
      Properties: {
        half: "bottom",
        variant: "default"
      }
    },
    {
      Name: "minecraft:purpur_stairs",
      Properties: {
        half: "top",
        facing: "east",
        shape: "straight"
      }
    },
    {
      Name: "minecraft:purpur_stairs",
      Properties: {
        half: "top",
        facing: "west",
        shape: "straight"
      }
    },
    {
      Name: "minecraft:end_rod",
      Properties: {
        facing: "west"
      }
    },
    {
      Name: "minecraft:end_rod",
      Properties: {
        facing: "north"
      }
    },
    {
      Name: "minecraft:purpur_stairs",
      Properties: {
        half: "top",
        facing: "north",
        shape: "straight"
      }
    }
  ],
  blocks: [
    {
      state: 0,
      pos: [0, 0, 0]
    },
    {
      state: 0,
      pos: [1, 0, 0]
    },
    {
      state: 0,
      pos: [2, 0, 0]
    },
    {
      state: 0,
      pos: [3, 0, 0]
    },
    {
      state: 0,
      pos: [4, 0, 0]
    },
    {
      state: 0,
      pos: [5, 0, 0]
    },
    {
      state: 0,
      pos: [6, 0, 0]
    },
    {
      state: 0,
      pos: [7, 0, 0]
    },
    {
      state: 0,
      pos: [8, 0, 0]
    },
    {
      state: 0,
      pos: [9, 0, 0]
    },
    {
      state: 0,
      pos: [10, 0, 0]
    },
    {
      state: 0,
      pos: [11, 0, 0]
    },
    {
      state: 0,
      pos: [12, 0, 0]
    },
    {
      state: 0,
      pos: [0, 1, 0]
    },
    {
      state: 0,
      pos: [1, 1, 0]
    },
    {
      state: 0,
      pos: [2, 1, 0]
    },
    {
      state: 0,
      pos: [3, 1, 0]
    },
    {
      state: 0,
      pos: [4, 1, 0]
    },
    {
      state: 0,
      pos: [5, 1, 0]
    },
    {
      state: 0,
      pos: [6, 1, 0]
    },
    {
      state: 0,
      pos: [7, 1, 0]
    },
    {
      state: 0,
      pos: [8, 1, 0]
    },
    {
      state: 0,
      pos: [9, 1, 0]
    },
    {
      state: 0,
      pos: [10, 1, 0]
    },
    {
      state: 0,
      pos: [11, 1, 0]
    },
    {
      state: 0,
      pos: [12, 1, 0]
    },
    {
      state: 0,
      pos: [0, 2, 0]
    },
    {
      state: 0,
      pos: [1, 2, 0]
    },
    {
      state: 0,
      pos: [2, 2, 0]
    },
    {
      state: 0,
      pos: [3, 2, 0]
    },
    {
      state: 0,
      pos: [4, 2, 0]
    },
    {
      state: 0,
      pos: [5, 2, 0]
    },
    {
      state: 0,
      pos: [7, 2, 0]
    },
    {
      state: 0,
      pos: [8, 2, 0]
    },
    {
      state: 0,
      pos: [9, 2, 0]
    },
    {
      state: 0,
      pos: [10, 2, 0]
    },
    {
      state: 0,
      pos: [11, 2, 0]
    },
    {
      state: 0,
      pos: [12, 2, 0]
    },
    {
      state: 0,
      pos: [0, 3, 0]
    },
    {
      state: 0,
      pos: [1, 3, 0]
    },
    {
      state: 0,
      pos: [2, 3, 0]
    },
    {
      state: 0,
      pos: [3, 3, 0]
    },
    {
      state: 0,
      pos: [4, 3, 0]
    },
    {
      state: 0,
      pos: [5, 3, 0]
    },
    {
      state: 0,
      pos: [6, 3, 0]
    },
    {
      state: 0,
      pos: [7, 3, 0]
    },
    {
      state: 0,
      pos: [8, 3, 0]
    },
    {
      state: 0,
      pos: [9, 3, 0]
    },
    {
      state: 0,
      pos: [10, 3, 0]
    },
    {
      state: 0,
      pos: [11, 3, 0]
    },
    {
      state: 0,
      pos: [12, 3, 0]
    },
    {
      state: 0,
      pos: [0, 0, 1]
    },
    {
      state: 0,
      pos: [1, 0, 1]
    },
    {
      state: 0,
      pos: [2, 0, 1]
    },
    {
      state: 0,
      pos: [3, 0, 1]
    },
    {
      state: 0,
      pos: [4, 0, 1]
    },
    {
      state: 1,
      pos: [5, 0, 1]
    },
    {
      state: 1,
      pos: [6, 0, 1]
    },
    {
      state: 1,
      pos: [7, 0, 1]
    },
    {
      state: 0,
      pos: [8, 0, 1]
    },
    {
      state: 0,
      pos: [9, 0, 1]
    },
    {
      state: 0,
      pos: [10, 0, 1]
    },
    {
      state: 0,
      pos: [11, 0, 1]
    },
    {
      state: 0,
      pos: [12, 0, 1]
    },
    {
      state: 0,
      pos: [0, 1, 1]
    },
    {
      state: 0,
      pos: [1, 1, 1]
    },
    {
      state: 0,
      pos: [2, 1, 1]
    },
    {
      state: 0,
      pos: [3, 1, 1]
    },
    {
      state: 0,
      pos: [4, 1, 1]
    },
    {
      state: 2,
      pos: [5, 1, 1]
    },
    {
      state: 2,
      pos: [6, 1, 1]
    },
    {
      state: 2,
      pos: [7, 1, 1]
    },
    {
      state: 0,
      pos: [8, 1, 1]
    },
    {
      state: 0,
      pos: [9, 1, 1]
    },
    {
      state: 0,
      pos: [10, 1, 1]
    },
    {
      state: 0,
      pos: [11, 1, 1]
    },
    {
      state: 0,
      pos: [12, 1, 1]
    },
    {
      state: 0,
      pos: [0, 2, 1]
    },
    {
      state: 0,
      pos: [1, 2, 1]
    },
    {
      state: 0,
      pos: [2, 2, 1]
    },
    {
      state: 0,
      pos: [3, 2, 1]
    },
    {
      state: 0,
      pos: [4, 2, 1]
    },
    {
      state: 2,
      pos: [5, 2, 1]
    },
    {
      state: 3,
      pos: [6, 2, 1]
    },
    {
      state: 2,
      pos: [7, 2, 1]
    },
    {
      state: 0,
      pos: [8, 2, 1]
    },
    {
      state: 0,
      pos: [9, 2, 1]
    },
    {
      state: 0,
      pos: [10, 2, 1]
    },
    {
      state: 0,
      pos: [11, 2, 1]
    },
    {
      state: 0,
      pos: [12, 2, 1]
    },
    {
      state: 0,
      pos: [0, 3, 1]
    },
    {
      state: 0,
      pos: [1, 3, 1]
    },
    {
      state: 0,
      pos: [2, 3, 1]
    },
    {
      state: 0,
      pos: [3, 3, 1]
    },
    {
      state: 0,
      pos: [4, 3, 1]
    },
    {
      state: 2,
      pos: [5, 3, 1]
    },
    {
      state: 2,
      pos: [6, 3, 1]
    },
    {
      state: 2,
      pos: [7, 3, 1]
    },
    {
      state: 0,
      pos: [8, 3, 1]
    },
    {
      state: 0,
      pos: [9, 3, 1]
    },
    {
      state: 0,
      pos: [10, 3, 1]
    },
    {
      state: 0,
      pos: [11, 3, 1]
    },
    {
      state: 0,
      pos: [12, 3, 1]
    },
    {
      state: 0,
      pos: [0, 0, 2]
    },
    {
      state: 0,
      pos: [1, 0, 2]
    },
    {
      state: 0,
      pos: [2, 0, 2]
    },
    {
      state: 1,
      pos: [3, 0, 2]
    },
    {
      state: 1,
      pos: [4, 0, 2]
    },
    {
      state: 1,
      pos: [5, 0, 2]
    },
    {
      state: 1,
      pos: [6, 0, 2]
    },
    {
      state: 1,
      pos: [7, 0, 2]
    },
    {
      state: 1,
      pos: [8, 0, 2]
    },
    {
      state: 1,
      pos: [9, 0, 2]
    },
    {
      state: 0,
      pos: [10, 0, 2]
    },
    {
      state: 0,
      pos: [11, 0, 2]
    },
    {
      state: 0,
      pos: [12, 0, 2]
    },
    {
      state: 0,
      pos: [0, 1, 2]
    },
    {
      state: 0,
      pos: [1, 1, 2]
    },
    {
      state: 0,
      pos: [2, 1, 2]
    },
    {
      state: 2,
      pos: [3, 1, 2]
    },
    {
      state: 2,
      pos: [4, 1, 2]
    },
    {
      state: 0,
      pos: [5, 1, 2]
    },
    {
      state: 0,
      pos: [6, 1, 2]
    },
    {
      state: 0,
      pos: [7, 1, 2]
    },
    {
      state: 2,
      pos: [8, 1, 2]
    },
    {
      state: 2,
      pos: [9, 1, 2]
    },
    {
      state: 0,
      pos: [10, 1, 2]
    },
    {
      state: 0,
      pos: [11, 1, 2]
    },
    {
      state: 0,
      pos: [12, 1, 2]
    },
    {
      state: 0,
      pos: [0, 2, 2]
    },
    {
      state: 0,
      pos: [1, 2, 2]
    },
    {
      state: 0,
      pos: [2, 2, 2]
    },
    {
      state: 2,
      pos: [3, 2, 2]
    },
    {
      state: 2,
      pos: [4, 2, 2]
    },
    {
      state: 0,
      pos: [5, 2, 2]
    },
    {
      state: 0,
      pos: [6, 2, 2]
    },
    {
      state: 0,
      pos: [7, 2, 2]
    },
    {
      state: 2,
      pos: [8, 2, 2]
    },
    {
      state: 2,
      pos: [9, 2, 2]
    },
    {
      state: 0,
      pos: [10, 2, 2]
    },
    {
      state: 0,
      pos: [11, 2, 2]
    },
    {
      state: 0,
      pos: [12, 2, 2]
    },
    {
      state: 0,
      pos: [0, 3, 2]
    },
    {
      state: 0,
      pos: [1, 3, 2]
    },
    {
      state: 0,
      pos: [2, 3, 2]
    },
    {
      state: 2,
      pos: [3, 3, 2]
    },
    {
      state: 2,
      pos: [4, 3, 2]
    },
    {
      state: 0,
      pos: [5, 3, 2]
    },
    {
      state: 0,
      pos: [6, 3, 2]
    },
    {
      state: 0,
      pos: [7, 3, 2]
    },
    {
      state: 2,
      pos: [8, 3, 2]
    },
    {
      state: 2,
      pos: [9, 3, 2]
    },
    {
      state: 0,
      pos: [10, 3, 2]
    },
    {
      state: 0,
      pos: [11, 3, 2]
    },
    {
      state: 0,
      pos: [12, 3, 2]
    },
    {
      state: 0,
      pos: [0, 0, 3]
    },
    {
      state: 0,
      pos: [1, 0, 3]
    },
    {
      state: 1,
      pos: [2, 0, 3]
    },
    {
      state: 1,
      pos: [3, 0, 3]
    },
    {
      state: 1,
      pos: [4, 0, 3]
    },
    {
      state: 1,
      pos: [5, 0, 3]
    },
    {
      state: 1,
      pos: [6, 0, 3]
    },
    {
      state: 1,
      pos: [7, 0, 3]
    },
    {
      state: 1,
      pos: [8, 0, 3]
    },
    {
      state: 1,
      pos: [9, 0, 3]
    },
    {
      state: 1,
      pos: [10, 0, 3]
    },
    {
      state: 0,
      pos: [11, 0, 3]
    },
    {
      state: 0,
      pos: [12, 0, 3]
    },
    {
      state: 0,
      pos: [0, 1, 3]
    },
    {
      state: 0,
      pos: [1, 1, 3]
    },
    {
      state: 2,
      pos: [2, 1, 3]
    },
    {
      state: 0,
      pos: [3, 1, 3]
    },
    {
      state: 0,
      pos: [4, 1, 3]
    },
    {
      state: 0,
      pos: [5, 1, 3]
    },
    {
      state: 0,
      pos: [6, 1, 3]
    },
    {
      state: 0,
      pos: [7, 1, 3]
    },
    {
      state: 0,
      pos: [8, 1, 3]
    },
    {
      state: 0,
      pos: [9, 1, 3]
    },
    {
      state: 2,
      pos: [10, 1, 3]
    },
    {
      state: 0,
      pos: [11, 1, 3]
    },
    {
      state: 0,
      pos: [12, 1, 3]
    },
    {
      state: 0,
      pos: [0, 2, 3]
    },
    {
      state: 0,
      pos: [1, 2, 3]
    },
    {
      state: 2,
      pos: [2, 2, 3]
    },
    {
      state: 0,
      pos: [3, 2, 3]
    },
    {
      state: 0,
      pos: [4, 2, 3]
    },
    {
      state: 0,
      pos: [5, 2, 3]
    },
    {
      state: 0,
      pos: [6, 2, 3]
    },
    {
      state: 0,
      pos: [7, 2, 3]
    },
    {
      state: 0,
      pos: [8, 2, 3]
    },
    {
      state: 0,
      pos: [9, 2, 3]
    },
    {
      state: 2,
      pos: [10, 2, 3]
    },
    {
      state: 0,
      pos: [11, 2, 3]
    },
    {
      state: 0,
      pos: [12, 2, 3]
    },
    {
      state: 0,
      pos: [0, 3, 3]
    },
    {
      state: 0,
      pos: [1, 3, 3]
    },
    {
      state: 2,
      pos: [2, 3, 3]
    },
    {
      state: 0,
      pos: [3, 3, 3]
    },
    {
      state: 0,
      pos: [5, 3, 3]
    },
    {
      state: 0,
      pos: [6, 3, 3]
    },
    {
      state: 0,
      pos: [7, 3, 3]
    },
    {
      state: 0,
      pos: [8, 3, 3]
    },
    {
      state: 0,
      pos: [9, 3, 3]
    },
    {
      state: 2,
      pos: [10, 3, 3]
    },
    {
      state: 0,
      pos: [11, 3, 3]
    },
    {
      state: 0,
      pos: [12, 3, 3]
    },
    {
      state: 0,
      pos: [0, 0, 4]
    },
    {
      state: 0,
      pos: [1, 0, 4]
    },
    {
      state: 1,
      pos: [2, 0, 4]
    },
    {
      state: 1,
      pos: [3, 0, 4]
    },
    {
      state: 1,
      pos: [4, 0, 4]
    },
    {
      state: 1,
      pos: [5, 0, 4]
    },
    {
      state: 1,
      pos: [6, 0, 4]
    },
    {
      state: 1,
      pos: [7, 0, 4]
    },
    {
      state: 1,
      pos: [8, 0, 4]
    },
    {
      state: 1,
      pos: [9, 0, 4]
    },
    {
      state: 1,
      pos: [10, 0, 4]
    },
    {
      state: 0,
      pos: [11, 0, 4]
    },
    {
      state: 0,
      pos: [12, 0, 4]
    },
    {
      state: 0,
      pos: [0, 1, 4]
    },
    {
      state: 0,
      pos: [1, 1, 4]
    },
    {
      state: 2,
      pos: [2, 1, 4]
    },
    {
      state: 0,
      pos: [3, 1, 4]
    },
    {
      state: 0,
      pos: [4, 1, 4]
    },
    {
      state: 0,
      pos: [5, 1, 4]
    },
    {
      state: 0,
      pos: [6, 1, 4]
    },
    {
      state: 0,
      pos: [7, 1, 4]
    },
    {
      state: 0,
      pos: [8, 1, 4]
    },
    {
      state: 0,
      pos: [9, 1, 4]
    },
    {
      state: 2,
      pos: [10, 1, 4]
    },
    {
      state: 0,
      pos: [11, 1, 4]
    },
    {
      state: 0,
      pos: [12, 1, 4]
    },
    {
      state: 0,
      pos: [0, 2, 4]
    },
    {
      state: 0,
      pos: [1, 2, 4]
    },
    {
      state: 2,
      pos: [2, 2, 4]
    },
    {
      state: 0,
      pos: [4, 2, 4]
    },
    {
      state: 0,
      pos: [5, 2, 4]
    },
    {
      state: 0,
      pos: [6, 2, 4]
    },
    {
      state: 0,
      pos: [7, 2, 4]
    },
    {
      state: 0,
      pos: [8, 2, 4]
    },
    {
      state: 0,
      pos: [9, 2, 4]
    },
    {
      state: 2,
      pos: [10, 2, 4]
    },
    {
      state: 0,
      pos: [11, 2, 4]
    },
    {
      state: 0,
      pos: [12, 2, 4]
    },
    {
      state: 0,
      pos: [0, 3, 4]
    },
    {
      state: 0,
      pos: [1, 3, 4]
    },
    {
      state: 2,
      pos: [2, 3, 4]
    },
    {
      state: 0,
      pos: [3, 3, 4]
    },
    {
      state: 0,
      pos: [4, 3, 4]
    },
    {
      state: 0,
      pos: [5, 3, 4]
    },
    {
      state: 0,
      pos: [6, 3, 4]
    },
    {
      state: 0,
      pos: [7, 3, 4]
    },
    {
      state: 0,
      pos: [8, 3, 4]
    },
    {
      state: 0,
      pos: [9, 3, 4]
    },
    {
      state: 2,
      pos: [10, 3, 4]
    },
    {
      state: 0,
      pos: [11, 3, 4]
    },
    {
      state: 0,
      pos: [12, 3, 4]
    },
    {
      state: 0,
      pos: [0, 0, 5]
    },
    {
      state: 1,
      pos: [1, 0, 5]
    },
    {
      state: 1,
      pos: [2, 0, 5]
    },
    {
      state: 1,
      pos: [3, 0, 5]
    },
    {
      state: 1,
      pos: [4, 0, 5]
    },
    {
      state: 0,
      pos: [5, 0, 5]
    },
    {
      state: 0,
      pos: [6, 0, 5]
    },
    {
      state: 0,
      pos: [7, 0, 5]
    },
    {
      state: 1,
      pos: [8, 0, 5]
    },
    {
      state: 1,
      pos: [9, 0, 5]
    },
    {
      state: 1,
      pos: [10, 0, 5]
    },
    {
      state: 1,
      pos: [11, 0, 5]
    },
    {
      state: 0,
      pos: [12, 0, 5]
    },
    {
      state: 0,
      pos: [0, 1, 5]
    },
    {
      state: 2,
      pos: [1, 1, 5]
    },
    {
      state: 0,
      pos: [3, 1, 5]
    },
    {
      state: 0,
      pos: [4, 1, 5]
    },
    {
      state: 0,
      pos: [5, 1, 5]
    },
    {
      state: 0,
      pos: [6, 1, 5]
    },
    {
      state: 0,
      pos: [7, 1, 5]
    },
    {
      state: 0,
      pos: [8, 1, 5]
    },
    {
      state: 0,
      pos: [9, 1, 5]
    },
    {
      state: 0,
      pos: [10, 1, 5]
    },
    {
      state: 2,
      pos: [11, 1, 5]
    },
    {
      state: 0,
      pos: [12, 1, 5]
    },
    {
      state: 0,
      pos: [0, 2, 5]
    },
    {
      state: 2,
      pos: [1, 2, 5]
    },
    {
      state: 0,
      pos: [2, 2, 5]
    },
    {
      state: 0,
      pos: [3, 2, 5]
    },
    {
      state: 0,
      pos: [4, 2, 5]
    },
    {
      state: 0,
      pos: [5, 2, 5]
    },
    {
      state: 0,
      pos: [6, 2, 5]
    },
    {
      state: 0,
      pos: [7, 2, 5]
    },
    {
      state: 0,
      pos: [8, 2, 5]
    },
    {
      state: 0,
      pos: [9, 2, 5]
    },
    {
      state: 0,
      pos: [10, 2, 5]
    },
    {
      state: 2,
      pos: [11, 2, 5]
    },
    {
      state: 0,
      pos: [12, 2, 5]
    },
    {
      state: 0,
      pos: [0, 3, 5]
    },
    {
      state: 2,
      pos: [1, 3, 5]
    },
    {
      state: 0,
      pos: [2, 3, 5]
    },
    {
      state: 0,
      pos: [3, 3, 5]
    },
    {
      state: 0,
      pos: [4, 3, 5]
    },
    {
      state: 0,
      pos: [5, 3, 5]
    },
    {
      state: 0,
      pos: [6, 3, 5]
    },
    {
      state: 0,
      pos: [7, 3, 5]
    },
    {
      state: 0,
      pos: [8, 3, 5]
    },
    {
      state: 0,
      pos: [9, 3, 5]
    },
    {
      state: 0,
      pos: [10, 3, 5]
    },
    {
      state: 2,
      pos: [11, 3, 5]
    },
    {
      state: 0,
      pos: [12, 3, 5]
    },
    {
      state: 0,
      pos: [0, 0, 6]
    },
    {
      state: 1,
      pos: [1, 0, 6]
    },
    {
      state: 1,
      pos: [2, 0, 6]
    },
    {
      state: 1,
      pos: [3, 0, 6]
    },
    {
      state: 1,
      pos: [4, 0, 6]
    },
    {
      state: 0,
      pos: [5, 0, 6]
    },
    {
      state: 0,
      pos: [6, 0, 6]
    },
    {
      state: 0,
      pos: [7, 0, 6]
    },
    {
      state: 1,
      pos: [8, 0, 6]
    },
    {
      state: 1,
      pos: [9, 0, 6]
    },
    {
      state: 1,
      pos: [10, 0, 6]
    },
    {
      state: 1,
      pos: [11, 0, 6]
    },
    {
      state: 0,
      pos: [12, 0, 6]
    },
    {
      state: 0,
      pos: [0, 1, 6]
    },
    {
      state: 2,
      pos: [1, 1, 6]
    },
    {
      state: 0,
      pos: [2, 1, 6]
    },
    {
      state: 0,
      pos: [3, 1, 6]
    },
    {
      state: 0,
      pos: [4, 1, 6]
    },
    {
      state: 0,
      pos: [5, 1, 6]
    },
    {
      state: 0,
      pos: [6, 1, 6]
    },
    {
      state: 0,
      pos: [7, 1, 6]
    },
    {
      state: 0,
      pos: [8, 1, 6]
    },
    {
      state: 0,
      pos: [9, 1, 6]
    },
    {
      state: 0,
      pos: [10, 1, 6]
    },
    {
      state: 2,
      pos: [11, 1, 6]
    },
    {
      state: 0,
      pos: [12, 1, 6]
    },
    {
      state: 4,
      pos: [1, 2, 6]
    },
    {
      state: 0,
      pos: [2, 2, 6]
    },
    {
      state: 0,
      pos: [3, 2, 6]
    },
    {
      state: 0,
      pos: [4, 2, 6]
    },
    {
      state: 0,
      pos: [5, 2, 6]
    },
    {
      state: 0,
      pos: [6, 2, 6]
    },
    {
      state: 0,
      pos: [7, 2, 6]
    },
    {
      state: 0,
      pos: [8, 2, 6]
    },
    {
      state: 0,
      pos: [9, 2, 6]
    },
    {
      state: 0,
      pos: [10, 2, 6]
    },
    {
      state: 4,
      pos: [11, 2, 6]
    },
    {
      state: 0,
      pos: [0, 3, 6]
    },
    {
      state: 2,
      pos: [1, 3, 6]
    },
    {
      state: 0,
      pos: [2, 3, 6]
    },
    {
      state: 0,
      pos: [3, 3, 6]
    },
    {
      state: 0,
      pos: [4, 3, 6]
    },
    {
      state: 0,
      pos: [5, 3, 6]
    },
    {
      state: 0,
      pos: [6, 3, 6]
    },
    {
      state: 0,
      pos: [7, 3, 6]
    },
    {
      state: 0,
      pos: [8, 3, 6]
    },
    {
      state: 0,
      pos: [9, 3, 6]
    },
    {
      state: 0,
      pos: [10, 3, 6]
    },
    {
      state: 2,
      pos: [11, 3, 6]
    },
    {
      state: 0,
      pos: [12, 3, 6]
    },
    {
      state: 0,
      pos: [0, 0, 7]
    },
    {
      state: 1,
      pos: [1, 0, 7]
    },
    {
      state: 1,
      pos: [2, 0, 7]
    },
    {
      state: 1,
      pos: [3, 0, 7]
    },
    {
      state: 1,
      pos: [4, 0, 7]
    },
    {
      state: 0,
      pos: [5, 0, 7]
    },
    {
      state: 0,
      pos: [7, 0, 7]
    },
    {
      state: 1,
      pos: [8, 0, 7]
    },
    {
      state: 1,
      pos: [9, 0, 7]
    },
    {
      state: 1,
      pos: [10, 0, 7]
    },
    {
      state: 1,
      pos: [11, 0, 7]
    },
    {
      state: 0,
      pos: [12, 0, 7]
    },
    {
      state: 0,
      pos: [0, 1, 7]
    },
    {
      state: 2,
      pos: [1, 1, 7]
    },
    {
      state: 0,
      pos: [2, 1, 7]
    },
    {
      state: 0,
      pos: [3, 1, 7]
    },
    {
      state: 0,
      pos: [4, 1, 7]
    },
    {
      state: 0,
      pos: [5, 1, 7]
    },
    {
      state: 0,
      pos: [6, 1, 7]
    },
    {
      state: 0,
      pos: [7, 1, 7]
    },
    {
      state: 0,
      pos: [8, 1, 7]
    },
    {
      state: 0,
      pos: [9, 1, 7]
    },
    {
      state: 2,
      pos: [11, 1, 7]
    },
    {
      state: 0,
      pos: [12, 1, 7]
    },
    {
      state: 0,
      pos: [0, 2, 7]
    },
    {
      state: 2,
      pos: [1, 2, 7]
    },
    {
      state: 0,
      pos: [2, 2, 7]
    },
    {
      state: 0,
      pos: [3, 2, 7]
    },
    {
      state: 0,
      pos: [4, 2, 7]
    },
    {
      state: 0,
      pos: [5, 2, 7]
    },
    {
      state: 0,
      pos: [6, 2, 7]
    },
    {
      state: 0,
      pos: [7, 2, 7]
    },
    {
      state: 0,
      pos: [8, 2, 7]
    },
    {
      state: 0,
      pos: [9, 2, 7]
    },
    {
      state: 0,
      pos: [10, 2, 7]
    },
    {
      state: 2,
      pos: [11, 2, 7]
    },
    {
      state: 0,
      pos: [12, 2, 7]
    },
    {
      state: 0,
      pos: [0, 3, 7]
    },
    {
      state: 2,
      pos: [1, 3, 7]
    },
    {
      state: 0,
      pos: [2, 3, 7]
    },
    {
      state: 0,
      pos: [3, 3, 7]
    },
    {
      state: 0,
      pos: [4, 3, 7]
    },
    {
      state: 0,
      pos: [5, 3, 7]
    },
    {
      state: 0,
      pos: [6, 3, 7]
    },
    {
      state: 0,
      pos: [7, 3, 7]
    },
    {
      state: 0,
      pos: [8, 3, 7]
    },
    {
      state: 0,
      pos: [9, 3, 7]
    },
    {
      state: 0,
      pos: [10, 3, 7]
    },
    {
      state: 2,
      pos: [11, 3, 7]
    },
    {
      state: 0,
      pos: [12, 3, 7]
    },
    {
      state: 0,
      pos: [0, 0, 8]
    },
    {
      state: 0,
      pos: [1, 0, 8]
    },
    {
      state: 1,
      pos: [2, 0, 8]
    },
    {
      state: 1,
      pos: [3, 0, 8]
    },
    {
      state: 1,
      pos: [4, 0, 8]
    },
    {
      state: 1,
      pos: [5, 0, 8]
    },
    {
      state: 1,
      pos: [6, 0, 8]
    },
    {
      state: 1,
      pos: [7, 0, 8]
    },
    {
      state: 1,
      pos: [8, 0, 8]
    },
    {
      state: 1,
      pos: [9, 0, 8]
    },
    {
      state: 1,
      pos: [10, 0, 8]
    },
    {
      state: 0,
      pos: [11, 0, 8]
    },
    {
      state: 0,
      pos: [12, 0, 8]
    },
    {
      state: 0,
      pos: [0, 1, 8]
    },
    {
      state: 0,
      pos: [1, 1, 8]
    },
    {
      state: 2,
      pos: [2, 1, 8]
    },
    {
      state: 0,
      pos: [3, 1, 8]
    },
    {
      state: 0,
      pos: [4, 1, 8]
    },
    {
      state: 0,
      pos: [5, 1, 8]
    },
    {
      state: 0,
      pos: [6, 1, 8]
    },
    {
      state: 0,
      pos: [7, 1, 8]
    },
    {
      state: 0,
      pos: [8, 1, 8]
    },
    {
      state: 0,
      pos: [9, 1, 8]
    },
    {
      state: 2,
      pos: [10, 1, 8]
    },
    {
      state: 0,
      pos: [11, 1, 8]
    },
    {
      state: 0,
      pos: [12, 1, 8]
    },
    {
      state: 0,
      pos: [0, 2, 8]
    },
    {
      state: 0,
      pos: [1, 2, 8]
    },
    {
      state: 2,
      pos: [2, 2, 8]
    },
    {
      state: 0,
      pos: [3, 2, 8]
    },
    {
      state: 0,
      pos: [4, 2, 8]
    },
    {
      state: 0,
      pos: [5, 2, 8]
    },
    {
      state: 0,
      pos: [6, 2, 8]
    },
    {
      state: 0,
      pos: [7, 2, 8]
    },
    {
      state: 0,
      pos: [8, 2, 8]
    },
    {
      state: 2,
      pos: [10, 2, 8]
    },
    {
      state: 0,
      pos: [11, 2, 8]
    },
    {
      state: 0,
      pos: [12, 2, 8]
    },
    {
      state: 0,
      pos: [0, 3, 8]
    },
    {
      state: 0,
      pos: [1, 3, 8]
    },
    {
      state: 2,
      pos: [2, 3, 8]
    },
    {
      state: 0,
      pos: [3, 3, 8]
    },
    {
      state: 0,
      pos: [4, 3, 8]
    },
    {
      state: 0,
      pos: [5, 3, 8]
    },
    {
      state: 0,
      pos: [6, 3, 8]
    },
    {
      state: 0,
      pos: [7, 3, 8]
    },
    {
      state: 0,
      pos: [8, 3, 8]
    },
    {
      state: 0,
      pos: [9, 3, 8]
    },
    {
      state: 2,
      pos: [10, 3, 8]
    },
    {
      state: 0,
      pos: [11, 3, 8]
    },
    {
      state: 0,
      pos: [12, 3, 8]
    },
    {
      state: 0,
      pos: [0, 0, 9]
    },
    {
      state: 0,
      pos: [1, 0, 9]
    },
    {
      state: 1,
      pos: [2, 0, 9]
    },
    {
      state: 1,
      pos: [3, 0, 9]
    },
    {
      state: 1,
      pos: [4, 0, 9]
    },
    {
      state: 1,
      pos: [5, 0, 9]
    },
    {
      state: 1,
      pos: [6, 0, 9]
    },
    {
      state: 1,
      pos: [7, 0, 9]
    },
    {
      state: 1,
      pos: [8, 0, 9]
    },
    {
      state: 1,
      pos: [9, 0, 9]
    },
    {
      state: 1,
      pos: [10, 0, 9]
    },
    {
      state: 0,
      pos: [11, 0, 9]
    },
    {
      state: 0,
      pos: [12, 0, 9]
    },
    {
      state: 0,
      pos: [0, 1, 9]
    },
    {
      state: 0,
      pos: [1, 1, 9]
    },
    {
      state: 2,
      pos: [2, 1, 9]
    },
    {
      state: 0,
      pos: [3, 1, 9]
    },
    {
      state: 0,
      pos: [4, 1, 9]
    },
    {
      state: 0,
      pos: [5, 1, 9]
    },
    {
      state: 0,
      pos: [6, 1, 9]
    },
    {
      state: 0,
      pos: [7, 1, 9]
    },
    {
      state: 0,
      pos: [8, 1, 9]
    },
    {
      state: 0,
      pos: [9, 1, 9]
    },
    {
      state: 2,
      pos: [10, 1, 9]
    },
    {
      state: 0,
      pos: [11, 1, 9]
    },
    {
      state: 0,
      pos: [12, 1, 9]
    },
    {
      state: 0,
      pos: [0, 2, 9]
    },
    {
      state: 0,
      pos: [1, 2, 9]
    },
    {
      state: 2,
      pos: [2, 2, 9]
    },
    {
      state: 0,
      pos: [3, 2, 9]
    },
    {
      state: 0,
      pos: [4, 2, 9]
    },
    {
      state: 0,
      pos: [5, 2, 9]
    },
    {
      state: 0,
      pos: [6, 2, 9]
    },
    {
      state: 0,
      pos: [7, 2, 9]
    },
    {
      state: 0,
      pos: [8, 2, 9]
    },
    {
      state: 0,
      pos: [9, 2, 9]
    },
    {
      state: 2,
      pos: [10, 2, 9]
    },
    {
      state: 0,
      pos: [11, 2, 9]
    },
    {
      state: 0,
      pos: [12, 2, 9]
    },
    {
      state: 0,
      pos: [0, 3, 9]
    },
    {
      state: 0,
      pos: [1, 3, 9]
    },
    {
      state: 2,
      pos: [2, 3, 9]
    },
    {
      state: 0,
      pos: [3, 3, 9]
    },
    {
      state: 0,
      pos: [4, 3, 9]
    },
    {
      state: 0,
      pos: [5, 3, 9]
    },
    {
      state: 0,
      pos: [6, 3, 9]
    },
    {
      state: 0,
      pos: [7, 3, 9]
    },
    {
      state: 0,
      pos: [9, 3, 9]
    },
    {
      state: 2,
      pos: [10, 3, 9]
    },
    {
      state: 0,
      pos: [11, 3, 9]
    },
    {
      state: 0,
      pos: [12, 3, 9]
    },
    {
      state: 0,
      pos: [0, 0, 10]
    },
    {
      state: 0,
      pos: [1, 0, 10]
    },
    {
      state: 0,
      pos: [2, 0, 10]
    },
    {
      state: 1,
      pos: [3, 0, 10]
    },
    {
      state: 1,
      pos: [4, 0, 10]
    },
    {
      state: 1,
      pos: [5, 0, 10]
    },
    {
      state: 1,
      pos: [6, 0, 10]
    },
    {
      state: 1,
      pos: [7, 0, 10]
    },
    {
      state: 1,
      pos: [8, 0, 10]
    },
    {
      state: 1,
      pos: [9, 0, 10]
    },
    {
      state: 0,
      pos: [10, 0, 10]
    },
    {
      state: 0,
      pos: [11, 0, 10]
    },
    {
      state: 0,
      pos: [12, 0, 10]
    },
    {
      state: 0,
      pos: [0, 1, 10]
    },
    {
      state: 0,
      pos: [1, 1, 10]
    },
    {
      state: 0,
      pos: [2, 1, 10]
    },
    {
      state: 2,
      pos: [3, 1, 10]
    },
    {
      state: 2,
      pos: [4, 1, 10]
    },
    {
      state: 0,
      pos: [5, 1, 10]
    },
    {
      state: 0,
      pos: [6, 1, 10]
    },
    {
      state: 0,
      pos: [7, 1, 10]
    },
    {
      state: 2,
      pos: [8, 1, 10]
    },
    {
      state: 2,
      pos: [9, 1, 10]
    },
    {
      state: 0,
      pos: [10, 1, 10]
    },
    {
      state: 0,
      pos: [11, 1, 10]
    },
    {
      state: 0,
      pos: [12, 1, 10]
    },
    {
      state: 0,
      pos: [0, 2, 10]
    },
    {
      state: 0,
      pos: [1, 2, 10]
    },
    {
      state: 0,
      pos: [2, 2, 10]
    },
    {
      state: 2,
      pos: [3, 2, 10]
    },
    {
      state: 2,
      pos: [4, 2, 10]
    },
    {
      state: 0,
      pos: [5, 2, 10]
    },
    {
      state: 0,
      pos: [6, 2, 10]
    },
    {
      state: 0,
      pos: [7, 2, 10]
    },
    {
      state: 2,
      pos: [8, 2, 10]
    },
    {
      state: 2,
      pos: [9, 2, 10]
    },
    {
      state: 0,
      pos: [10, 2, 10]
    },
    {
      state: 0,
      pos: [11, 2, 10]
    },
    {
      state: 0,
      pos: [12, 2, 10]
    },
    {
      state: 0,
      pos: [0, 3, 10]
    },
    {
      state: 0,
      pos: [1, 3, 10]
    },
    {
      state: 0,
      pos: [2, 3, 10]
    },
    {
      state: 2,
      pos: [3, 3, 10]
    },
    {
      state: 2,
      pos: [4, 3, 10]
    },
    {
      state: 0,
      pos: [5, 3, 10]
    },
    {
      state: 0,
      pos: [6, 3, 10]
    },
    {
      state: 0,
      pos: [7, 3, 10]
    },
    {
      state: 2,
      pos: [8, 3, 10]
    },
    {
      state: 2,
      pos: [9, 3, 10]
    },
    {
      state: 0,
      pos: [10, 3, 10]
    },
    {
      state: 0,
      pos: [11, 3, 10]
    },
    {
      state: 0,
      pos: [12, 3, 10]
    },
    {
      state: 0,
      pos: [0, 0, 11]
    },
    {
      state: 0,
      pos: [1, 0, 11]
    },
    {
      state: 0,
      pos: [2, 0, 11]
    },
    {
      state: 0,
      pos: [3, 0, 11]
    },
    {
      state: 0,
      pos: [4, 0, 11]
    },
    {
      state: 1,
      pos: [5, 0, 11]
    },
    {
      state: 1,
      pos: [6, 0, 11]
    },
    {
      state: 1,
      pos: [7, 0, 11]
    },
    {
      state: 0,
      pos: [8, 0, 11]
    },
    {
      state: 0,
      pos: [9, 0, 11]
    },
    {
      state: 0,
      pos: [10, 0, 11]
    },
    {
      state: 0,
      pos: [11, 0, 11]
    },
    {
      state: 0,
      pos: [12, 0, 11]
    },
    {
      state: 0,
      pos: [0, 1, 11]
    },
    {
      state: 0,
      pos: [1, 1, 11]
    },
    {
      state: 0,
      pos: [2, 1, 11]
    },
    {
      state: 0,
      pos: [3, 1, 11]
    },
    {
      state: 0,
      pos: [4, 1, 11]
    },
    {
      state: 2,
      pos: [5, 1, 11]
    },
    {
      state: 2,
      pos: [6, 1, 11]
    },
    {
      state: 2,
      pos: [7, 1, 11]
    },
    {
      state: 0,
      pos: [8, 1, 11]
    },
    {
      state: 0,
      pos: [9, 1, 11]
    },
    {
      state: 0,
      pos: [10, 1, 11]
    },
    {
      state: 0,
      pos: [11, 1, 11]
    },
    {
      state: 0,
      pos: [12, 1, 11]
    },
    {
      state: 0,
      pos: [0, 2, 11]
    },
    {
      state: 0,
      pos: [1, 2, 11]
    },
    {
      state: 0,
      pos: [2, 2, 11]
    },
    {
      state: 0,
      pos: [3, 2, 11]
    },
    {
      state: 0,
      pos: [4, 2, 11]
    },
    {
      state: 2,
      pos: [5, 2, 11]
    },
    {
      state: 3,
      pos: [6, 2, 11]
    },
    {
      state: 2,
      pos: [7, 2, 11]
    },
    {
      state: 0,
      pos: [8, 2, 11]
    },
    {
      state: 0,
      pos: [9, 2, 11]
    },
    {
      state: 0,
      pos: [10, 2, 11]
    },
    {
      state: 0,
      pos: [11, 2, 11]
    },
    {
      state: 0,
      pos: [12, 2, 11]
    },
    {
      state: 0,
      pos: [0, 3, 11]
    },
    {
      state: 0,
      pos: [1, 3, 11]
    },
    {
      state: 0,
      pos: [2, 3, 11]
    },
    {
      state: 0,
      pos: [3, 3, 11]
    },
    {
      state: 0,
      pos: [4, 3, 11]
    },
    {
      state: 2,
      pos: [5, 3, 11]
    },
    {
      state: 2,
      pos: [6, 3, 11]
    },
    {
      state: 2,
      pos: [7, 3, 11]
    },
    {
      state: 0,
      pos: [8, 3, 11]
    },
    {
      state: 0,
      pos: [9, 3, 11]
    },
    {
      state: 0,
      pos: [10, 3, 11]
    },
    {
      state: 0,
      pos: [11, 3, 11]
    },
    {
      state: 0,
      pos: [12, 3, 11]
    },
    {
      state: 0,
      pos: [0, 0, 12]
    },
    {
      state: 0,
      pos: [1, 0, 12]
    },
    {
      state: 0,
      pos: [2, 0, 12]
    },
    {
      state: 0,
      pos: [3, 0, 12]
    },
    {
      state: 0,
      pos: [4, 0, 12]
    },
    {
      state: 0,
      pos: [5, 0, 12]
    },
    {
      state: 0,
      pos: [6, 0, 12]
    },
    {
      state: 0,
      pos: [7, 0, 12]
    },
    {
      state: 0,
      pos: [8, 0, 12]
    },
    {
      state: 0,
      pos: [9, 0, 12]
    },
    {
      state: 0,
      pos: [10, 0, 12]
    },
    {
      state: 0,
      pos: [11, 0, 12]
    },
    {
      state: 0,
      pos: [12, 0, 12]
    },
    {
      state: 0,
      pos: [0, 1, 12]
    },
    {
      state: 0,
      pos: [1, 1, 12]
    },
    {
      state: 0,
      pos: [2, 1, 12]
    },
    {
      state: 0,
      pos: [3, 1, 12]
    },
    {
      state: 0,
      pos: [4, 1, 12]
    },
    {
      state: 0,
      pos: [5, 1, 12]
    },
    {
      state: 0,
      pos: [6, 1, 12]
    },
    {
      state: 0,
      pos: [7, 1, 12]
    },
    {
      state: 0,
      pos: [8, 1, 12]
    },
    {
      state: 0,
      pos: [9, 1, 12]
    },
    {
      state: 0,
      pos: [10, 1, 12]
    },
    {
      state: 0,
      pos: [11, 1, 12]
    },
    {
      state: 0,
      pos: [12, 1, 12]
    },
    {
      state: 0,
      pos: [0, 2, 12]
    },
    {
      state: 0,
      pos: [1, 2, 12]
    },
    {
      state: 0,
      pos: [2, 2, 12]
    },
    {
      state: 0,
      pos: [3, 2, 12]
    },
    {
      state: 0,
      pos: [4, 2, 12]
    },
    {
      state: 0,
      pos: [5, 2, 12]
    },
    {
      state: 0,
      pos: [7, 2, 12]
    },
    {
      state: 0,
      pos: [8, 2, 12]
    },
    {
      state: 0,
      pos: [9, 2, 12]
    },
    {
      state: 0,
      pos: [10, 2, 12]
    },
    {
      state: 0,
      pos: [11, 2, 12]
    },
    {
      state: 0,
      pos: [12, 2, 12]
    },
    {
      state: 0,
      pos: [0, 3, 12]
    },
    {
      state: 0,
      pos: [1, 3, 12]
    },
    {
      state: 0,
      pos: [2, 3, 12]
    },
    {
      state: 0,
      pos: [3, 3, 12]
    },
    {
      state: 0,
      pos: [4, 3, 12]
    },
    {
      state: 0,
      pos: [5, 3, 12]
    },
    {
      state: 0,
      pos: [6, 3, 12]
    },
    {
      state: 0,
      pos: [7, 3, 12]
    },
    {
      state: 0,
      pos: [8, 3, 12]
    },
    {
      state: 0,
      pos: [9, 3, 12]
    },
    {
      state: 0,
      pos: [10, 3, 12]
    },
    {
      state: 0,
      pos: [11, 3, 12]
    },
    {
      state: 0,
      pos: [12, 3, 12]
    },
    {
      state: 5,
      pos: [6, 2, 0]
    },
    {
      state: 6,
      pos: [4, 3, 3]
    },
    {
      state: 7,
      pos: [3, 2, 4]
    },
    {
      state: 8,
      pos: [2, 1, 5]
    },
    {
      state: 9,
      pos: [0, 2, 6]
    },
    {
      state: 10,
      pos: [12, 2, 6]
    },
    {
      state: 8,
      pos: [6, 0, 7]
    },
    {
      state: 8,
      pos: [10, 1, 7]
    },
    {
      state: 11,
      pos: [9, 2, 8]
    },
    {
      state: 12,
      pos: [8, 3, 9]
    },
    {
      state: 13,
      pos: [6, 2, 12]
    }
  ],
  entities: [],
  version: 1,
  size: [13, 4, 13]
}