{
  author: "ProfMobius",
  palette: [
    {
      Name: "minecraft:coal_ore"
    }
  ],
  blocks: [
    {
      state: 0,
      pos: [3, 3, 0]
    },
    {
      state: 0,
      pos: [0, 0, 1]
    },
    {
      state: 0,
      pos: [1, 0, 1]
    },
    {
      state: 0,
      pos: [2, 0, 1]
    },
    {
      state: 0,
      pos: [4, 0, 1]
    },
    {
      state: 0,
      pos: [5, 0, 1]
    },
    {
      state: 0,
      pos: [6, 0, 1]
    },
    {
      state: 0,
      pos: [0, 1, 1]
    },
    {
      state: 0,
      pos: [6, 1, 1]
    },
    {
      state: 0,
      pos: [0, 2, 1]
    },
    {
      state: 0,
      pos: [6, 2, 1]
    },
    {
      state: 0,
      pos: [0, 3, 1]
    },
    {
      state: 0,
      pos: [1, 3, 1]
    },
    {
      state: 0,
      pos: [2, 3, 1]
    },
    {
      state: 0,
      pos: [3, 3, 1]
    },
    {
      state: 0,
      pos: [4, 3, 1]
    },
    {
      state: 0,
      pos: [5, 3, 1]
    },
    {
      state: 0,
      pos: [6, 3, 1]
    },
    {
      state: 0,
      pos: [3, 3, 2]
    },
    {
      state: 0,
      pos: [0, 0, 3]
    },
    {
      state: 0,
      pos: [1, 0, 3]
    },
    {
      state: 0,
      pos: [2, 0, 3]
    },
    {
      state: 0,
      pos: [5, 0, 3]
    },
    {
      state: 0,
      pos: [6, 0, 3]
    },
    {
      state: 0,
      pos: [0, 1, 3]
    },
    {
      state: 0,
      pos: [6, 1, 3]
    },
    {
      state: 0,
      pos: [0, 2, 3]
    },
    {
      state: 0,
      pos: [6, 2, 3]
    },
    {
      state: 0,
      pos: [0, 3, 3]
    },
    {
      state: 0,
      pos: [1, 3, 3]
    },
    {
      state: 0,
      pos: [2, 3, 3]
    },
    {
      state: 0,
      pos: [3, 3, 3]
    },
    {
      state: 0,
      pos: [4, 3, 3]
    },
    {
      state: 0,
      pos: [5, 3, 3]
    },
    {
      state: 0,
      pos: [6, 3, 3]
    },
    {
      state: 0,
      pos: [3, 3, 4]
    },
    {
      state: 0,
      pos: [0, 0, 5]
    },
    {
      state: 0,
      pos: [1, 0, 5]
    },
    {
      state: 0,
      pos: [2, 0, 5]
    },
    {
      state: 0,
      pos: [5, 0, 5]
    },
    {
      state: 0,
      pos: [6, 0, 5]
    },
    {
      state: 0,
      pos: [0, 1, 5]
    },
    {
      state: 0,
      pos: [6, 1, 5]
    },
    {
      state: 0,
      pos: [0, 2, 5]
    },
    {
      state: 0,
      pos: [6, 2, 5]
    },
    {
      state: 0,
      pos: [0, 3, 5]
    },
    {
      state: 0,
      pos: [1, 3, 5]
    },
    {
      state: 0,
      pos: [2, 3, 5]
    },
    {
      state: 0,
      pos: [3, 3, 5]
    },
    {
      state: 0,
      pos: [4, 3, 5]
    },
    {
      state: 0,
      pos: [5, 3, 5]
    },
    {
      state: 0,
      pos: [6, 3, 5]
    },
    {
      state: 0,
      pos: [3, 3, 6]
    },
    {
      state: 0,
      pos: [0, 0, 7]
    },
    {
      state: 0,
      pos: [1, 0, 7]
    },
    {
      state: 0,
      pos: [2, 0, 7]
    },
    {
      state: 0,
      pos: [5, 0, 7]
    },
    {
      state: 0,
      pos: [6, 0, 7]
    },
    {
      state: 0,
      pos: [0, 1, 7]
    },
    {
      state: 0,
      pos: [6, 1, 7]
    },
    {
      state: 0,
      pos: [0, 2, 7]
    },
    {
      state: 0,
      pos: [6, 2, 7]
    },
    {
      state: 0,
      pos: [0, 3, 7]
    },
    {
      state: 0,
      pos: [1, 3, 7]
    },
    {
      state: 0,
      pos: [2, 3, 7]
    },
    {
      state: 0,
      pos: [3, 3, 7]
    },
    {
      state: 0,
      pos: [4, 3, 7]
    },
    {
      state: 0,
      pos: [5, 3, 7]
    },
    {
      state: 0,
      pos: [6, 3, 7]
    },
    {
      state: 0,
      pos: [3, 3, 8]
    },
    {
      state: 0,
      pos: [0, 0, 9]
    },
    {
      state: 0,
      pos: [1, 0, 9]
    },
    {
      state: 0,
      pos: [2, 0, 9]
    },
    {
      state: 0,
      pos: [5, 0, 9]
    },
    {
      state: 0,
      pos: [6, 0, 9]
    },
    {
      state: 0,
      pos: [0, 1, 9]
    },
    {
      state: 0,
      pos: [6, 1, 9]
    },
    {
      state: 0,
      pos: [0, 2, 9]
    },
    {
      state: 0,
      pos: [6, 2, 9]
    },
    {
      state: 0,
      pos: [0, 3, 9]
    },
    {
      state: 0,
      pos: [1, 3, 9]
    },
    {
      state: 0,
      pos: [2, 3, 9]
    },
    {
      state: 0,
      pos: [3, 3, 9]
    },
    {
      state: 0,
      pos: [4, 3, 9]
    },
    {
      state: 0,
      pos: [5, 3, 9]
    },
    {
      state: 0,
      pos: [6, 3, 9]
    },
    {
      state: 0,
      pos: [3, 3, 10]
    },
    {
      state: 0,
      pos: [0, 0, 11]
    },
    {
      state: 0,
      pos: [1, 0, 11]
    },
    {
      state: 0,
      pos: [2, 0, 11]
    },
    {
      state: 0,
      pos: [5, 0, 11]
    },
    {
      state: 0,
      pos: [6, 0, 11]
    },
    {
      state: 0,
      pos: [0, 1, 11]
    },
    {
      state: 0,
      pos: [6, 1, 11]
    },
    {
      state: 0,
      pos: [0, 2, 11]
    },
    {
      state: 0,
      pos: [6, 2, 11]
    },
    {
      state: 0,
      pos: [0, 3, 11]
    },
    {
      state: 0,
      pos: [1, 3, 11]
    },
    {
      state: 0,
      pos: [2, 3, 11]
    },
    {
      state: 0,
      pos: [3, 3, 11]
    },
    {
      state: 0,
      pos: [4, 3, 11]
    },
    {
      state: 0,
      pos: [5, 3, 11]
    },
    {
      state: 0,
      pos: [6, 3, 11]
    },
    {
      state: 0,
      pos: [3, 3, 12]
    }
  ],
  entities: [],
  version: 1,
  size: [7, 4, 13]
}